[2016-09-28 16:56:10] DEBUG [django.db.backends:89] (0.000) 
            SELECT name, type FROM sqlite_master
            WHERE type in ('table', 'view') AND NOT name='sqlite_sequence'
            ORDER BY name; args=None
[2016-09-28 16:56:10] DEBUG [django.db.backends:89] (0.000) SELECT "django_migrations"."app", "django_migrations"."name" FROM "django_migrations"; args=()
[2016-09-28 16:56:10] DEBUG [django.db.backends:89] (0.000) 
            SELECT name, type FROM sqlite_master
            WHERE type in ('table', 'view') AND NOT name='sqlite_sequence'
            ORDER BY name; args=None
[2016-09-28 16:56:10] DEBUG [django.db.backends:89] (0.000) SELECT "django_migrations"."app", "django_migrations"."name" FROM "django_migrations"; args=()
[2016-09-28 16:56:10] DEBUG [django.db.backends:89] (0.000) SELECT "django_content_type"."id", "django_content_type"."app_label", "django_content_type"."model" FROM "django_content_type" WHERE ("django_content_type"."model" = 'logentry' AND "django_content_type"."app_label" = 'admin'); args=('logentry', 'admin')
[2016-09-28 16:56:10] DEBUG [django.db.backends:89] (0.000) SELECT "auth_permission"."content_type_id", "auth_permission"."codename" FROM "auth_permission" INNER JOIN "django_content_type" ON ("auth_permission"."content_type_id" = "django_content_type"."id") WHERE "auth_permission"."content_type_id" IN (1) ORDER BY "django_content_type"."app_label" ASC, "django_content_type"."model" ASC, "auth_permission"."codename" ASC; args=(1,)
[2016-09-28 16:56:10] DEBUG [django.db.backends:89] (0.000) SELECT "django_content_type"."id", "django_content_type"."app_label", "django_content_type"."model" FROM "django_content_type" WHERE "django_content_type"."app_label" = 'admin'; args=('admin',)
[2016-09-28 16:56:10] DEBUG [django.db.backends:89] (0.000) SELECT "django_content_type"."id", "django_content_type"."app_label", "django_content_type"."model" FROM "django_content_type" WHERE ("django_content_type"."model" = 'permission' AND "django_content_type"."app_label" = 'auth'); args=('permission', 'auth')
[2016-09-28 16:56:10] DEBUG [django.db.backends:89] (0.000) SELECT "django_content_type"."id", "django_content_type"."app_label", "django_content_type"."model" FROM "django_content_type" WHERE ("django_content_type"."model" = 'group' AND "django_content_type"."app_label" = 'auth'); args=('group', 'auth')
[2016-09-28 16:56:10] DEBUG [django.db.backends:89] (0.000) SELECT "auth_permission"."content_type_id", "auth_permission"."codename" FROM "auth_permission" INNER JOIN "django_content_type" ON ("auth_permission"."content_type_id" = "django_content_type"."id") WHERE "auth_permission"."content_type_id" IN (2, 3) ORDER BY "django_content_type"."app_label" ASC, "django_content_type"."model" ASC, "auth_permission"."codename" ASC; args=(2, 3)
[2016-09-28 16:56:10] DEBUG [django.db.backends:89] (0.000) SELECT "django_content_type"."id", "django_content_type"."app_label", "django_content_type"."model" FROM "django_content_type" WHERE "django_content_type"."app_label" = 'auth'; args=('auth',)
[2016-09-28 16:56:10] DEBUG [django.db.backends:89] (0.000) SELECT "django_content_type"."id", "django_content_type"."app_label", "django_content_type"."model" FROM "django_content_type" WHERE ("django_content_type"."model" = 'contenttype' AND "django_content_type"."app_label" = 'contenttypes'); args=('contenttype', 'contenttypes')
[2016-09-28 16:56:10] DEBUG [django.db.backends:89] (0.000) SELECT "auth_permission"."content_type_id", "auth_permission"."codename" FROM "auth_permission" INNER JOIN "django_content_type" ON ("auth_permission"."content_type_id" = "django_content_type"."id") WHERE "auth_permission"."content_type_id" IN (4) ORDER BY "django_content_type"."app_label" ASC, "django_content_type"."model" ASC, "auth_permission"."codename" ASC; args=(4,)
[2016-09-28 16:56:10] DEBUG [django.db.backends:89] (0.000) SELECT "django_content_type"."id", "django_content_type"."app_label", "django_content_type"."model" FROM "django_content_type" WHERE "django_content_type"."app_label" = 'contenttypes'; args=('contenttypes',)
[2016-09-28 16:56:10] DEBUG [django.db.backends:89] (0.000) SELECT "django_content_type"."id", "django_content_type"."app_label", "django_content_type"."model" FROM "django_content_type" WHERE ("django_content_type"."model" = 'session' AND "django_content_type"."app_label" = 'sessions'); args=('session', 'sessions')
[2016-09-28 16:56:10] DEBUG [django.db.backends:89] (0.000) SELECT "auth_permission"."content_type_id", "auth_permission"."codename" FROM "auth_permission" INNER JOIN "django_content_type" ON ("auth_permission"."content_type_id" = "django_content_type"."id") WHERE "auth_permission"."content_type_id" IN (5) ORDER BY "django_content_type"."app_label" ASC, "django_content_type"."model" ASC, "auth_permission"."codename" ASC; args=(5,)
[2016-09-28 16:56:10] DEBUG [django.db.backends:89] (0.000) SELECT "django_content_type"."id", "django_content_type"."app_label", "django_content_type"."model" FROM "django_content_type" WHERE "django_content_type"."app_label" = 'sessions'; args=('sessions',)
[2016-09-28 16:56:10] DEBUG [django.db.backends:89] (0.000) SELECT "django_content_type"."id", "django_content_type"."app_label", "django_content_type"."model" FROM "django_content_type" WHERE ("django_content_type"."model" = 'site' AND "django_content_type"."app_label" = 'sites'); args=('site', 'sites')
[2016-09-28 16:56:10] DEBUG [django.db.backends:89] (0.000) SELECT "auth_permission"."content_type_id", "auth_permission"."codename" FROM "auth_permission" INNER JOIN "django_content_type" ON ("auth_permission"."content_type_id" = "django_content_type"."id") WHERE "auth_permission"."content_type_id" IN (6) ORDER BY "django_content_type"."app_label" ASC, "django_content_type"."model" ASC, "auth_permission"."codename" ASC; args=(6,)
[2016-09-28 16:56:10] DEBUG [django.db.backends:89] (0.000) SELECT "django_content_type"."id", "django_content_type"."app_label", "django_content_type"."model" FROM "django_content_type" WHERE "django_content_type"."app_label" = 'sites'; args=('sites',)
[2016-09-28 16:56:10] DEBUG [django.db.backends:89] (0.000) SELECT (1) AS "a" FROM "django_site" LIMIT 1; args=()
[2016-09-28 16:56:10] DEBUG [django.db.backends:89] (0.000) SELECT "django_content_type"."id", "django_content_type"."app_label", "django_content_type"."model" FROM "django_content_type" WHERE ("django_content_type"."model" = 'flatpage' AND "django_content_type"."app_label" = 'flatpages'); args=('flatpage', 'flatpages')
[2016-09-28 16:56:10] DEBUG [django.db.backends:89] (0.000) SELECT "auth_permission"."content_type_id", "auth_permission"."codename" FROM "auth_permission" INNER JOIN "django_content_type" ON ("auth_permission"."content_type_id" = "django_content_type"."id") WHERE "auth_permission"."content_type_id" IN (23) ORDER BY "django_content_type"."app_label" ASC, "django_content_type"."model" ASC, "auth_permission"."codename" ASC; args=(23,)
[2016-09-28 16:56:10] DEBUG [django.db.backends:89] (0.000) SELECT "django_content_type"."id", "django_content_type"."app_label", "django_content_type"."model" FROM "django_content_type" WHERE "django_content_type"."app_label" = 'flatpages'; args=('flatpages',)
[2016-09-28 16:56:10] DEBUG [django.db.backends:89] (0.000) SELECT "django_content_type"."id", "django_content_type"."app_label", "django_content_type"."model" FROM "django_content_type" WHERE ("django_content_type"."model" = 'person' AND "django_content_type"."app_label" = 'params'); args=('person', 'params')
[2016-09-28 16:56:10] DEBUG [django.db.backends:89] (0.000) SELECT "auth_permission"."content_type_id", "auth_permission"."codename" FROM "auth_permission" INNER JOIN "django_content_type" ON ("auth_permission"."content_type_id" = "django_content_type"."id") WHERE "auth_permission"."content_type_id" IN (9) ORDER BY "django_content_type"."app_label" ASC, "django_content_type"."model" ASC, "auth_permission"."codename" ASC; args=(9,)
[2016-09-28 16:56:10] DEBUG [django.db.backends:89] (0.000) SELECT "django_content_type"."id", "django_content_type"."app_label", "django_content_type"."model" FROM "django_content_type" WHERE "django_content_type"."app_label" = 'params'; args=('params',)
[2016-09-28 16:56:14] DEBUG [django.db.backends:89] (0.000) SELECT "auth_permission"."id", "auth_permission"."name", "auth_permission"."content_type_id", "auth_permission"."codename" FROM "auth_permission" INNER JOIN "django_content_type" ON ("auth_permission"."content_type_id" = "django_content_type"."id") WHERE "auth_permission"."content_type_id" IN (61) ORDER BY "django_content_type"."app_label" ASC, "django_content_type"."model" ASC, "auth_permission"."codename" ASC; args=(61,)
[2016-09-28 16:56:14] DEBUG [django.db.backends:89] (0.000) SELECT "sad_menu"."id", "sad_menu"."module", "sad_menu"."title", "sad_menu"."url", "sad_menu"."pos", "sad_menu"."icon", "sad_menu"."is_active", "sad_menu"."description", "sad_menu"."created_at", "sad_menu"."updated_at", "sad_menu"."permission_id", "sad_menu"."parent_id" FROM "sad_menu" WHERE "sad_menu"."permission_id" IN (61); args=(61,)
[2016-09-28 16:56:14] DEBUG [django.db.backends:89] (0.000) SELECT "sad_menu"."id", "sad_menu"."module", "sad_menu"."title", "sad_menu"."url", "sad_menu"."pos", "sad_menu"."icon", "sad_menu"."is_active", "sad_menu"."description", "sad_menu"."created_at", "sad_menu"."updated_at", "sad_menu"."permission_id", "sad_menu"."parent_id" FROM "sad_menu" WHERE "sad_menu"."parent_id" IN (27); args=(27,)
[2016-09-28 16:56:14] DEBUG [django.db.backends:89] (0.000) SELECT "django_admin_log"."id", "django_admin_log"."action_time", "django_admin_log"."user_id", "django_admin_log"."content_type_id", "django_admin_log"."object_id", "django_admin_log"."object_repr", "django_admin_log"."action_flag", "django_admin_log"."change_message" FROM "django_admin_log" WHERE "django_admin_log"."content_type_id" IN (61) ORDER BY "django_admin_log"."action_time" DESC; args=(61,)
[2016-09-28 16:56:14] DEBUG [django.db.backends:89] (0.000) BEGIN; args=None
[2016-09-28 16:56:14] DEBUG [django.db.backends:89] (0.000) DELETE FROM "auth_user_user_permissions" WHERE "auth_user_user_permissions"."permission_id" IN (61); args=(61,)
[2016-09-28 16:56:14] DEBUG [django.db.backends:89] (0.000) DELETE FROM "auth_group_permissions" WHERE "auth_group_permissions"."permission_id" IN (61); args=(61,)
[2016-09-28 16:56:14] DEBUG [django.db.backends:89] (0.000) UPDATE "sad_menu" SET "permission_id" = NULL WHERE "sad_menu"."id" IN (27); args=(27,)
[2016-09-28 16:56:14] DEBUG [django.db.backends:89] (0.000) DELETE FROM "auth_permission" WHERE "auth_permission"."id" IN (61); args=(61,)
[2016-09-28 16:56:14] DEBUG [django.db.backends:89] (0.000) DELETE FROM "sad_menu" WHERE "sad_menu"."id" IN (27); args=(27,)
[2016-09-28 16:56:14] DEBUG [django.db.backends:89] (0.000) DELETE FROM "django_content_type" WHERE "django_content_type"."id" IN (61); args=(61,)
[2016-09-28 16:56:14] DEBUG [django.db.backends:89] (0.000) SELECT "django_content_type"."id", "django_content_type"."app_label", "django_content_type"."model" FROM "django_content_type" WHERE ("django_content_type"."model" = 'solution' AND "django_content_type"."app_label" = 'space'); args=('solution', 'space')
[2016-09-28 16:56:14] DEBUG [django.db.backends:89] (0.000) SELECT "django_content_type"."id", "django_content_type"."app_label", "django_content_type"."model" FROM "django_content_type" WHERE ("django_content_type"."model" = 'association' AND "django_content_type"."app_label" = 'space'); args=('association', 'space')
[2016-09-28 16:56:14] DEBUG [django.db.backends:89] (0.000) SELECT "django_content_type"."id", "django_content_type"."app_label", "django_content_type"."model" FROM "django_content_type" WHERE ("django_content_type"."model" = 'enterprise' AND "django_content_type"."app_label" = 'space'); args=('enterprise', 'space')
[2016-09-28 16:56:14] DEBUG [django.db.backends:89] (0.000) SELECT "django_content_type"."id", "django_content_type"."app_label", "django_content_type"."model" FROM "django_content_type" WHERE ("django_content_type"."model" = 'headquar' AND "django_content_type"."app_label" = 'space'); args=('headquar', 'space')
[2016-09-28 16:56:14] DEBUG [django.db.backends:89] (0.000) SELECT "auth_permission"."content_type_id", "auth_permission"."codename" FROM "auth_permission" INNER JOIN "django_content_type" ON ("auth_permission"."content_type_id" = "django_content_type"."id") WHERE "auth_permission"."content_type_id" IN (11, 12, 13, 14) ORDER BY "django_content_type"."app_label" ASC, "django_content_type"."model" ASC, "auth_permission"."codename" ASC; args=(11, 12, 13, 14)
[2016-09-28 16:56:14] DEBUG [django.db.backends:89] (0.000) SELECT "django_content_type"."id", "django_content_type"."app_label", "django_content_type"."model" FROM "django_content_type" WHERE "django_content_type"."app_label" = 'space'; args=('space',)
[2016-09-28 16:56:14] DEBUG [django.db.backends:89] (0.000) SELECT "django_content_type"."id", "django_content_type"."app_label", "django_content_type"."model" FROM "django_content_type" WHERE ("django_content_type"."model" = 'user' AND "django_content_type"."app_label" = 'sad'); args=('user', 'sad')
[2016-09-28 16:56:14] DEBUG [django.db.backends:89] (0.000) SELECT "django_content_type"."id", "django_content_type"."app_label", "django_content_type"."model" FROM "django_content_type" WHERE ("django_content_type"."model" = 'userstatus' AND "django_content_type"."app_label" = 'sad'); args=('userstatus', 'sad')
[2016-09-28 16:56:14] DEBUG [django.db.backends:89] (0.000) SELECT "django_content_type"."id", "django_content_type"."app_label", "django_content_type"."model" FROM "django_content_type" WHERE ("django_content_type"."model" = 'access' AND "django_content_type"."app_label" = 'sad'); args=('access', 'sad')
[2016-09-28 16:56:14] DEBUG [django.db.backends:89] (0.000) SELECT "django_content_type"."id", "django_content_type"."app_label", "django_content_type"."model" FROM "django_content_type" WHERE ("django_content_type"."model" = 'module' AND "django_content_type"."app_label" = 'sad'); args=('module', 'sad')
[2016-09-28 16:56:14] DEBUG [django.db.backends:89] (0.000) SELECT "django_content_type"."id", "django_content_type"."app_label", "django_content_type"."model" FROM "django_content_type" WHERE ("django_content_type"."model" = 'menu' AND "django_content_type"."app_label" = 'sad'); args=('menu', 'sad')
[2016-09-28 16:56:14] DEBUG [django.db.backends:89] (0.000) SELECT "django_content_type"."id", "django_content_type"."app_label", "django_content_type"."model" FROM "django_content_type" WHERE ("django_content_type"."model" = 'userenterprise' AND "django_content_type"."app_label" = 'sad'); args=('userenterprise', 'sad')
[2016-09-28 16:56:14] DEBUG [django.db.backends:89] (0.000) SELECT "django_content_type"."id", "django_content_type"."app_label", "django_content_type"."model" FROM "django_content_type" WHERE ("django_content_type"."model" = 'userheadquar' AND "django_content_type"."app_label" = 'sad'); args=('userheadquar', 'sad')
[2016-09-28 16:56:14] DEBUG [django.db.backends:89] (0.000) SELECT "django_content_type"."id", "django_content_type"."app_label", "django_content_type"."model" FROM "django_content_type" WHERE ("django_content_type"."model" = 'userassociation' AND "django_content_type"."app_label" = 'sad'); args=('userassociation', 'sad')
[2016-09-28 16:56:14] DEBUG [django.db.backends:89] (0.000) SELECT "django_content_type"."id", "django_content_type"."app_label", "django_content_type"."model" FROM "django_content_type" WHERE ("django_content_type"."model" = 'ticket' AND "django_content_type"."app_label" = 'sad'); args=('ticket', 'sad')
[2016-09-28 16:56:14] DEBUG [django.db.backends:89] (0.000) SELECT "django_content_type"."id", "django_content_type"."app_label", "django_content_type"."model" FROM "django_content_type" WHERE ("django_content_type"."model" = 'backup' AND "django_content_type"."app_label" = 'sad'); args=('backup', 'sad')
[2016-09-28 16:56:14] DEBUG [django.db.backends:89] (0.000) SELECT "auth_permission"."content_type_id", "auth_permission"."codename" FROM "auth_permission" INNER JOIN "django_content_type" ON ("auth_permission"."content_type_id" = "django_content_type"."id") WHERE "auth_permission"."content_type_id" IN (101, 8, 15, 16, 17, 18, 19, 20, 21, 22) ORDER BY "django_content_type"."app_label" ASC, "django_content_type"."model" ASC, "auth_permission"."codename" ASC; args=(101, 8, 15, 16, 17, 18, 19, 20, 21, 22)
[2016-09-28 16:56:14] DEBUG [django.db.backends:89] (0.000) SELECT "django_content_type"."id", "django_content_type"."app_label", "django_content_type"."model" FROM "django_content_type" WHERE "django_content_type"."app_label" = 'sad'; args=('sad',)
[2016-09-28 16:56:20] DEBUG [django.db.backends:89] (0.001) 
            SELECT name, type FROM sqlite_master
            WHERE type in ('table', 'view') AND NOT name='sqlite_sequence'
            ORDER BY name; args=None
[2016-09-28 16:56:20] DEBUG [django.db.backends:89] (0.000) SELECT "django_migrations"."app", "django_migrations"."name" FROM "django_migrations"; args=()
[2016-09-28 16:56:44] DEBUG [django.db.backends:89] (0.001) 
            SELECT name, type FROM sqlite_master
            WHERE type in ('table', 'view') AND NOT name='sqlite_sequence'
            ORDER BY name; args=None
[2016-09-28 16:56:44] DEBUG [django.db.backends:89] (0.000) SELECT "django_migrations"."app", "django_migrations"."name" FROM "django_migrations"; args=()
[2016-09-28 16:56:46] DEBUG [django.template:927] Exception while resolving variable 'redirect_to' in template 'home/index.html'.
Traceback (most recent call last):
  File "/home/alumno/Proyectos/myvenv/local/lib/python2.7/site-packages/django/template/base.py", line 905, in _resolve_lookup
    (bit, current))  # missing attribute
VariableDoesNotExist: Failed lookup for key [redirect_to] in u"[{'False': False, 'None': None, 'True': True}, {u'csrf_token': <SimpleLazyObject: u'voFYGNbri6rL3ya3aWrq3eUBvmQJi0mC'>, 'perms': <django.contrib.auth.context_processors.PermWrapper object at 0x7f2ab32be210>, u'request': <WSGIRequest: GET '/'>, 'messages': <django.contrib.messages.storage.fallback.FallbackStorage object at 0x7f2ab3363890>, u'TIME_ZONE': 'UTC', u'STATIC_URL': '/static/', u'LANGUAGES': (('ja', <django.utils.functional.__proxy__ object at 0x7f2abaf8aa10>), ('zh-tw', <django.utils.functional.__proxy__ object at 0x7f2abaf8aa50>), ('fr', <django.utils.functional.__proxy__ object at 0x7f2abaf8aa90>), ('de', <django.utils.functional.__proxy__ object at 0x7f2abaf7dbd0>), ('en', <django.utils.functional.__proxy__ object at 0x7f2abaf97550>), ('es', <django.utils.functional.__proxy__ object at 0x7f2abaf97590>), ('es-ar', <django.utils.functional.__proxy__ object at 0x7f2abaf975d0>), ('es-pe', <django.utils.functional.__proxy__ object at 0x7f2abaf97610>), ('pt', <django.utils.functional.__proxy__ object at 0x7f2abaf97650>), ('pt-br', <django.utils.functional.__proxy__ object at 0x7f2abaf97690>)), 'user': <SimpleLazyObject: <function <lambda> at 0x7f2ab3356b18>>, u'LANGUAGE_CODE': u'es', 'DEFAULT_MESSAGE_LEVELS': {'DEBUG': 10, 'INFO': 20, 'WARNING': 30, 'SUCCESS': 25, 'ERROR': 40}, u'LANGUAGE_BIDI': False, u'MEDIA_URL': '/media/'}, {}, {'page_title': u'Home Page.', 'page_module': u'Inicio'}, {'block': <Block Node: header. Contents: [<TextNode: u'\\n'>, <django.template.loader_tags.IncludeNode object at 0x7f2ab32ca450>, <TextNode: u'\\n'>]>}, {}]"
[2016-09-28 16:56:46] DEBUG [django.template:927] Exception while resolving variable 'userx' in template 'home/index.html'.
Traceback (most recent call last):
  File "/home/alumno/Proyectos/myvenv/local/lib/python2.7/site-packages/django/template/base.py", line 905, in _resolve_lookup
    (bit, current))  # missing attribute
VariableDoesNotExist: Failed lookup for key [userx] in u"[{'False': False, 'None': None, 'True': True}, {u'csrf_token': <SimpleLazyObject: u'voFYGNbri6rL3ya3aWrq3eUBvmQJi0mC'>, 'perms': <django.contrib.auth.context_processors.PermWrapper object at 0x7f2ab32be210>, u'request': <WSGIRequest: GET '/'>, 'messages': <django.contrib.messages.storage.fallback.FallbackStorage object at 0x7f2ab3363890>, u'TIME_ZONE': 'UTC', u'STATIC_URL': '/static/', u'LANGUAGES': (('ja', <django.utils.functional.__proxy__ object at 0x7f2abaf8aa10>), ('zh-tw', <django.utils.functional.__proxy__ object at 0x7f2abaf8aa50>), ('fr', <django.utils.functional.__proxy__ object at 0x7f2abaf8aa90>), ('de', <django.utils.functional.__proxy__ object at 0x7f2abaf7dbd0>), ('en', <django.utils.functional.__proxy__ object at 0x7f2abaf97550>), ('es', <django.utils.functional.__proxy__ object at 0x7f2abaf97590>), ('es-ar', <django.utils.functional.__proxy__ object at 0x7f2abaf975d0>), ('es-pe', <django.utils.functional.__proxy__ object at 0x7f2abaf97610>), ('pt', <django.utils.functional.__proxy__ object at 0x7f2abaf97650>), ('pt-br', <django.utils.functional.__proxy__ object at 0x7f2abaf97690>)), 'user': <SimpleLazyObject: <function <lambda> at 0x7f2ab3356b18>>, u'LANGUAGE_CODE': u'es', 'DEFAULT_MESSAGE_LEVELS': {'DEBUG': 10, 'INFO': 20, 'WARNING': 30, 'SUCCESS': 25, 'ERROR': 40}, u'LANGUAGE_BIDI': False, u'MEDIA_URL': '/media/'}, {}, {'page_title': u'Home Page.', 'page_module': u'Inicio'}, {'block': <Block Node: header. Contents: [<TextNode: u'\\n'>, <django.template.loader_tags.IncludeNode object at 0x7f2ab32ca450>, <TextNode: u'\\n'>]>}, {}]"
[2016-09-28 16:56:46] WARNING [django.request:182] Not Found: /favicon.ico
[2016-09-28 16:56:46] DEBUG [django.template:927] Exception while resolving variable 'name' in template 'unknown'.
Traceback (most recent call last):
  File "/home/alumno/Proyectos/myvenv/local/lib/python2.7/site-packages/django/template/base.py", line 905, in _resolve_lookup
    (bit, current))  # missing attribute
VariableDoesNotExist: Failed lookup for key [name] in u'<RegexURLResolver <RegexURLPattern list> (admin:admin) ^admin/>'
[2016-09-28 16:56:46] DEBUG [django.template:927] Exception while resolving variable 'name' in template 'unknown'.
Traceback (most recent call last):
  File "/home/alumno/Proyectos/myvenv/local/lib/python2.7/site-packages/django/template/base.py", line 905, in _resolve_lookup
    (bit, current))  # missing attribute
VariableDoesNotExist: Failed lookup for key [name] in u"<RegexURLResolver <module 'django.contrib.admindocs.urls' from '/home/alumno/Proyectos/myvenv/local/lib/python2.7/site-packages/django/contrib/admindocs/urls.pyc'> (None:None) ^admin/doc/>"
[2016-09-28 16:56:46] DEBUG [django.template:927] Exception while resolving variable 'name' in template 'unknown'.
Traceback (most recent call last):
  File "/home/alumno/Proyectos/myvenv/local/lib/python2.7/site-packages/django/template/base.py", line 905, in _resolve_lookup
    (bit, current))  # missing attribute
VariableDoesNotExist: Failed lookup for key [name] in u"<RegexURLResolver <module 'apps.home.urls' from '/home/alumno/Proyectos/CLIVET/apps/home/urls.pyc'> (None:home) ^home/>"
[2016-09-28 16:56:46] DEBUG [django.template:927] Exception while resolving variable 'name' in template 'unknown'.
Traceback (most recent call last):
  File "/home/alumno/Proyectos/myvenv/local/lib/python2.7/site-packages/django/template/base.py", line 905, in _resolve_lookup
    (bit, current))  # missing attribute
VariableDoesNotExist: Failed lookup for key [name] in u"<RegexURLResolver <module 'apps.space.urls' from '/home/alumno/Proyectos/CLIVET/apps/space/urls.pyc'> (None:space) ^space/>"
[2016-09-28 16:56:46] DEBUG [django.template:927] Exception while resolving variable 'name' in template 'unknown'.
Traceback (most recent call last):
  File "/home/alumno/Proyectos/myvenv/local/lib/python2.7/site-packages/django/template/base.py", line 905, in _resolve_lookup
    (bit, current))  # missing attribute
VariableDoesNotExist: Failed lookup for key [name] in u"<RegexURLResolver <module 'apps.sad.urls' from '/home/alumno/Proyectos/CLIVET/apps/sad/urls.pyc'> (None:sad) ^sad/>"
[2016-09-28 16:56:46] DEBUG [django.template:927] Exception while resolving variable 'name' in template 'unknown'.
Traceback (most recent call last):
  File "/home/alumno/Proyectos/myvenv/local/lib/python2.7/site-packages/django/template/base.py", line 905, in _resolve_lookup
    (bit, current))  # missing attribute
VariableDoesNotExist: Failed lookup for key [name] in u"<RegexURLResolver <module 'apps.mod_backend.urls' from '/home/alumno/Proyectos/CLIVET/apps/mod_backend/urls.pyc'> (None:mod_backend) ^mod_backend/>"
[2016-09-28 16:56:46] DEBUG [django.template:927] Exception while resolving variable 'name' in template 'unknown'.
Traceback (most recent call last):
  File "/home/alumno/Proyectos/myvenv/local/lib/python2.7/site-packages/django/template/base.py", line 905, in _resolve_lookup
    (bit, current))  # missing attribute
VariableDoesNotExist: Failed lookup for key [name] in u"<RegexURLResolver <module 'apps.accounts.urls' from '/home/alumno/Proyectos/CLIVET/apps/accounts/urls.pyc'> (None:None) ^accounts/>"
[2016-09-28 16:56:46] DEBUG [django.template:927] Exception while resolving variable 'name' in template 'unknown'.
Traceback (most recent call last):
  File "/home/alumno/Proyectos/myvenv/local/lib/python2.7/site-packages/django/template/base.py", line 905, in _resolve_lookup
    (bit, current))  # missing attribute
VariableDoesNotExist: Failed lookup for key [name] in u"<RegexURLResolver <module 'apps.clivet.urls' from '/home/alumno/Proyectos/CLIVET/apps/clivet/urls.pyc'> (None:None) ^clivet/>"
[2016-09-28 16:56:46] DEBUG [django.template:927] Exception while resolving variable 'name' in template 'unknown'.
Traceback (most recent call last):
  File "/home/alumno/Proyectos/myvenv/local/lib/python2.7/site-packages/django/template/base.py", line 905, in _resolve_lookup
    (bit, current))  # missing attribute
VariableDoesNotExist: Failed lookup for key [name] in u"<RegexURLResolver <module 'django.conf.urls.i18n' from '/home/alumno/Proyectos/myvenv/local/lib/python2.7/site-packages/django/conf/urls/i18n.pyc'> (None:None) ^i18n/>"
[2016-09-28 16:56:49] DEBUG [django.template:927] Exception while resolving variable 'redirect_to' in template 'registration/login.html'.
Traceback (most recent call last):
  File "/home/alumno/Proyectos/myvenv/local/lib/python2.7/site-packages/django/template/base.py", line 905, in _resolve_lookup
    (bit, current))  # missing attribute
VariableDoesNotExist: Failed lookup for key [redirect_to] in u"[{'False': False, 'None': None, 'True': True}, {u'csrf_token': <SimpleLazyObject: u'voFYGNbri6rL3ya3aWrq3eUBvmQJi0mC'>, 'perms': <django.contrib.auth.context_processors.PermWrapper object at 0x7f2ab200b4d0>, u'request': <WSGIRequest: GET '/accounts/login/'>, 'messages': <django.contrib.messages.storage.fallback.FallbackStorage object at 0x7f2ab32bea90>, u'TIME_ZONE': 'UTC', u'STATIC_URL': '/static/', u'LANGUAGES': (('ja', <django.utils.functional.__proxy__ object at 0x7f2abaf8aa10>), ('zh-tw', <django.utils.functional.__proxy__ object at 0x7f2abaf8aa50>), ('fr', <django.utils.functional.__proxy__ object at 0x7f2abaf8aa90>), ('de', <django.utils.functional.__proxy__ object at 0x7f2abaf7dbd0>), ('en', <django.utils.functional.__proxy__ object at 0x7f2abaf97550>), ('es', <django.utils.functional.__proxy__ object at 0x7f2abaf97590>), ('es-ar', <django.utils.functional.__proxy__ object at 0x7f2abaf975d0>), ('es-pe', <django.utils.functional.__proxy__ object at 0x7f2abaf97610>), ('pt', <django.utils.functional.__proxy__ object at 0x7f2abaf97650>), ('pt-br', <django.utils.functional.__proxy__ object at 0x7f2abaf97690>)), 'user': <SimpleLazyObject: <django.contrib.auth.models.AnonymousUser object at 0x7f2ab32be8d0>>, u'LANGUAGE_CODE': u'es', 'DEFAULT_MESSAGE_LEVELS': {'DEBUG': 10, 'INFO': 20, 'WARNING': 30, 'SUCCESS': 25, 'ERROR': 40}, u'LANGUAGE_BIDI': False, u'MEDIA_URL': '/media/'}, {}, {'form': <LoginForm bound=False, valid=Unknown, fields=(username;password;remember_me)>, u'view': <apps.accounts.views.LoginView object at 0x7f2ab32beb50>}, {'block': <Block Node: header. Contents: [<TextNode: u'\\n'>, <django.template.loader_tags.IncludeNode object at 0x7f2ab2014c90>, <TextNode: u'\\n'>]>}, {}]"
[2016-09-28 16:56:49] DEBUG [django.template:927] Exception while resolving variable 'userx' in template 'registration/login.html'.
Traceback (most recent call last):
  File "/home/alumno/Proyectos/myvenv/local/lib/python2.7/site-packages/django/template/base.py", line 905, in _resolve_lookup
    (bit, current))  # missing attribute
VariableDoesNotExist: Failed lookup for key [userx] in u"[{'False': False, 'None': None, 'True': True}, {u'csrf_token': <SimpleLazyObject: u'voFYGNbri6rL3ya3aWrq3eUBvmQJi0mC'>, 'perms': <django.contrib.auth.context_processors.PermWrapper object at 0x7f2ab200b4d0>, u'request': <WSGIRequest: GET '/accounts/login/'>, 'messages': <django.contrib.messages.storage.fallback.FallbackStorage object at 0x7f2ab32bea90>, u'TIME_ZONE': 'UTC', u'STATIC_URL': '/static/', u'LANGUAGES': (('ja', <django.utils.functional.__proxy__ object at 0x7f2abaf8aa10>), ('zh-tw', <django.utils.functional.__proxy__ object at 0x7f2abaf8aa50>), ('fr', <django.utils.functional.__proxy__ object at 0x7f2abaf8aa90>), ('de', <django.utils.functional.__proxy__ object at 0x7f2abaf7dbd0>), ('en', <django.utils.functional.__proxy__ object at 0x7f2abaf97550>), ('es', <django.utils.functional.__proxy__ object at 0x7f2abaf97590>), ('es-ar', <django.utils.functional.__proxy__ object at 0x7f2abaf975d0>), ('es-pe', <django.utils.functional.__proxy__ object at 0x7f2abaf97610>), ('pt', <django.utils.functional.__proxy__ object at 0x7f2abaf97650>), ('pt-br', <django.utils.functional.__proxy__ object at 0x7f2abaf97690>)), 'user': <SimpleLazyObject: <django.contrib.auth.models.AnonymousUser object at 0x7f2ab32be8d0>>, u'LANGUAGE_CODE': u'es', 'DEFAULT_MESSAGE_LEVELS': {'DEBUG': 10, 'INFO': 20, 'WARNING': 30, 'SUCCESS': 25, 'ERROR': 40}, u'LANGUAGE_BIDI': False, u'MEDIA_URL': '/media/'}, {}, {'form': <LoginForm bound=False, valid=Unknown, fields=(username;password;remember_me)>, u'view': <apps.accounts.views.LoginView object at 0x7f2ab32beb50>}, {'block': <Block Node: header. Contents: [<TextNode: u'\\n'>, <django.template.loader_tags.IncludeNode object at 0x7f2ab2014c90>, <TextNode: u'\\n'>]>}, {}]"
[2016-09-28 16:56:49] DEBUG [django.template:927] Exception while resolving variable 'tag' in template 'bootstrap3/field.html'.
Traceback (most recent call last):
  File "/home/alumno/Proyectos/myvenv/local/lib/python2.7/site-packages/django/template/base.py", line 905, in _resolve_lookup
    (bit, current))  # missing attribute
VariableDoesNotExist: Failed lookup for key [tag] in u'[{\'False\': False, \'None\': None, \'True\': True}, {u\'csrf_token\': <SimpleLazyObject: u\'voFYGNbri6rL3ya3aWrq3eUBvmQJi0mC\'>, \'html5_required\': False, \'perms\': <django.contrib.auth.context_processors.PermWrapper object at 0x7f2ab200b4d0>, u\'request\': <WSGIRequest: GET \'/accounts/login/\'>, \'help_text_inline\': False, \'formset_error_title\': None, \'attrs\': {\'class\': \'js-validate form-vertical\'}, u\'LANGUAGE_CODE\': u\'es\', \'include_media\': True, \'field_class\': \'\', \'is_formset\': False, \'form_action\': \'\', \'label_class\': \'\', u\'TIME_ZONE\': \'UTC\', \'form_style\': \'\', \'form_tag\': True, u\'labelclass\': None, u\'field\': <django.forms.boundfield.BoundField object at 0x7f2ab200be90>, \'disable_csrf\': False, \'form_show_errors\': True, \'form_class\': \'js-validate form-vertical\', \'True\': True, \'form_method\': \'post\', \'inputs\': [], \'None\': None, \'form_id\': \'\', \'form\': <LoginForm bound=False, valid=Unknown, fields=(username;password;remember_me)>, \'form_show_labels\': True, \'flat_attrs\': u\'\', u\'STATIC_URL\': \'/static/\', u\'LANGUAGES\': ((\'ja\', <django.utils.functional.__proxy__ object at 0x7f2abaf8aa10>), (\'zh-tw\', <django.utils.functional.__proxy__ object at 0x7f2abaf8aa50>), (\'fr\', <django.utils.functional.__proxy__ object at 0x7f2abaf8aa90>), (\'de\', <django.utils.functional.__proxy__ object at 0x7f2abaf7dbd0>), (\'en\', <django.utils.functional.__proxy__ object at 0x7f2abaf97550>), (\'es\', <django.utils.functional.__proxy__ object at 0x7f2abaf97590>), (\'es-ar\', <django.utils.functional.__proxy__ object at 0x7f2abaf975d0>), (\'es-pe\', <django.utils.functional.__proxy__ object at 0x7f2abaf97610>), (\'pt\', <django.utils.functional.__proxy__ object at 0x7f2abaf97650>), (\'pt-br\', <django.utils.functional.__proxy__ object at 0x7f2abaf97690>)), \'user\': <SimpleLazyObject: <django.contrib.auth.models.AnonymousUser object at 0x7f2ab32be8d0>>, \'DEFAULT_MESSAGE_LEVELS\': {\'DEBUG\': 10, \'INFO\': 20, \'WARNING\': 30, \'SUCCESS\': 25, \'ERROR\': 40}, \'form_attrs\': {\'class\': \'js-validate form-vertical\'}, \'template_pack\': \'bootstrap3\', \'False\': False, \'form_error_title\': None, \'error_text_inline\': True, \'messages\': <django.contrib.messages.storage.fallback.FallbackStorage object at 0x7f2ab32bea90>, u\'LANGUAGE_BIDI\': False, u\'MEDIA_URL\': \'/media/\', \'label_size\': 0, \'block\': <Block Node: rootcontainer. Contents: [<TextNode: u\'\\n\\n<div id="shell-load">\\n \'>, <django.templatetags.i18n.TranslateNode object at 0x7f2ab200b390>, <TextNode: u\'</h3>\\n      </div>\\n      \'>, <django.template.library.SimpleNode object at 0x7f2ab200b3d0>, <TextNode: u\'\\n\\n      \'>, <crispy_forms.templatetags.crispy_forms_tags.CrispyFormNode object at 0x7f2ab200b550>, <TextNode: u\'\\n      \'>, <django.template.defaulttags.URLNode object at 0x7f2ab200b650>, <TextNode: u\'\\n      \'>, <IfNode>, <TextNode: u\'\\n      \\n    </div>\\n  </di\'>]>, u\'view\': <apps.accounts.views.LoginView object at 0x7f2ab32beb50>}]'
[2016-09-28 16:56:49] DEBUG [django.template:927] Exception while resolving variable 'wrapper_class' in template 'bootstrap3/field.html'.
Traceback (most recent call last):
  File "/home/alumno/Proyectos/myvenv/local/lib/python2.7/site-packages/django/template/base.py", line 905, in _resolve_lookup
    (bit, current))  # missing attribute
VariableDoesNotExist: Failed lookup for key [wrapper_class] in u'[{\'False\': False, \'None\': None, \'True\': True}, {u\'csrf_token\': <SimpleLazyObject: u\'voFYGNbri6rL3ya3aWrq3eUBvmQJi0mC\'>, \'html5_required\': False, \'perms\': <django.contrib.auth.context_processors.PermWrapper object at 0x7f2ab200b4d0>, u\'request\': <WSGIRequest: GET \'/accounts/login/\'>, \'help_text_inline\': False, \'formset_error_title\': None, \'attrs\': {\'class\': \'js-validate form-vertical\'}, u\'LANGUAGE_CODE\': u\'es\', \'include_media\': True, \'field_class\': \'\', \'is_formset\': False, \'form_action\': \'\', \'label_class\': \'\', u\'TIME_ZONE\': \'UTC\', \'form_style\': \'\', \'form_tag\': True, u\'labelclass\': None, u\'field\': <django.forms.boundfield.BoundField object at 0x7f2ab200be90>, \'disable_csrf\': False, \'form_show_errors\': True, \'form_class\': \'js-validate form-vertical\', \'True\': True, \'form_method\': \'post\', \'inputs\': [], \'None\': None, \'form_id\': \'\', \'form\': <LoginForm bound=False, valid=Unknown, fields=(username;password;remember_me)>, \'form_show_labels\': True, \'flat_attrs\': u\'\', u\'STATIC_URL\': \'/static/\', u\'LANGUAGES\': ((\'ja\', <django.utils.functional.__proxy__ object at 0x7f2abaf8aa10>), (\'zh-tw\', <django.utils.functional.__proxy__ object at 0x7f2abaf8aa50>), (\'fr\', <django.utils.functional.__proxy__ object at 0x7f2abaf8aa90>), (\'de\', <django.utils.functional.__proxy__ object at 0x7f2abaf7dbd0>), (\'en\', <django.utils.functional.__proxy__ object at 0x7f2abaf97550>), (\'es\', <django.utils.functional.__proxy__ object at 0x7f2abaf97590>), (\'es-ar\', <django.utils.functional.__proxy__ object at 0x7f2abaf975d0>), (\'es-pe\', <django.utils.functional.__proxy__ object at 0x7f2abaf97610>), (\'pt\', <django.utils.functional.__proxy__ object at 0x7f2abaf97650>), (\'pt-br\', <django.utils.functional.__proxy__ object at 0x7f2abaf97690>)), \'user\': <SimpleLazyObject: <django.contrib.auth.models.AnonymousUser object at 0x7f2ab32be8d0>>, \'DEFAULT_MESSAGE_LEVELS\': {\'DEBUG\': 10, \'INFO\': 20, \'WARNING\': 30, \'SUCCESS\': 25, \'ERROR\': 40}, \'form_attrs\': {\'class\': \'js-validate form-vertical\'}, \'template_pack\': \'bootstrap3\', \'False\': False, \'form_error_title\': None, \'error_text_inline\': True, \'messages\': <django.contrib.messages.storage.fallback.FallbackStorage object at 0x7f2ab32bea90>, u\'LANGUAGE_BIDI\': False, u\'MEDIA_URL\': \'/media/\', \'label_size\': 0, \'block\': <Block Node: rootcontainer. Contents: [<TextNode: u\'\\n\\n<div id="shell-load">\\n \'>, <django.templatetags.i18n.TranslateNode object at 0x7f2ab200b390>, <TextNode: u\'</h3>\\n      </div>\\n      \'>, <django.template.library.SimpleNode object at 0x7f2ab200b3d0>, <TextNode: u\'\\n\\n      \'>, <crispy_forms.templatetags.crispy_forms_tags.CrispyFormNode object at 0x7f2ab200b550>, <TextNode: u\'\\n      \'>, <django.template.defaulttags.URLNode object at 0x7f2ab200b650>, <TextNode: u\'\\n      \'>, <IfNode>, <TextNode: u\'\\n      \\n    </div>\\n  </di\'>]>, u\'view\': <apps.accounts.views.LoginView object at 0x7f2ab32beb50>}]'
[2016-09-28 16:56:49] DEBUG [django.template:927] Exception while resolving variable 'tag' in template 'bootstrap3/field.html'.
Traceback (most recent call last):
  File "/home/alumno/Proyectos/myvenv/local/lib/python2.7/site-packages/django/template/base.py", line 905, in _resolve_lookup
    (bit, current))  # missing attribute
VariableDoesNotExist: Failed lookup for key [tag] in u'[{\'False\': False, \'None\': None, \'True\': True}, {u\'csrf_token\': <SimpleLazyObject: u\'voFYGNbri6rL3ya3aWrq3eUBvmQJi0mC\'>, \'html5_required\': False, \'perms\': <django.contrib.auth.context_processors.PermWrapper object at 0x7f2ab200b4d0>, u\'request\': <WSGIRequest: GET \'/accounts/login/\'>, \'help_text_inline\': False, \'formset_error_title\': None, \'attrs\': {\'class\': \'js-validate form-vertical\'}, u\'LANGUAGE_CODE\': u\'es\', \'include_media\': True, \'field_class\': \'\', \'is_formset\': False, \'form_action\': \'\', \'label_class\': \'\', u\'TIME_ZONE\': \'UTC\', \'form_style\': \'\', \'form_tag\': True, u\'labelclass\': None, u\'field\': <django.forms.boundfield.BoundField object at 0x7f2ab200be90>, \'disable_csrf\': False, \'form_show_errors\': True, \'form_class\': \'js-validate form-vertical\', \'True\': True, \'form_method\': \'post\', \'inputs\': [], \'None\': None, \'form_id\': \'\', \'form\': <LoginForm bound=False, valid=False, fields=(username;password;remember_me)>, \'form_show_labels\': True, \'flat_attrs\': u\'\', u\'STATIC_URL\': \'/static/\', u\'LANGUAGES\': ((\'ja\', <django.utils.functional.__proxy__ object at 0x7f2abaf8aa10>), (\'zh-tw\', <django.utils.functional.__proxy__ object at 0x7f2abaf8aa50>), (\'fr\', <django.utils.functional.__proxy__ object at 0x7f2abaf8aa90>), (\'de\', <django.utils.functional.__proxy__ object at 0x7f2abaf7dbd0>), (\'en\', <django.utils.functional.__proxy__ object at 0x7f2abaf97550>), (\'es\', <django.utils.functional.__proxy__ object at 0x7f2abaf97590>), (\'es-ar\', <django.utils.functional.__proxy__ object at 0x7f2abaf975d0>), (\'es-pe\', <django.utils.functional.__proxy__ object at 0x7f2abaf97610>), (\'pt\', <django.utils.functional.__proxy__ object at 0x7f2abaf97650>), (\'pt-br\', <django.utils.functional.__proxy__ object at 0x7f2abaf97690>)), \'user\': <SimpleLazyObject: <django.contrib.auth.models.AnonymousUser object at 0x7f2ab32be8d0>>, \'DEFAULT_MESSAGE_LEVELS\': {\'DEBUG\': 10, \'INFO\': 20, \'WARNING\': 30, \'SUCCESS\': 25, \'ERROR\': 40}, \'form_attrs\': {\'class\': \'js-validate form-vertical\'}, \'template_pack\': \'bootstrap3\', \'False\': False, \'form_error_title\': None, \'error_text_inline\': True, \'messages\': <django.contrib.messages.storage.fallback.FallbackStorage object at 0x7f2ab32bea90>, u\'LANGUAGE_BIDI\': False, u\'MEDIA_URL\': \'/media/\', \'label_size\': 0, \'block\': <Block Node: rootcontainer. Contents: [<TextNode: u\'\\n\\n<div id="shell-load">\\n \'>, <django.templatetags.i18n.TranslateNode object at 0x7f2ab200b390>, <TextNode: u\'</h3>\\n      </div>\\n      \'>, <django.template.library.SimpleNode object at 0x7f2ab200b3d0>, <TextNode: u\'\\n\\n      \'>, <crispy_forms.templatetags.crispy_forms_tags.CrispyFormNode object at 0x7f2ab200b550>, <TextNode: u\'\\n      \'>, <django.template.defaulttags.URLNode object at 0x7f2ab200b650>, <TextNode: u\'\\n      \'>, <IfNode>, <TextNode: u\'\\n      \\n    </div>\\n  </di\'>]>, u\'view\': <apps.accounts.views.LoginView object at 0x7f2ab32beb50>}]'
[2016-09-28 16:56:49] DEBUG [django.template:927] Exception while resolving variable 'tag' in template 'bootstrap3/field.html'.
Traceback (most recent call last):
  File "/home/alumno/Proyectos/myvenv/local/lib/python2.7/site-packages/django/template/base.py", line 905, in _resolve_lookup
    (bit, current))  # missing attribute
VariableDoesNotExist: Failed lookup for key [tag] in u'[{\'False\': False, \'None\': None, \'True\': True}, {u\'csrf_token\': <SimpleLazyObject: u\'voFYGNbri6rL3ya3aWrq3eUBvmQJi0mC\'>, \'html5_required\': False, \'perms\': <django.contrib.auth.context_processors.PermWrapper object at 0x7f2ab200b4d0>, u\'request\': <WSGIRequest: GET \'/accounts/login/\'>, \'help_text_inline\': False, \'formset_error_title\': None, \'attrs\': {\'class\': \'js-validate form-vertical\'}, u\'LANGUAGE_CODE\': u\'es\', \'include_media\': True, \'field_class\': \'\', \'is_formset\': False, \'form_action\': \'\', \'label_class\': \'\', u\'TIME_ZONE\': \'UTC\', \'form_style\': \'\', \'form_tag\': True, u\'labelclass\': None, u\'field\': <django.forms.boundfield.BoundField object at 0x7f2ab200bd50>, \'disable_csrf\': False, \'form_show_errors\': True, \'form_class\': \'js-validate form-vertical\', \'True\': True, \'form_method\': \'post\', \'inputs\': [], \'None\': None, \'form_id\': \'\', \'form\': <LoginForm bound=False, valid=False, fields=(username;password;remember_me)>, \'form_show_labels\': True, \'flat_attrs\': u\'\', u\'STATIC_URL\': \'/static/\', u\'LANGUAGES\': ((\'ja\', <django.utils.functional.__proxy__ object at 0x7f2abaf8aa10>), (\'zh-tw\', <django.utils.functional.__proxy__ object at 0x7f2abaf8aa50>), (\'fr\', <django.utils.functional.__proxy__ object at 0x7f2abaf8aa90>), (\'de\', <django.utils.functional.__proxy__ object at 0x7f2abaf7dbd0>), (\'en\', <django.utils.functional.__proxy__ object at 0x7f2abaf97550>), (\'es\', <django.utils.functional.__proxy__ object at 0x7f2abaf97590>), (\'es-ar\', <django.utils.functional.__proxy__ object at 0x7f2abaf975d0>), (\'es-pe\', <django.utils.functional.__proxy__ object at 0x7f2abaf97610>), (\'pt\', <django.utils.functional.__proxy__ object at 0x7f2abaf97650>), (\'pt-br\', <django.utils.functional.__proxy__ object at 0x7f2abaf97690>)), \'user\': <SimpleLazyObject: <django.contrib.auth.models.AnonymousUser object at 0x7f2ab32be8d0>>, \'DEFAULT_MESSAGE_LEVELS\': {\'DEBUG\': 10, \'INFO\': 20, \'WARNING\': 30, \'SUCCESS\': 25, \'ERROR\': 40}, \'form_attrs\': {\'class\': \'js-validate form-vertical\'}, \'template_pack\': \'bootstrap3\', \'False\': False, \'form_error_title\': None, \'error_text_inline\': True, \'messages\': <django.contrib.messages.storage.fallback.FallbackStorage object at 0x7f2ab32bea90>, u\'LANGUAGE_BIDI\': False, u\'MEDIA_URL\': \'/media/\', \'label_size\': 0, \'block\': <Block Node: rootcontainer. Contents: [<TextNode: u\'\\n\\n<div id="shell-load">\\n \'>, <django.templatetags.i18n.TranslateNode object at 0x7f2ab200b390>, <TextNode: u\'</h3>\\n      </div>\\n      \'>, <django.template.library.SimpleNode object at 0x7f2ab200b3d0>, <TextNode: u\'\\n\\n      \'>, <crispy_forms.templatetags.crispy_forms_tags.CrispyFormNode object at 0x7f2ab200b550>, <TextNode: u\'\\n      \'>, <django.template.defaulttags.URLNode object at 0x7f2ab200b650>, <TextNode: u\'\\n      \'>, <IfNode>, <TextNode: u\'\\n      \\n    </div>\\n  </di\'>]>, u\'view\': <apps.accounts.views.LoginView object at 0x7f2ab32beb50>}]'
[2016-09-28 16:56:49] DEBUG [django.template:927] Exception while resolving variable 'wrapper_class' in template 'bootstrap3/field.html'.
Traceback (most recent call last):
  File "/home/alumno/Proyectos/myvenv/local/lib/python2.7/site-packages/django/template/base.py", line 905, in _resolve_lookup
    (bit, current))  # missing attribute
VariableDoesNotExist: Failed lookup for key [wrapper_class] in u'[{\'False\': False, \'None\': None, \'True\': True}, {u\'csrf_token\': <SimpleLazyObject: u\'voFYGNbri6rL3ya3aWrq3eUBvmQJi0mC\'>, \'html5_required\': False, \'perms\': <django.contrib.auth.context_processors.PermWrapper object at 0x7f2ab200b4d0>, u\'request\': <WSGIRequest: GET \'/accounts/login/\'>, \'help_text_inline\': False, \'formset_error_title\': None, \'attrs\': {\'class\': \'js-validate form-vertical\'}, u\'LANGUAGE_CODE\': u\'es\', \'include_media\': True, \'field_class\': \'\', \'is_formset\': False, \'form_action\': \'\', \'label_class\': \'\', u\'TIME_ZONE\': \'UTC\', \'form_style\': \'\', \'form_tag\': True, u\'labelclass\': None, u\'field\': <django.forms.boundfield.BoundField object at 0x7f2ab200bd50>, \'disable_csrf\': False, \'form_show_errors\': True, \'form_class\': \'js-validate form-vertical\', \'True\': True, \'form_method\': \'post\', \'inputs\': [], \'None\': None, \'form_id\': \'\', \'form\': <LoginForm bound=False, valid=False, fields=(username;password;remember_me)>, \'form_show_labels\': True, \'flat_attrs\': u\'\', u\'STATIC_URL\': \'/static/\', u\'LANGUAGES\': ((\'ja\', <django.utils.functional.__proxy__ object at 0x7f2abaf8aa10>), (\'zh-tw\', <django.utils.functional.__proxy__ object at 0x7f2abaf8aa50>), (\'fr\', <django.utils.functional.__proxy__ object at 0x7f2abaf8aa90>), (\'de\', <django.utils.functional.__proxy__ object at 0x7f2abaf7dbd0>), (\'en\', <django.utils.functional.__proxy__ object at 0x7f2abaf97550>), (\'es\', <django.utils.functional.__proxy__ object at 0x7f2abaf97590>), (\'es-ar\', <django.utils.functional.__proxy__ object at 0x7f2abaf975d0>), (\'es-pe\', <django.utils.functional.__proxy__ object at 0x7f2abaf97610>), (\'pt\', <django.utils.functional.__proxy__ object at 0x7f2abaf97650>), (\'pt-br\', <django.utils.functional.__proxy__ object at 0x7f2abaf97690>)), \'user\': <SimpleLazyObject: <django.contrib.auth.models.AnonymousUser object at 0x7f2ab32be8d0>>, \'DEFAULT_MESSAGE_LEVELS\': {\'DEBUG\': 10, \'INFO\': 20, \'WARNING\': 30, \'SUCCESS\': 25, \'ERROR\': 40}, \'form_attrs\': {\'class\': \'js-validate form-vertical\'}, \'template_pack\': \'bootstrap3\', \'False\': False, \'form_error_title\': None, \'error_text_inline\': True, \'messages\': <django.contrib.messages.storage.fallback.FallbackStorage object at 0x7f2ab32bea90>, u\'LANGUAGE_BIDI\': False, u\'MEDIA_URL\': \'/media/\', \'label_size\': 0, \'block\': <Block Node: rootcontainer. Contents: [<TextNode: u\'\\n\\n<div id="shell-load">\\n \'>, <django.templatetags.i18n.TranslateNode object at 0x7f2ab200b390>, <TextNode: u\'</h3>\\n      </div>\\n      \'>, <django.template.library.SimpleNode object at 0x7f2ab200b3d0>, <TextNode: u\'\\n\\n      \'>, <crispy_forms.templatetags.crispy_forms_tags.CrispyFormNode object at 0x7f2ab200b550>, <TextNode: u\'\\n      \'>, <django.template.defaulttags.URLNode object at 0x7f2ab200b650>, <TextNode: u\'\\n      \'>, <IfNode>, <TextNode: u\'\\n      \\n    </div>\\n  </di\'>]>, u\'view\': <apps.accounts.views.LoginView object at 0x7f2ab32beb50>}]'
[2016-09-28 16:56:49] DEBUG [django.template:927] Exception while resolving variable 'tag' in template 'bootstrap3/field.html'.
Traceback (most recent call last):
  File "/home/alumno/Proyectos/myvenv/local/lib/python2.7/site-packages/django/template/base.py", line 905, in _resolve_lookup
    (bit, current))  # missing attribute
VariableDoesNotExist: Failed lookup for key [tag] in u'[{\'False\': False, \'None\': None, \'True\': True}, {u\'csrf_token\': <SimpleLazyObject: u\'voFYGNbri6rL3ya3aWrq3eUBvmQJi0mC\'>, \'html5_required\': False, \'perms\': <django.contrib.auth.context_processors.PermWrapper object at 0x7f2ab200b4d0>, u\'request\': <WSGIRequest: GET \'/accounts/login/\'>, \'help_text_inline\': False, \'formset_error_title\': None, \'attrs\': {\'class\': \'js-validate form-vertical\'}, u\'LANGUAGE_CODE\': u\'es\', \'include_media\': True, \'field_class\': \'\', \'is_formset\': False, \'form_action\': \'\', \'label_class\': \'\', u\'TIME_ZONE\': \'UTC\', \'form_style\': \'\', \'form_tag\': True, u\'labelclass\': None, u\'field\': <django.forms.boundfield.BoundField object at 0x7f2ab200bd50>, \'disable_csrf\': False, \'form_show_errors\': True, \'form_class\': \'js-validate form-vertical\', \'True\': True, \'form_method\': \'post\', \'inputs\': [], \'None\': None, \'form_id\': \'\', \'form\': <LoginForm bound=False, valid=False, fields=(username;password;remember_me)>, \'form_show_labels\': True, \'flat_attrs\': u\'\', u\'STATIC_URL\': \'/static/\', u\'LANGUAGES\': ((\'ja\', <django.utils.functional.__proxy__ object at 0x7f2abaf8aa10>), (\'zh-tw\', <django.utils.functional.__proxy__ object at 0x7f2abaf8aa50>), (\'fr\', <django.utils.functional.__proxy__ object at 0x7f2abaf8aa90>), (\'de\', <django.utils.functional.__proxy__ object at 0x7f2abaf7dbd0>), (\'en\', <django.utils.functional.__proxy__ object at 0x7f2abaf97550>), (\'es\', <django.utils.functional.__proxy__ object at 0x7f2abaf97590>), (\'es-ar\', <django.utils.functional.__proxy__ object at 0x7f2abaf975d0>), (\'es-pe\', <django.utils.functional.__proxy__ object at 0x7f2abaf97610>), (\'pt\', <django.utils.functional.__proxy__ object at 0x7f2abaf97650>), (\'pt-br\', <django.utils.functional.__proxy__ object at 0x7f2abaf97690>)), \'user\': <SimpleLazyObject: <django.contrib.auth.models.AnonymousUser object at 0x7f2ab32be8d0>>, \'DEFAULT_MESSAGE_LEVELS\': {\'DEBUG\': 10, \'INFO\': 20, \'WARNING\': 30, \'SUCCESS\': 25, \'ERROR\': 40}, \'form_attrs\': {\'class\': \'js-validate form-vertical\'}, \'template_pack\': \'bootstrap3\', \'False\': False, \'form_error_title\': None, \'error_text_inline\': True, \'messages\': <django.contrib.messages.storage.fallback.FallbackStorage object at 0x7f2ab32bea90>, u\'LANGUAGE_BIDI\': False, u\'MEDIA_URL\': \'/media/\', \'label_size\': 0, \'block\': <Block Node: rootcontainer. Contents: [<TextNode: u\'\\n\\n<div id="shell-load">\\n \'>, <django.templatetags.i18n.TranslateNode object at 0x7f2ab200b390>, <TextNode: u\'</h3>\\n      </div>\\n      \'>, <django.template.library.SimpleNode object at 0x7f2ab200b3d0>, <TextNode: u\'\\n\\n      \'>, <crispy_forms.templatetags.crispy_forms_tags.CrispyFormNode object at 0x7f2ab200b550>, <TextNode: u\'\\n      \'>, <django.template.defaulttags.URLNode object at 0x7f2ab200b650>, <TextNode: u\'\\n      \'>, <IfNode>, <TextNode: u\'\\n      \\n    </div>\\n  </di\'>]>, u\'view\': <apps.accounts.views.LoginView object at 0x7f2ab32beb50>}]'
[2016-09-28 16:56:49] DEBUG [django.template:927] Exception while resolving variable 'tag' in template 'bootstrap3/field.html'.
Traceback (most recent call last):
  File "/home/alumno/Proyectos/myvenv/local/lib/python2.7/site-packages/django/template/base.py", line 905, in _resolve_lookup
    (bit, current))  # missing attribute
VariableDoesNotExist: Failed lookup for key [tag] in u'[{\'False\': False, \'None\': None, \'True\': True}, {u\'csrf_token\': <SimpleLazyObject: u\'voFYGNbri6rL3ya3aWrq3eUBvmQJi0mC\'>, \'html5_required\': False, \'perms\': <django.contrib.auth.context_processors.PermWrapper object at 0x7f2ab200b4d0>, u\'request\': <WSGIRequest: GET \'/accounts/login/\'>, \'help_text_inline\': False, \'formset_error_title\': None, \'attrs\': {\'class\': \'js-validate form-vertical\'}, u\'LANGUAGE_CODE\': u\'es\', \'include_media\': True, \'field_class\': \'\', \'is_formset\': False, \'form_action\': \'\', \'label_class\': \'\', u\'TIME_ZONE\': \'UTC\', \'form_style\': \'\', \'form_tag\': True, u\'labelclass\': None, u\'field\': <django.forms.boundfield.BoundField object at 0x7f2ab201f890>, \'disable_csrf\': False, \'form_show_errors\': True, \'form_class\': \'js-validate form-vertical\', \'True\': True, \'form_method\': \'post\', \'inputs\': [], \'None\': None, \'form_id\': \'\', \'form\': <LoginForm bound=False, valid=False, fields=(username;password;remember_me)>, \'form_show_labels\': True, \'flat_attrs\': u\'\', u\'STATIC_URL\': \'/static/\', u\'LANGUAGES\': ((\'ja\', <django.utils.functional.__proxy__ object at 0x7f2abaf8aa10>), (\'zh-tw\', <django.utils.functional.__proxy__ object at 0x7f2abaf8aa50>), (\'fr\', <django.utils.functional.__proxy__ object at 0x7f2abaf8aa90>), (\'de\', <django.utils.functional.__proxy__ object at 0x7f2abaf7dbd0>), (\'en\', <django.utils.functional.__proxy__ object at 0x7f2abaf97550>), (\'es\', <django.utils.functional.__proxy__ object at 0x7f2abaf97590>), (\'es-ar\', <django.utils.functional.__proxy__ object at 0x7f2abaf975d0>), (\'es-pe\', <django.utils.functional.__proxy__ object at 0x7f2abaf97610>), (\'pt\', <django.utils.functional.__proxy__ object at 0x7f2abaf97650>), (\'pt-br\', <django.utils.functional.__proxy__ object at 0x7f2abaf97690>)), \'user\': <SimpleLazyObject: <django.contrib.auth.models.AnonymousUser object at 0x7f2ab32be8d0>>, \'DEFAULT_MESSAGE_LEVELS\': {\'DEBUG\': 10, \'INFO\': 20, \'WARNING\': 30, \'SUCCESS\': 25, \'ERROR\': 40}, \'form_attrs\': {\'class\': \'js-validate form-vertical\'}, \'template_pack\': \'bootstrap3\', \'False\': False, \'form_error_title\': None, \'error_text_inline\': True, \'messages\': <django.contrib.messages.storage.fallback.FallbackStorage object at 0x7f2ab32bea90>, u\'LANGUAGE_BIDI\': False, u\'MEDIA_URL\': \'/media/\', \'label_size\': 0, \'block\': <Block Node: rootcontainer. Contents: [<TextNode: u\'\\n\\n<div id="shell-load">\\n \'>, <django.templatetags.i18n.TranslateNode object at 0x7f2ab200b390>, <TextNode: u\'</h3>\\n      </div>\\n      \'>, <django.template.library.SimpleNode object at 0x7f2ab200b3d0>, <TextNode: u\'\\n\\n      \'>, <crispy_forms.templatetags.crispy_forms_tags.CrispyFormNode object at 0x7f2ab200b550>, <TextNode: u\'\\n      \'>, <django.template.defaulttags.URLNode object at 0x7f2ab200b650>, <TextNode: u\'\\n      \'>, <IfNode>, <TextNode: u\'\\n      \\n    </div>\\n  </di\'>]>, u\'view\': <apps.accounts.views.LoginView object at 0x7f2ab32beb50>}]'
[2016-09-28 16:56:49] DEBUG [django.template:927] Exception while resolving variable 'wrapper_class' in template 'bootstrap3/field.html'.
Traceback (most recent call last):
  File "/home/alumno/Proyectos/myvenv/local/lib/python2.7/site-packages/django/template/base.py", line 905, in _resolve_lookup
    (bit, current))  # missing attribute
VariableDoesNotExist: Failed lookup for key [wrapper_class] in u'[{\'False\': False, \'None\': None, \'True\': True}, {u\'csrf_token\': <SimpleLazyObject: u\'voFYGNbri6rL3ya3aWrq3eUBvmQJi0mC\'>, \'html5_required\': False, \'perms\': <django.contrib.auth.context_processors.PermWrapper object at 0x7f2ab200b4d0>, u\'request\': <WSGIRequest: GET \'/accounts/login/\'>, \'help_text_inline\': False, \'formset_error_title\': None, \'attrs\': {\'class\': \'js-validate form-vertical\'}, u\'LANGUAGE_CODE\': u\'es\', \'include_media\': True, \'field_class\': \'\', \'is_formset\': False, \'form_action\': \'\', \'label_class\': \'\', u\'TIME_ZONE\': \'UTC\', \'form_style\': \'\', \'form_tag\': True, u\'labelclass\': None, u\'field\': <django.forms.boundfield.BoundField object at 0x7f2ab201f890>, \'disable_csrf\': False, \'form_show_errors\': True, \'form_class\': \'js-validate form-vertical\', \'True\': True, \'form_method\': \'post\', \'inputs\': [], \'None\': None, \'form_id\': \'\', \'form\': <LoginForm bound=False, valid=False, fields=(username;password;remember_me)>, \'form_show_labels\': True, \'flat_attrs\': u\'\', u\'STATIC_URL\': \'/static/\', u\'LANGUAGES\': ((\'ja\', <django.utils.functional.__proxy__ object at 0x7f2abaf8aa10>), (\'zh-tw\', <django.utils.functional.__proxy__ object at 0x7f2abaf8aa50>), (\'fr\', <django.utils.functional.__proxy__ object at 0x7f2abaf8aa90>), (\'de\', <django.utils.functional.__proxy__ object at 0x7f2abaf7dbd0>), (\'en\', <django.utils.functional.__proxy__ object at 0x7f2abaf97550>), (\'es\', <django.utils.functional.__proxy__ object at 0x7f2abaf97590>), (\'es-ar\', <django.utils.functional.__proxy__ object at 0x7f2abaf975d0>), (\'es-pe\', <django.utils.functional.__proxy__ object at 0x7f2abaf97610>), (\'pt\', <django.utils.functional.__proxy__ object at 0x7f2abaf97650>), (\'pt-br\', <django.utils.functional.__proxy__ object at 0x7f2abaf97690>)), \'user\': <SimpleLazyObject: <django.contrib.auth.models.AnonymousUser object at 0x7f2ab32be8d0>>, \'DEFAULT_MESSAGE_LEVELS\': {\'DEBUG\': 10, \'INFO\': 20, \'WARNING\': 30, \'SUCCESS\': 25, \'ERROR\': 40}, \'form_attrs\': {\'class\': \'js-validate form-vertical\'}, \'template_pack\': \'bootstrap3\', \'False\': False, \'form_error_title\': None, \'error_text_inline\': True, \'messages\': <django.contrib.messages.storage.fallback.FallbackStorage object at 0x7f2ab32bea90>, u\'LANGUAGE_BIDI\': False, u\'MEDIA_URL\': \'/media/\', \'label_size\': 0, \'block\': <Block Node: rootcontainer. Contents: [<TextNode: u\'\\n\\n<div id="shell-load">\\n \'>, <django.templatetags.i18n.TranslateNode object at 0x7f2ab200b390>, <TextNode: u\'</h3>\\n      </div>\\n      \'>, <django.template.library.SimpleNode object at 0x7f2ab200b3d0>, <TextNode: u\'\\n\\n      \'>, <crispy_forms.templatetags.crispy_forms_tags.CrispyFormNode object at 0x7f2ab200b550>, <TextNode: u\'\\n      \'>, <django.template.defaulttags.URLNode object at 0x7f2ab200b650>, <TextNode: u\'\\n      \'>, <IfNode>, <TextNode: u\'\\n      \\n    </div>\\n  </di\'>]>, u\'view\': <apps.accounts.views.LoginView object at 0x7f2ab32beb50>}]'
[2016-09-28 16:56:49] DEBUG [django.template:927] Exception while resolving variable 'tag' in template 'bootstrap3/field.html'.
Traceback (most recent call last):
  File "/home/alumno/Proyectos/myvenv/local/lib/python2.7/site-packages/django/template/base.py", line 905, in _resolve_lookup
    (bit, current))  # missing attribute
VariableDoesNotExist: Failed lookup for key [tag] in u'[{\'False\': False, \'None\': None, \'True\': True}, {u\'csrf_token\': <SimpleLazyObject: u\'voFYGNbri6rL3ya3aWrq3eUBvmQJi0mC\'>, \'html5_required\': False, \'perms\': <django.contrib.auth.context_processors.PermWrapper object at 0x7f2ab200b4d0>, u\'request\': <WSGIRequest: GET \'/accounts/login/\'>, \'help_text_inline\': False, \'formset_error_title\': None, \'attrs\': {\'class\': \'js-validate form-vertical\'}, u\'LANGUAGE_CODE\': u\'es\', \'include_media\': True, \'field_class\': \'\', \'is_formset\': False, \'form_action\': \'\', \'label_class\': \'\', u\'TIME_ZONE\': \'UTC\', \'form_style\': \'\', \'form_tag\': True, u\'labelclass\': None, u\'field\': <django.forms.boundfield.BoundField object at 0x7f2ab201f890>, \'disable_csrf\': False, \'form_show_errors\': True, \'form_class\': \'js-validate form-vertical\', \'True\': True, \'form_method\': \'post\', \'inputs\': [], \'None\': None, \'form_id\': \'\', \'form\': <LoginForm bound=False, valid=False, fields=(username;password;remember_me)>, \'form_show_labels\': True, \'flat_attrs\': u\'\', u\'STATIC_URL\': \'/static/\', u\'LANGUAGES\': ((\'ja\', <django.utils.functional.__proxy__ object at 0x7f2abaf8aa10>), (\'zh-tw\', <django.utils.functional.__proxy__ object at 0x7f2abaf8aa50>), (\'fr\', <django.utils.functional.__proxy__ object at 0x7f2abaf8aa90>), (\'de\', <django.utils.functional.__proxy__ object at 0x7f2abaf7dbd0>), (\'en\', <django.utils.functional.__proxy__ object at 0x7f2abaf97550>), (\'es\', <django.utils.functional.__proxy__ object at 0x7f2abaf97590>), (\'es-ar\', <django.utils.functional.__proxy__ object at 0x7f2abaf975d0>), (\'es-pe\', <django.utils.functional.__proxy__ object at 0x7f2abaf97610>), (\'pt\', <django.utils.functional.__proxy__ object at 0x7f2abaf97650>), (\'pt-br\', <django.utils.functional.__proxy__ object at 0x7f2abaf97690>)), \'user\': <SimpleLazyObject: <django.contrib.auth.models.AnonymousUser object at 0x7f2ab32be8d0>>, \'DEFAULT_MESSAGE_LEVELS\': {\'DEBUG\': 10, \'INFO\': 20, \'WARNING\': 30, \'SUCCESS\': 25, \'ERROR\': 40}, \'form_attrs\': {\'class\': \'js-validate form-vertical\'}, \'template_pack\': \'bootstrap3\', \'False\': False, \'form_error_title\': None, \'error_text_inline\': True, \'messages\': <django.contrib.messages.storage.fallback.FallbackStorage object at 0x7f2ab32bea90>, u\'LANGUAGE_BIDI\': False, u\'MEDIA_URL\': \'/media/\', \'label_size\': 0, \'block\': <Block Node: rootcontainer. Contents: [<TextNode: u\'\\n\\n<div id="shell-load">\\n \'>, <django.templatetags.i18n.TranslateNode object at 0x7f2ab200b390>, <TextNode: u\'</h3>\\n      </div>\\n      \'>, <django.template.library.SimpleNode object at 0x7f2ab200b3d0>, <TextNode: u\'\\n\\n      \'>, <crispy_forms.templatetags.crispy_forms_tags.CrispyFormNode object at 0x7f2ab200b550>, <TextNode: u\'\\n      \'>, <django.template.defaulttags.URLNode object at 0x7f2ab200b650>, <TextNode: u\'\\n      \'>, <IfNode>, <TextNode: u\'\\n      \\n    </div>\\n  </di\'>]>, u\'view\': <apps.accounts.views.LoginView object at 0x7f2ab32beb50>}]'
[2016-09-28 16:56:49] DEBUG [django.db.backends:89] (0.000) SELECT (1) AS "a" FROM "django_session" WHERE "django_session"."session_key" = 'sofiya3va6z3ic7px8yr71w3jovsmozs' LIMIT 1; args=(u'sofiya3va6z3ic7px8yr71w3jovsmozs',)
[2016-09-28 16:56:49] DEBUG [django.db.backends:89] (0.000) BEGIN; args=None
[2016-09-28 16:56:49] DEBUG [django.db.backends:89] (0.000) INSERT INTO "django_session" ("session_key", "session_data", "expire_date") SELECT 'sofiya3va6z3ic7px8yr71w3jovsmozs', 'NGEyZDVmNzk0YjhjMTBhZTBiNzkzZWY4NzNlOWUxYWRmZTI0NjFlNjp7InRlc3Rjb29raWUiOiJ3b3JrZWQifQ==', '2016-10-12 16:56:49.369456'; args=(u'sofiya3va6z3ic7px8yr71w3jovsmozs', u'NGEyZDVmNzk0YjhjMTBhZTBiNzkzZWY4NzNlOWUxYWRmZTI0NjFlNjp7InRlc3Rjb29raWUiOiJ3b3JrZWQifQ==', u'2016-10-12 16:56:49.369456')
[2016-09-28 16:56:49] DEBUG [django.db.backends:89] (0.001) SELECT "django_session"."session_key", "django_session"."session_data", "django_session"."expire_date" FROM "django_session" WHERE ("django_session"."session_key" = 'sofiya3va6z3ic7px8yr71w3jovsmozs' AND "django_session"."expire_date" > '2016-09-28 16:56:49.482898'); args=('sofiya3va6z3ic7px8yr71w3jovsmozs', u'2016-09-28 16:56:49.482898')
[2016-09-28 16:56:58] DEBUG [django.db.backends:89] (0.001) SELECT "django_session"."session_key", "django_session"."session_data", "django_session"."expire_date" FROM "django_session" WHERE ("django_session"."session_key" = 'sofiya3va6z3ic7px8yr71w3jovsmozs' AND "django_session"."expire_date" > '2016-09-28 16:56:58.709348'); args=('sofiya3va6z3ic7px8yr71w3jovsmozs', u'2016-09-28 16:56:58.709348')
[2016-09-28 16:56:58] WARNING [django.request:182] Not Found: /clivet
[2016-09-28 16:56:58] DEBUG [django.template:927] Exception while resolving variable 'name' in template 'unknown'.
Traceback (most recent call last):
  File "/home/alumno/Proyectos/myvenv/local/lib/python2.7/site-packages/django/template/base.py", line 905, in _resolve_lookup
    (bit, current))  # missing attribute
VariableDoesNotExist: Failed lookup for key [name] in u'<RegexURLResolver <RegexURLPattern list> (admin:admin) ^admin/>'
[2016-09-28 16:56:58] DEBUG [django.template:927] Exception while resolving variable 'name' in template 'unknown'.
Traceback (most recent call last):
  File "/home/alumno/Proyectos/myvenv/local/lib/python2.7/site-packages/django/template/base.py", line 905, in _resolve_lookup
    (bit, current))  # missing attribute
VariableDoesNotExist: Failed lookup for key [name] in u"<RegexURLResolver <module 'django.contrib.admindocs.urls' from '/home/alumno/Proyectos/myvenv/local/lib/python2.7/site-packages/django/contrib/admindocs/urls.pyc'> (None:None) ^admin/doc/>"
[2016-09-28 16:56:58] DEBUG [django.template:927] Exception while resolving variable 'name' in template 'unknown'.
Traceback (most recent call last):
  File "/home/alumno/Proyectos/myvenv/local/lib/python2.7/site-packages/django/template/base.py", line 905, in _resolve_lookup
    (bit, current))  # missing attribute
VariableDoesNotExist: Failed lookup for key [name] in u"<RegexURLResolver <module 'apps.home.urls' from '/home/alumno/Proyectos/CLIVET/apps/home/urls.pyc'> (None:home) ^home/>"
[2016-09-28 16:56:58] DEBUG [django.template:927] Exception while resolving variable 'name' in template 'unknown'.
Traceback (most recent call last):
  File "/home/alumno/Proyectos/myvenv/local/lib/python2.7/site-packages/django/template/base.py", line 905, in _resolve_lookup
    (bit, current))  # missing attribute
VariableDoesNotExist: Failed lookup for key [name] in u"<RegexURLResolver <module 'apps.space.urls' from '/home/alumno/Proyectos/CLIVET/apps/space/urls.pyc'> (None:space) ^space/>"
[2016-09-28 16:56:58] DEBUG [django.template:927] Exception while resolving variable 'name' in template 'unknown'.
Traceback (most recent call last):
  File "/home/alumno/Proyectos/myvenv/local/lib/python2.7/site-packages/django/template/base.py", line 905, in _resolve_lookup
    (bit, current))  # missing attribute
VariableDoesNotExist: Failed lookup for key [name] in u"<RegexURLResolver <module 'apps.sad.urls' from '/home/alumno/Proyectos/CLIVET/apps/sad/urls.pyc'> (None:sad) ^sad/>"
[2016-09-28 16:56:58] DEBUG [django.template:927] Exception while resolving variable 'name' in template 'unknown'.
Traceback (most recent call last):
  File "/home/alumno/Proyectos/myvenv/local/lib/python2.7/site-packages/django/template/base.py", line 905, in _resolve_lookup
    (bit, current))  # missing attribute
VariableDoesNotExist: Failed lookup for key [name] in u"<RegexURLResolver <module 'apps.mod_backend.urls' from '/home/alumno/Proyectos/CLIVET/apps/mod_backend/urls.pyc'> (None:mod_backend) ^mod_backend/>"
[2016-09-28 16:56:58] DEBUG [django.template:927] Exception while resolving variable 'name' in template 'unknown'.
Traceback (most recent call last):
  File "/home/alumno/Proyectos/myvenv/local/lib/python2.7/site-packages/django/template/base.py", line 905, in _resolve_lookup
    (bit, current))  # missing attribute
VariableDoesNotExist: Failed lookup for key [name] in u"<RegexURLResolver <module 'apps.accounts.urls' from '/home/alumno/Proyectos/CLIVET/apps/accounts/urls.pyc'> (None:None) ^accounts/>"
[2016-09-28 16:56:58] DEBUG [django.template:927] Exception while resolving variable 'name' in template 'unknown'.
Traceback (most recent call last):
  File "/home/alumno/Proyectos/myvenv/local/lib/python2.7/site-packages/django/template/base.py", line 905, in _resolve_lookup
    (bit, current))  # missing attribute
VariableDoesNotExist: Failed lookup for key [name] in u"<RegexURLResolver <module 'apps.clivet.urls' from '/home/alumno/Proyectos/CLIVET/apps/clivet/urls.pyc'> (None:None) ^clivet/>"
[2016-09-28 16:56:58] DEBUG [django.template:927] Exception while resolving variable 'name' in template 'unknown'.
Traceback (most recent call last):
  File "/home/alumno/Proyectos/myvenv/local/lib/python2.7/site-packages/django/template/base.py", line 905, in _resolve_lookup
    (bit, current))  # missing attribute
VariableDoesNotExist: Failed lookup for key [name] in u"<RegexURLResolver <module 'django.conf.urls.i18n' from '/home/alumno/Proyectos/myvenv/local/lib/python2.7/site-packages/django/conf/urls/i18n.pyc'> (None:None) ^i18n/>"
[2016-09-28 16:56:58] DEBUG [django.db.backends:89] (0.001) SELECT "django_session"."session_key", "django_session"."session_data", "django_session"."expire_date" FROM "django_session" WHERE ("django_session"."session_key" = 'sofiya3va6z3ic7px8yr71w3jovsmozs' AND "django_session"."expire_date" > '2016-09-28 16:56:58.720018'); args=('sofiya3va6z3ic7px8yr71w3jovsmozs', u'2016-09-28 16:56:58.720018')
[2016-09-28 17:08:24] WARNING [django.request:182] Not Found: /css/bootstrap.min.css
[2016-09-28 17:08:24] DEBUG [django.template:927] Exception while resolving variable 'name' in template 'unknown'.
Traceback (most recent call last):
  File "/home/alumno/Proyectos/myvenv/local/lib/python2.7/site-packages/django/template/base.py", line 905, in _resolve_lookup
    (bit, current))  # missing attribute
VariableDoesNotExist: Failed lookup for key [name] in u'<RegexURLResolver <RegexURLPattern list> (admin:admin) ^admin/>'
[2016-09-28 17:08:24] DEBUG [django.template:927] Exception while resolving variable 'name' in template 'unknown'.
Traceback (most recent call last):
  File "/home/alumno/Proyectos/myvenv/local/lib/python2.7/site-packages/django/template/base.py", line 905, in _resolve_lookup
    (bit, current))  # missing attribute
VariableDoesNotExist: Failed lookup for key [name] in u"<RegexURLResolver <module 'django.contrib.admindocs.urls' from '/home/alumno/Proyectos/myvenv/local/lib/python2.7/site-packages/django/contrib/admindocs/urls.pyc'> (None:None) ^admin/doc/>"
[2016-09-28 17:08:24] DEBUG [django.template:927] Exception while resolving variable 'name' in template 'unknown'.
Traceback (most recent call last):
  File "/home/alumno/Proyectos/myvenv/local/lib/python2.7/site-packages/django/template/base.py", line 905, in _resolve_lookup
    (bit, current))  # missing attribute
VariableDoesNotExist: Failed lookup for key [name] in u"<RegexURLResolver <module 'apps.home.urls' from '/home/alumno/Proyectos/CLIVET/apps/home/urls.pyc'> (None:home) ^home/>"
[2016-09-28 17:08:24] WARNING [django.request:182] Not Found: /css/sb-admin.css
[2016-09-28 17:08:24] DEBUG [django.template:927] Exception while resolving variable 'name' in template 'unknown'.
Traceback (most recent call last):
  File "/home/alumno/Proyectos/myvenv/local/lib/python2.7/site-packages/django/template/base.py", line 905, in _resolve_lookup
    (bit, current))  # missing attribute
VariableDoesNotExist: Failed lookup for key [name] in u"<RegexURLResolver <module 'apps.space.urls' from '/home/alumno/Proyectos/CLIVET/apps/space/urls.pyc'> (None:space) ^space/>"
[2016-09-28 17:08:24] DEBUG [django.template:927] Exception while resolving variable 'name' in template 'unknown'.
Traceback (most recent call last):
  File "/home/alumno/Proyectos/myvenv/local/lib/python2.7/site-packages/django/template/base.py", line 905, in _resolve_lookup
    (bit, current))  # missing attribute
VariableDoesNotExist: Failed lookup for key [name] in u'<RegexURLResolver <RegexURLPattern list> (admin:admin) ^admin/>'
[2016-09-28 17:08:24] WARNING [django.request:182] Not Found: /font-awesome/css/font-awesome.min.css
[2016-09-28 17:08:24] DEBUG [django.template:927] Exception while resolving variable 'name' in template 'unknown'.
Traceback (most recent call last):
  File "/home/alumno/Proyectos/myvenv/local/lib/python2.7/site-packages/django/template/base.py", line 905, in _resolve_lookup
    (bit, current))  # missing attribute
VariableDoesNotExist: Failed lookup for key [name] in u"<RegexURLResolver <module 'apps.sad.urls' from '/home/alumno/Proyectos/CLIVET/apps/sad/urls.pyc'> (None:sad) ^sad/>"
[2016-09-28 17:08:24] DEBUG [django.template:927] Exception while resolving variable 'name' in template 'unknown'.
Traceback (most recent call last):
  File "/home/alumno/Proyectos/myvenv/local/lib/python2.7/site-packages/django/template/base.py", line 905, in _resolve_lookup
    (bit, current))  # missing attribute
VariableDoesNotExist: Failed lookup for key [name] in u"<RegexURLResolver <module 'django.contrib.admindocs.urls' from '/home/alumno/Proyectos/myvenv/local/lib/python2.7/site-packages/django/contrib/admindocs/urls.pyc'> (None:None) ^admin/doc/>"
[2016-09-28 17:08:24] DEBUG [django.template:927] Exception while resolving variable 'name' in template 'unknown'.
Traceback (most recent call last):
  File "/home/alumno/Proyectos/myvenv/local/lib/python2.7/site-packages/django/template/base.py", line 905, in _resolve_lookup
    (bit, current))  # missing attribute
VariableDoesNotExist: Failed lookup for key [name] in u'<RegexURLResolver <RegexURLPattern list> (admin:admin) ^admin/>'
[2016-09-28 17:08:24] DEBUG [django.template:927] Exception while resolving variable 'name' in template 'unknown'.
Traceback (most recent call last):
  File "/home/alumno/Proyectos/myvenv/local/lib/python2.7/site-packages/django/template/base.py", line 905, in _resolve_lookup
    (bit, current))  # missing attribute
VariableDoesNotExist: Failed lookup for key [name] in u"<RegexURLResolver <module 'apps.mod_backend.urls' from '/home/alumno/Proyectos/CLIVET/apps/mod_backend/urls.pyc'> (None:mod_backend) ^mod_backend/>"
[2016-09-28 17:08:24] DEBUG [django.template:927] Exception while resolving variable 'name' in template 'unknown'.
Traceback (most recent call last):
  File "/home/alumno/Proyectos/myvenv/local/lib/python2.7/site-packages/django/template/base.py", line 905, in _resolve_lookup
    (bit, current))  # missing attribute
VariableDoesNotExist: Failed lookup for key [name] in u"<RegexURLResolver <module 'apps.home.urls' from '/home/alumno/Proyectos/CLIVET/apps/home/urls.pyc'> (None:home) ^home/>"
[2016-09-28 17:08:24] DEBUG [django.template:927] Exception while resolving variable 'name' in template 'unknown'.
Traceback (most recent call last):
  File "/home/alumno/Proyectos/myvenv/local/lib/python2.7/site-packages/django/template/base.py", line 905, in _resolve_lookup
    (bit, current))  # missing attribute
VariableDoesNotExist: Failed lookup for key [name] in u"<RegexURLResolver <module 'django.contrib.admindocs.urls' from '/home/alumno/Proyectos/myvenv/local/lib/python2.7/site-packages/django/contrib/admindocs/urls.pyc'> (None:None) ^admin/doc/>"
[2016-09-28 17:08:24] DEBUG [django.template:927] Exception while resolving variable 'name' in template 'unknown'.
Traceback (most recent call last):
  File "/home/alumno/Proyectos/myvenv/local/lib/python2.7/site-packages/django/template/base.py", line 905, in _resolve_lookup
    (bit, current))  # missing attribute
VariableDoesNotExist: Failed lookup for key [name] in u"<RegexURLResolver <module 'apps.accounts.urls' from '/home/alumno/Proyectos/CLIVET/apps/accounts/urls.pyc'> (None:None) ^accounts/>"
[2016-09-28 17:08:24] DEBUG [django.template:927] Exception while resolving variable 'name' in template 'unknown'.
Traceback (most recent call last):
  File "/home/alumno/Proyectos/myvenv/local/lib/python2.7/site-packages/django/template/base.py", line 905, in _resolve_lookup
    (bit, current))  # missing attribute
VariableDoesNotExist: Failed lookup for key [name] in u"<RegexURLResolver <module 'apps.space.urls' from '/home/alumno/Proyectos/CLIVET/apps/space/urls.pyc'> (None:space) ^space/>"
[2016-09-28 17:08:24] DEBUG [django.template:927] Exception while resolving variable 'name' in template 'unknown'.
Traceback (most recent call last):
  File "/home/alumno/Proyectos/myvenv/local/lib/python2.7/site-packages/django/template/base.py", line 905, in _resolve_lookup
    (bit, current))  # missing attribute
VariableDoesNotExist: Failed lookup for key [name] in u"<RegexURLResolver <module 'apps.home.urls' from '/home/alumno/Proyectos/CLIVET/apps/home/urls.pyc'> (None:home) ^home/>"
[2016-09-28 17:08:24] DEBUG [django.template:927] Exception while resolving variable 'name' in template 'unknown'.
Traceback (most recent call last):
  File "/home/alumno/Proyectos/myvenv/local/lib/python2.7/site-packages/django/template/base.py", line 905, in _resolve_lookup
    (bit, current))  # missing attribute
VariableDoesNotExist: Failed lookup for key [name] in u"<RegexURLResolver <module 'apps.clivet.urls' from '/home/alumno/Proyectos/CLIVET/apps/clivet/urls.pyc'> (None:None) ^clivet/>"
[2016-09-28 17:08:24] DEBUG [django.template:927] Exception while resolving variable 'name' in template 'unknown'.
Traceback (most recent call last):
  File "/home/alumno/Proyectos/myvenv/local/lib/python2.7/site-packages/django/template/base.py", line 905, in _resolve_lookup
    (bit, current))  # missing attribute
VariableDoesNotExist: Failed lookup for key [name] in u"<RegexURLResolver <module 'apps.sad.urls' from '/home/alumno/Proyectos/CLIVET/apps/sad/urls.pyc'> (None:sad) ^sad/>"
[2016-09-28 17:08:24] DEBUG [django.template:927] Exception while resolving variable 'name' in template 'unknown'.
Traceback (most recent call last):
  File "/home/alumno/Proyectos/myvenv/local/lib/python2.7/site-packages/django/template/base.py", line 905, in _resolve_lookup
    (bit, current))  # missing attribute
VariableDoesNotExist: Failed lookup for key [name] in u"<RegexURLResolver <module 'apps.space.urls' from '/home/alumno/Proyectos/CLIVET/apps/space/urls.pyc'> (None:space) ^space/>"
[2016-09-28 17:08:24] DEBUG [django.template:927] Exception while resolving variable 'name' in template 'unknown'.
Traceback (most recent call last):
  File "/home/alumno/Proyectos/myvenv/local/lib/python2.7/site-packages/django/template/base.py", line 905, in _resolve_lookup
    (bit, current))  # missing attribute
VariableDoesNotExist: Failed lookup for key [name] in u"<RegexURLResolver <module 'django.conf.urls.i18n' from '/home/alumno/Proyectos/myvenv/local/lib/python2.7/site-packages/django/conf/urls/i18n.pyc'> (None:None) ^i18n/>"
[2016-09-28 17:08:24] DEBUG [django.template:927] Exception while resolving variable 'name' in template 'unknown'.
Traceback (most recent call last):
  File "/home/alumno/Proyectos/myvenv/local/lib/python2.7/site-packages/django/template/base.py", line 905, in _resolve_lookup
    (bit, current))  # missing attribute
VariableDoesNotExist: Failed lookup for key [name] in u"<RegexURLResolver <module 'apps.mod_backend.urls' from '/home/alumno/Proyectos/CLIVET/apps/mod_backend/urls.pyc'> (None:mod_backend) ^mod_backend/>"
[2016-09-28 17:08:24] DEBUG [django.template:927] Exception while resolving variable 'name' in template 'unknown'.
Traceback (most recent call last):
  File "/home/alumno/Proyectos/myvenv/local/lib/python2.7/site-packages/django/template/base.py", line 905, in _resolve_lookup
    (bit, current))  # missing attribute
VariableDoesNotExist: Failed lookup for key [name] in u"<RegexURLResolver <module 'apps.sad.urls' from '/home/alumno/Proyectos/CLIVET/apps/sad/urls.pyc'> (None:sad) ^sad/>"
[2016-09-28 17:08:24] DEBUG [django.template:927] Exception while resolving variable 'name' in template 'unknown'.
Traceback (most recent call last):
  File "/home/alumno/Proyectos/myvenv/local/lib/python2.7/site-packages/django/template/base.py", line 905, in _resolve_lookup
    (bit, current))  # missing attribute
VariableDoesNotExist: Failed lookup for key [name] in u"<RegexURLResolver <module 'apps.accounts.urls' from '/home/alumno/Proyectos/CLIVET/apps/accounts/urls.pyc'> (None:None) ^accounts/>"
[2016-09-28 17:08:24] DEBUG [django.template:927] Exception while resolving variable 'name' in template 'unknown'.
Traceback (most recent call last):
  File "/home/alumno/Proyectos/myvenv/local/lib/python2.7/site-packages/django/template/base.py", line 905, in _resolve_lookup
    (bit, current))  # missing attribute
VariableDoesNotExist: Failed lookup for key [name] in u"<RegexURLResolver <module 'apps.clivet.urls' from '/home/alumno/Proyectos/CLIVET/apps/clivet/urls.pyc'> (None:None) ^clivet/>"
[2016-09-28 17:08:24] DEBUG [django.template:927] Exception while resolving variable 'name' in template 'unknown'.
Traceback (most recent call last):
  File "/home/alumno/Proyectos/myvenv/local/lib/python2.7/site-packages/django/template/base.py", line 905, in _resolve_lookup
    (bit, current))  # missing attribute
VariableDoesNotExist: Failed lookup for key [name] in u"<RegexURLResolver <module 'django.conf.urls.i18n' from '/home/alumno/Proyectos/myvenv/local/lib/python2.7/site-packages/django/conf/urls/i18n.pyc'> (None:None) ^i18n/>"
[2016-09-28 17:08:24] DEBUG [django.template:927] Exception while resolving variable 'name' in template 'unknown'.
Traceback (most recent call last):
  File "/home/alumno/Proyectos/myvenv/local/lib/python2.7/site-packages/django/template/base.py", line 905, in _resolve_lookup
    (bit, current))  # missing attribute
VariableDoesNotExist: Failed lookup for key [name] in u"<RegexURLResolver <module 'apps.mod_backend.urls' from '/home/alumno/Proyectos/CLIVET/apps/mod_backend/urls.pyc'> (None:mod_backend) ^mod_backend/>"
[2016-09-28 17:08:24] DEBUG [django.template:927] Exception while resolving variable 'name' in template 'unknown'.
Traceback (most recent call last):
  File "/home/alumno/Proyectos/myvenv/local/lib/python2.7/site-packages/django/template/base.py", line 905, in _resolve_lookup
    (bit, current))  # missing attribute
VariableDoesNotExist: Failed lookup for key [name] in u"<RegexURLResolver <module 'apps.accounts.urls' from '/home/alumno/Proyectos/CLIVET/apps/accounts/urls.pyc'> (None:None) ^accounts/>"
[2016-09-28 17:08:24] DEBUG [django.template:927] Exception while resolving variable 'name' in template 'unknown'.
Traceback (most recent call last):
  File "/home/alumno/Proyectos/myvenv/local/lib/python2.7/site-packages/django/template/base.py", line 905, in _resolve_lookup
    (bit, current))  # missing attribute
VariableDoesNotExist: Failed lookup for key [name] in u"<RegexURLResolver <module 'apps.clivet.urls' from '/home/alumno/Proyectos/CLIVET/apps/clivet/urls.pyc'> (None:None) ^clivet/>"
[2016-09-28 17:08:24] DEBUG [django.template:927] Exception while resolving variable 'name' in template 'unknown'.
Traceback (most recent call last):
  File "/home/alumno/Proyectos/myvenv/local/lib/python2.7/site-packages/django/template/base.py", line 905, in _resolve_lookup
    (bit, current))  # missing attribute
VariableDoesNotExist: Failed lookup for key [name] in u"<RegexURLResolver <module 'django.conf.urls.i18n' from '/home/alumno/Proyectos/myvenv/local/lib/python2.7/site-packages/django/conf/urls/i18n.pyc'> (None:None) ^i18n/>"
[2016-09-28 17:09:00] DEBUG [django.db.backends:89] (0.001) SELECT "django_session"."session_key", "django_session"."session_data", "django_session"."expire_date" FROM "django_session" WHERE ("django_session"."session_key" = 'sofiya3va6z3ic7px8yr71w3jovsmozs' AND "django_session"."expire_date" > '2016-09-28 17:09:00.884443'); args=('sofiya3va6z3ic7px8yr71w3jovsmozs', u'2016-09-28 17:09:00.884443')
[2016-09-28 17:13:49] WARNING [django.request:182] Not Found: /index.html
[2016-09-28 17:13:49] DEBUG [django.template:927] Exception while resolving variable 'name' in template 'unknown'.
Traceback (most recent call last):
  File "/home/alumno/Proyectos/myvenv/local/lib/python2.7/site-packages/django/template/base.py", line 905, in _resolve_lookup
    (bit, current))  # missing attribute
VariableDoesNotExist: Failed lookup for key [name] in u'<RegexURLResolver <RegexURLPattern list> (admin:admin) ^admin/>'
[2016-09-28 17:13:49] DEBUG [django.template:927] Exception while resolving variable 'name' in template 'unknown'.
Traceback (most recent call last):
  File "/home/alumno/Proyectos/myvenv/local/lib/python2.7/site-packages/django/template/base.py", line 905, in _resolve_lookup
    (bit, current))  # missing attribute
VariableDoesNotExist: Failed lookup for key [name] in u"<RegexURLResolver <module 'django.contrib.admindocs.urls' from '/home/alumno/Proyectos/myvenv/local/lib/python2.7/site-packages/django/contrib/admindocs/urls.pyc'> (None:None) ^admin/doc/>"
[2016-09-28 17:13:49] DEBUG [django.template:927] Exception while resolving variable 'name' in template 'unknown'.
Traceback (most recent call last):
  File "/home/alumno/Proyectos/myvenv/local/lib/python2.7/site-packages/django/template/base.py", line 905, in _resolve_lookup
    (bit, current))  # missing attribute
VariableDoesNotExist: Failed lookup for key [name] in u"<RegexURLResolver <module 'apps.home.urls' from '/home/alumno/Proyectos/CLIVET/apps/home/urls.pyc'> (None:home) ^home/>"
[2016-09-28 17:13:49] DEBUG [django.template:927] Exception while resolving variable 'name' in template 'unknown'.
Traceback (most recent call last):
  File "/home/alumno/Proyectos/myvenv/local/lib/python2.7/site-packages/django/template/base.py", line 905, in _resolve_lookup
    (bit, current))  # missing attribute
VariableDoesNotExist: Failed lookup for key [name] in u"<RegexURLResolver <module 'apps.space.urls' from '/home/alumno/Proyectos/CLIVET/apps/space/urls.pyc'> (None:space) ^space/>"
[2016-09-28 17:13:49] DEBUG [django.template:927] Exception while resolving variable 'name' in template 'unknown'.
Traceback (most recent call last):
  File "/home/alumno/Proyectos/myvenv/local/lib/python2.7/site-packages/django/template/base.py", line 905, in _resolve_lookup
    (bit, current))  # missing attribute
VariableDoesNotExist: Failed lookup for key [name] in u"<RegexURLResolver <module 'apps.sad.urls' from '/home/alumno/Proyectos/CLIVET/apps/sad/urls.pyc'> (None:sad) ^sad/>"
[2016-09-28 17:13:49] DEBUG [django.template:927] Exception while resolving variable 'name' in template 'unknown'.
Traceback (most recent call last):
  File "/home/alumno/Proyectos/myvenv/local/lib/python2.7/site-packages/django/template/base.py", line 905, in _resolve_lookup
    (bit, current))  # missing attribute
VariableDoesNotExist: Failed lookup for key [name] in u"<RegexURLResolver <module 'apps.mod_backend.urls' from '/home/alumno/Proyectos/CLIVET/apps/mod_backend/urls.pyc'> (None:mod_backend) ^mod_backend/>"
[2016-09-28 17:13:49] DEBUG [django.template:927] Exception while resolving variable 'name' in template 'unknown'.
Traceback (most recent call last):
  File "/home/alumno/Proyectos/myvenv/local/lib/python2.7/site-packages/django/template/base.py", line 905, in _resolve_lookup
    (bit, current))  # missing attribute
VariableDoesNotExist: Failed lookup for key [name] in u"<RegexURLResolver <module 'apps.accounts.urls' from '/home/alumno/Proyectos/CLIVET/apps/accounts/urls.pyc'> (None:None) ^accounts/>"
[2016-09-28 17:13:49] DEBUG [django.template:927] Exception while resolving variable 'name' in template 'unknown'.
Traceback (most recent call last):
  File "/home/alumno/Proyectos/myvenv/local/lib/python2.7/site-packages/django/template/base.py", line 905, in _resolve_lookup
    (bit, current))  # missing attribute
VariableDoesNotExist: Failed lookup for key [name] in u"<RegexURLResolver <module 'apps.clivet.urls' from '/home/alumno/Proyectos/CLIVET/apps/clivet/urls.pyc'> (None:None) ^clivet/>"
[2016-09-28 17:13:49] DEBUG [django.template:927] Exception while resolving variable 'name' in template 'unknown'.
Traceback (most recent call last):
  File "/home/alumno/Proyectos/myvenv/local/lib/python2.7/site-packages/django/template/base.py", line 905, in _resolve_lookup
    (bit, current))  # missing attribute
VariableDoesNotExist: Failed lookup for key [name] in u"<RegexURLResolver <module 'django.conf.urls.i18n' from '/home/alumno/Proyectos/myvenv/local/lib/python2.7/site-packages/django/conf/urls/i18n.pyc'> (None:None) ^i18n/>"
[2016-09-28 17:13:50] WARNING [django.request:182] Not Found: /index.html
[2016-09-28 17:13:50] DEBUG [django.template:927] Exception while resolving variable 'name' in template 'unknown'.
Traceback (most recent call last):
  File "/home/alumno/Proyectos/myvenv/local/lib/python2.7/site-packages/django/template/base.py", line 905, in _resolve_lookup
    (bit, current))  # missing attribute
VariableDoesNotExist: Failed lookup for key [name] in u'<RegexURLResolver <RegexURLPattern list> (admin:admin) ^admin/>'
[2016-09-28 17:13:50] DEBUG [django.template:927] Exception while resolving variable 'name' in template 'unknown'.
Traceback (most recent call last):
  File "/home/alumno/Proyectos/myvenv/local/lib/python2.7/site-packages/django/template/base.py", line 905, in _resolve_lookup
    (bit, current))  # missing attribute
VariableDoesNotExist: Failed lookup for key [name] in u"<RegexURLResolver <module 'django.contrib.admindocs.urls' from '/home/alumno/Proyectos/myvenv/local/lib/python2.7/site-packages/django/contrib/admindocs/urls.pyc'> (None:None) ^admin/doc/>"
[2016-09-28 17:13:50] DEBUG [django.template:927] Exception while resolving variable 'name' in template 'unknown'.
Traceback (most recent call last):
  File "/home/alumno/Proyectos/myvenv/local/lib/python2.7/site-packages/django/template/base.py", line 905, in _resolve_lookup
    (bit, current))  # missing attribute
VariableDoesNotExist: Failed lookup for key [name] in u"<RegexURLResolver <module 'apps.home.urls' from '/home/alumno/Proyectos/CLIVET/apps/home/urls.pyc'> (None:home) ^home/>"
[2016-09-28 17:13:50] DEBUG [django.template:927] Exception while resolving variable 'name' in template 'unknown'.
Traceback (most recent call last):
  File "/home/alumno/Proyectos/myvenv/local/lib/python2.7/site-packages/django/template/base.py", line 905, in _resolve_lookup
    (bit, current))  # missing attribute
VariableDoesNotExist: Failed lookup for key [name] in u"<RegexURLResolver <module 'apps.space.urls' from '/home/alumno/Proyectos/CLIVET/apps/space/urls.pyc'> (None:space) ^space/>"
[2016-09-28 17:13:50] DEBUG [django.template:927] Exception while resolving variable 'name' in template 'unknown'.
Traceback (most recent call last):
  File "/home/alumno/Proyectos/myvenv/local/lib/python2.7/site-packages/django/template/base.py", line 905, in _resolve_lookup
    (bit, current))  # missing attribute
VariableDoesNotExist: Failed lookup for key [name] in u"<RegexURLResolver <module 'apps.sad.urls' from '/home/alumno/Proyectos/CLIVET/apps/sad/urls.pyc'> (None:sad) ^sad/>"
[2016-09-28 17:13:50] DEBUG [django.template:927] Exception while resolving variable 'name' in template 'unknown'.
Traceback (most recent call last):
  File "/home/alumno/Proyectos/myvenv/local/lib/python2.7/site-packages/django/template/base.py", line 905, in _resolve_lookup
    (bit, current))  # missing attribute
VariableDoesNotExist: Failed lookup for key [name] in u"<RegexURLResolver <module 'apps.mod_backend.urls' from '/home/alumno/Proyectos/CLIVET/apps/mod_backend/urls.pyc'> (None:mod_backend) ^mod_backend/>"
[2016-09-28 17:13:50] DEBUG [django.template:927] Exception while resolving variable 'name' in template 'unknown'.
Traceback (most recent call last):
  File "/home/alumno/Proyectos/myvenv/local/lib/python2.7/site-packages/django/template/base.py", line 905, in _resolve_lookup
    (bit, current))  # missing attribute
VariableDoesNotExist: Failed lookup for key [name] in u"<RegexURLResolver <module 'apps.accounts.urls' from '/home/alumno/Proyectos/CLIVET/apps/accounts/urls.pyc'> (None:None) ^accounts/>"
[2016-09-28 17:13:50] DEBUG [django.template:927] Exception while resolving variable 'name' in template 'unknown'.
Traceback (most recent call last):
  File "/home/alumno/Proyectos/myvenv/local/lib/python2.7/site-packages/django/template/base.py", line 905, in _resolve_lookup
    (bit, current))  # missing attribute
VariableDoesNotExist: Failed lookup for key [name] in u"<RegexURLResolver <module 'apps.clivet.urls' from '/home/alumno/Proyectos/CLIVET/apps/clivet/urls.pyc'> (None:None) ^clivet/>"
[2016-09-28 17:13:50] DEBUG [django.template:927] Exception while resolving variable 'name' in template 'unknown'.
Traceback (most recent call last):
  File "/home/alumno/Proyectos/myvenv/local/lib/python2.7/site-packages/django/template/base.py", line 905, in _resolve_lookup
    (bit, current))  # missing attribute
VariableDoesNotExist: Failed lookup for key [name] in u"<RegexURLResolver <module 'django.conf.urls.i18n' from '/home/alumno/Proyectos/myvenv/local/lib/python2.7/site-packages/django/conf/urls/i18n.pyc'> (None:None) ^i18n/>"
[2016-09-28 17:13:58] WARNING [django.request:182] Not Found: /index.html
[2016-09-28 17:13:58] DEBUG [django.template:927] Exception while resolving variable 'name' in template 'unknown'.
Traceback (most recent call last):
  File "/home/alumno/Proyectos/myvenv/local/lib/python2.7/site-packages/django/template/base.py", line 905, in _resolve_lookup
    (bit, current))  # missing attribute
VariableDoesNotExist: Failed lookup for key [name] in u'<RegexURLResolver <RegexURLPattern list> (admin:admin) ^admin/>'
[2016-09-28 17:13:58] DEBUG [django.template:927] Exception while resolving variable 'name' in template 'unknown'.
Traceback (most recent call last):
  File "/home/alumno/Proyectos/myvenv/local/lib/python2.7/site-packages/django/template/base.py", line 905, in _resolve_lookup
    (bit, current))  # missing attribute
VariableDoesNotExist: Failed lookup for key [name] in u"<RegexURLResolver <module 'django.contrib.admindocs.urls' from '/home/alumno/Proyectos/myvenv/local/lib/python2.7/site-packages/django/contrib/admindocs/urls.pyc'> (None:None) ^admin/doc/>"
[2016-09-28 17:13:58] DEBUG [django.template:927] Exception while resolving variable 'name' in template 'unknown'.
Traceback (most recent call last):
  File "/home/alumno/Proyectos/myvenv/local/lib/python2.7/site-packages/django/template/base.py", line 905, in _resolve_lookup
    (bit, current))  # missing attribute
VariableDoesNotExist: Failed lookup for key [name] in u"<RegexURLResolver <module 'apps.home.urls' from '/home/alumno/Proyectos/CLIVET/apps/home/urls.pyc'> (None:home) ^home/>"
[2016-09-28 17:13:58] DEBUG [django.template:927] Exception while resolving variable 'name' in template 'unknown'.
Traceback (most recent call last):
  File "/home/alumno/Proyectos/myvenv/local/lib/python2.7/site-packages/django/template/base.py", line 905, in _resolve_lookup
    (bit, current))  # missing attribute
VariableDoesNotExist: Failed lookup for key [name] in u"<RegexURLResolver <module 'apps.space.urls' from '/home/alumno/Proyectos/CLIVET/apps/space/urls.pyc'> (None:space) ^space/>"
[2016-09-28 17:13:58] DEBUG [django.template:927] Exception while resolving variable 'name' in template 'unknown'.
Traceback (most recent call last):
  File "/home/alumno/Proyectos/myvenv/local/lib/python2.7/site-packages/django/template/base.py", line 905, in _resolve_lookup
    (bit, current))  # missing attribute
VariableDoesNotExist: Failed lookup for key [name] in u"<RegexURLResolver <module 'apps.sad.urls' from '/home/alumno/Proyectos/CLIVET/apps/sad/urls.pyc'> (None:sad) ^sad/>"
[2016-09-28 17:13:58] DEBUG [django.template:927] Exception while resolving variable 'name' in template 'unknown'.
Traceback (most recent call last):
  File "/home/alumno/Proyectos/myvenv/local/lib/python2.7/site-packages/django/template/base.py", line 905, in _resolve_lookup
    (bit, current))  # missing attribute
VariableDoesNotExist: Failed lookup for key [name] in u"<RegexURLResolver <module 'apps.mod_backend.urls' from '/home/alumno/Proyectos/CLIVET/apps/mod_backend/urls.pyc'> (None:mod_backend) ^mod_backend/>"
[2016-09-28 17:13:58] DEBUG [django.template:927] Exception while resolving variable 'name' in template 'unknown'.
Traceback (most recent call last):
  File "/home/alumno/Proyectos/myvenv/local/lib/python2.7/site-packages/django/template/base.py", line 905, in _resolve_lookup
    (bit, current))  # missing attribute
VariableDoesNotExist: Failed lookup for key [name] in u"<RegexURLResolver <module 'apps.accounts.urls' from '/home/alumno/Proyectos/CLIVET/apps/accounts/urls.pyc'> (None:None) ^accounts/>"
[2016-09-28 17:13:58] DEBUG [django.template:927] Exception while resolving variable 'name' in template 'unknown'.
Traceback (most recent call last):
  File "/home/alumno/Proyectos/myvenv/local/lib/python2.7/site-packages/django/template/base.py", line 905, in _resolve_lookup
    (bit, current))  # missing attribute
VariableDoesNotExist: Failed lookup for key [name] in u"<RegexURLResolver <module 'apps.clivet.urls' from '/home/alumno/Proyectos/CLIVET/apps/clivet/urls.pyc'> (None:None) ^clivet/>"
[2016-09-28 17:13:58] DEBUG [django.template:927] Exception while resolving variable 'name' in template 'unknown'.
Traceback (most recent call last):
  File "/home/alumno/Proyectos/myvenv/local/lib/python2.7/site-packages/django/template/base.py", line 905, in _resolve_lookup
    (bit, current))  # missing attribute
VariableDoesNotExist: Failed lookup for key [name] in u"<RegexURLResolver <module 'django.conf.urls.i18n' from '/home/alumno/Proyectos/myvenv/local/lib/python2.7/site-packages/django/conf/urls/i18n.pyc'> (None:None) ^i18n/>"
[2016-09-28 17:13:58] WARNING [django.request:182] Not Found: /index.html
[2016-09-28 17:13:58] DEBUG [django.template:927] Exception while resolving variable 'name' in template 'unknown'.
Traceback (most recent call last):
  File "/home/alumno/Proyectos/myvenv/local/lib/python2.7/site-packages/django/template/base.py", line 905, in _resolve_lookup
    (bit, current))  # missing attribute
VariableDoesNotExist: Failed lookup for key [name] in u'<RegexURLResolver <RegexURLPattern list> (admin:admin) ^admin/>'
[2016-09-28 17:13:58] DEBUG [django.template:927] Exception while resolving variable 'name' in template 'unknown'.
Traceback (most recent call last):
  File "/home/alumno/Proyectos/myvenv/local/lib/python2.7/site-packages/django/template/base.py", line 905, in _resolve_lookup
    (bit, current))  # missing attribute
VariableDoesNotExist: Failed lookup for key [name] in u"<RegexURLResolver <module 'django.contrib.admindocs.urls' from '/home/alumno/Proyectos/myvenv/local/lib/python2.7/site-packages/django/contrib/admindocs/urls.pyc'> (None:None) ^admin/doc/>"
[2016-09-28 17:13:58] DEBUG [django.template:927] Exception while resolving variable 'name' in template 'unknown'.
Traceback (most recent call last):
  File "/home/alumno/Proyectos/myvenv/local/lib/python2.7/site-packages/django/template/base.py", line 905, in _resolve_lookup
    (bit, current))  # missing attribute
VariableDoesNotExist: Failed lookup for key [name] in u"<RegexURLResolver <module 'apps.home.urls' from '/home/alumno/Proyectos/CLIVET/apps/home/urls.pyc'> (None:home) ^home/>"
[2016-09-28 17:13:58] DEBUG [django.template:927] Exception while resolving variable 'name' in template 'unknown'.
Traceback (most recent call last):
  File "/home/alumno/Proyectos/myvenv/local/lib/python2.7/site-packages/django/template/base.py", line 905, in _resolve_lookup
    (bit, current))  # missing attribute
VariableDoesNotExist: Failed lookup for key [name] in u"<RegexURLResolver <module 'apps.space.urls' from '/home/alumno/Proyectos/CLIVET/apps/space/urls.pyc'> (None:space) ^space/>"
[2016-09-28 17:13:58] DEBUG [django.template:927] Exception while resolving variable 'name' in template 'unknown'.
Traceback (most recent call last):
  File "/home/alumno/Proyectos/myvenv/local/lib/python2.7/site-packages/django/template/base.py", line 905, in _resolve_lookup
    (bit, current))  # missing attribute
VariableDoesNotExist: Failed lookup for key [name] in u"<RegexURLResolver <module 'apps.sad.urls' from '/home/alumno/Proyectos/CLIVET/apps/sad/urls.pyc'> (None:sad) ^sad/>"
[2016-09-28 17:13:58] DEBUG [django.template:927] Exception while resolving variable 'name' in template 'unknown'.
Traceback (most recent call last):
  File "/home/alumno/Proyectos/myvenv/local/lib/python2.7/site-packages/django/template/base.py", line 905, in _resolve_lookup
    (bit, current))  # missing attribute
VariableDoesNotExist: Failed lookup for key [name] in u"<RegexURLResolver <module 'apps.mod_backend.urls' from '/home/alumno/Proyectos/CLIVET/apps/mod_backend/urls.pyc'> (None:mod_backend) ^mod_backend/>"
[2016-09-28 17:13:58] DEBUG [django.template:927] Exception while resolving variable 'name' in template 'unknown'.
Traceback (most recent call last):
  File "/home/alumno/Proyectos/myvenv/local/lib/python2.7/site-packages/django/template/base.py", line 905, in _resolve_lookup
    (bit, current))  # missing attribute
VariableDoesNotExist: Failed lookup for key [name] in u"<RegexURLResolver <module 'apps.accounts.urls' from '/home/alumno/Proyectos/CLIVET/apps/accounts/urls.pyc'> (None:None) ^accounts/>"
[2016-09-28 17:13:58] DEBUG [django.template:927] Exception while resolving variable 'name' in template 'unknown'.
Traceback (most recent call last):
  File "/home/alumno/Proyectos/myvenv/local/lib/python2.7/site-packages/django/template/base.py", line 905, in _resolve_lookup
    (bit, current))  # missing attribute
VariableDoesNotExist: Failed lookup for key [name] in u"<RegexURLResolver <module 'apps.clivet.urls' from '/home/alumno/Proyectos/CLIVET/apps/clivet/urls.pyc'> (None:None) ^clivet/>"
[2016-09-28 17:13:58] DEBUG [django.template:927] Exception while resolving variable 'name' in template 'unknown'.
Traceback (most recent call last):
  File "/home/alumno/Proyectos/myvenv/local/lib/python2.7/site-packages/django/template/base.py", line 905, in _resolve_lookup
    (bit, current))  # missing attribute
VariableDoesNotExist: Failed lookup for key [name] in u"<RegexURLResolver <module 'django.conf.urls.i18n' from '/home/alumno/Proyectos/myvenv/local/lib/python2.7/site-packages/django/conf/urls/i18n.pyc'> (None:None) ^i18n/>"
[2016-09-28 17:14:05] DEBUG [django.template:927] Exception while resolving variable 'redirect_to' in template 'home/index.html'.
Traceback (most recent call last):
  File "/home/alumno/Proyectos/myvenv/local/lib/python2.7/site-packages/django/template/base.py", line 905, in _resolve_lookup
    (bit, current))  # missing attribute
VariableDoesNotExist: Failed lookup for key [redirect_to] in u"[{'False': False, 'None': None, 'True': True}, {u'csrf_token': <SimpleLazyObject: u'wLqas35aO5bkeyr3zn4MEg2VWNtQtbay'>, 'perms': <django.contrib.auth.context_processors.PermWrapper object at 0x7f2ab1797710>, u'request': <WSGIRequest: GET '/'>, 'messages': <django.contrib.messages.storage.fallback.FallbackStorage object at 0x7f2ab1797490>, u'TIME_ZONE': 'UTC', u'STATIC_URL': '/static/', u'LANGUAGES': (('ja', <django.utils.functional.__proxy__ object at 0x7f2abaf8aa10>), ('zh-tw', <django.utils.functional.__proxy__ object at 0x7f2abaf8aa50>), ('fr', <django.utils.functional.__proxy__ object at 0x7f2abaf8aa90>), ('de', <django.utils.functional.__proxy__ object at 0x7f2abaf7dbd0>), ('en', <django.utils.functional.__proxy__ object at 0x7f2abaf97550>), ('es', <django.utils.functional.__proxy__ object at 0x7f2abaf97590>), ('es-ar', <django.utils.functional.__proxy__ object at 0x7f2abaf975d0>), ('es-pe', <django.utils.functional.__proxy__ object at 0x7f2abaf97610>), ('pt', <django.utils.functional.__proxy__ object at 0x7f2abaf97650>), ('pt-br', <django.utils.functional.__proxy__ object at 0x7f2abaf97690>)), 'user': <SimpleLazyObject: <function <lambda> at 0x7f2ab32b68c0>>, u'LANGUAGE_CODE': u'es', 'DEFAULT_MESSAGE_LEVELS': {'DEBUG': 10, 'INFO': 20, 'WARNING': 30, 'SUCCESS': 25, 'ERROR': 40}, u'LANGUAGE_BIDI': False, u'MEDIA_URL': '/media/'}, {}, {'page_title': u'Home Page.', 'page_module': u'Inicio'}, {'block': <Block Node: header. Contents: [<TextNode: u'\\n'>, <django.template.loader_tags.IncludeNode object at 0x7f2ab178efd0>, <TextNode: u'\\n'>]>}, {}]"
[2016-09-28 17:14:05] DEBUG [django.template:927] Exception while resolving variable 'userx' in template 'home/index.html'.
Traceback (most recent call last):
  File "/home/alumno/Proyectos/myvenv/local/lib/python2.7/site-packages/django/template/base.py", line 905, in _resolve_lookup
    (bit, current))  # missing attribute
VariableDoesNotExist: Failed lookup for key [userx] in u"[{'False': False, 'None': None, 'True': True}, {u'csrf_token': <SimpleLazyObject: u'wLqas35aO5bkeyr3zn4MEg2VWNtQtbay'>, 'perms': <django.contrib.auth.context_processors.PermWrapper object at 0x7f2ab1797710>, u'request': <WSGIRequest: GET '/'>, 'messages': <django.contrib.messages.storage.fallback.FallbackStorage object at 0x7f2ab1797490>, u'TIME_ZONE': 'UTC', u'STATIC_URL': '/static/', u'LANGUAGES': (('ja', <django.utils.functional.__proxy__ object at 0x7f2abaf8aa10>), ('zh-tw', <django.utils.functional.__proxy__ object at 0x7f2abaf8aa50>), ('fr', <django.utils.functional.__proxy__ object at 0x7f2abaf8aa90>), ('de', <django.utils.functional.__proxy__ object at 0x7f2abaf7dbd0>), ('en', <django.utils.functional.__proxy__ object at 0x7f2abaf97550>), ('es', <django.utils.functional.__proxy__ object at 0x7f2abaf97590>), ('es-ar', <django.utils.functional.__proxy__ object at 0x7f2abaf975d0>), ('es-pe', <django.utils.functional.__proxy__ object at 0x7f2abaf97610>), ('pt', <django.utils.functional.__proxy__ object at 0x7f2abaf97650>), ('pt-br', <django.utils.functional.__proxy__ object at 0x7f2abaf97690>)), 'user': <SimpleLazyObject: <function <lambda> at 0x7f2ab32b68c0>>, u'LANGUAGE_CODE': u'es', 'DEFAULT_MESSAGE_LEVELS': {'DEBUG': 10, 'INFO': 20, 'WARNING': 30, 'SUCCESS': 25, 'ERROR': 40}, u'LANGUAGE_BIDI': False, u'MEDIA_URL': '/media/'}, {}, {'page_title': u'Home Page.', 'page_module': u'Inicio'}, {'block': <Block Node: header. Contents: [<TextNode: u'\\n'>, <django.template.loader_tags.IncludeNode object at 0x7f2ab178efd0>, <TextNode: u'\\n'>]>}, {}]"
[2016-09-28 17:14:12] WARNING [django.request:182] Not Found: /clivet
[2016-09-28 17:14:12] DEBUG [django.template:927] Exception while resolving variable 'name' in template 'unknown'.
Traceback (most recent call last):
  File "/home/alumno/Proyectos/myvenv/local/lib/python2.7/site-packages/django/template/base.py", line 905, in _resolve_lookup
    (bit, current))  # missing attribute
VariableDoesNotExist: Failed lookup for key [name] in u'<RegexURLResolver <RegexURLPattern list> (admin:admin) ^admin/>'
[2016-09-28 17:14:12] DEBUG [django.template:927] Exception while resolving variable 'name' in template 'unknown'.
Traceback (most recent call last):
  File "/home/alumno/Proyectos/myvenv/local/lib/python2.7/site-packages/django/template/base.py", line 905, in _resolve_lookup
    (bit, current))  # missing attribute
VariableDoesNotExist: Failed lookup for key [name] in u"<RegexURLResolver <module 'django.contrib.admindocs.urls' from '/home/alumno/Proyectos/myvenv/local/lib/python2.7/site-packages/django/contrib/admindocs/urls.pyc'> (None:None) ^admin/doc/>"
[2016-09-28 17:14:12] DEBUG [django.template:927] Exception while resolving variable 'name' in template 'unknown'.
Traceback (most recent call last):
  File "/home/alumno/Proyectos/myvenv/local/lib/python2.7/site-packages/django/template/base.py", line 905, in _resolve_lookup
    (bit, current))  # missing attribute
VariableDoesNotExist: Failed lookup for key [name] in u"<RegexURLResolver <module 'apps.home.urls' from '/home/alumno/Proyectos/CLIVET/apps/home/urls.pyc'> (None:home) ^home/>"
[2016-09-28 17:14:12] DEBUG [django.template:927] Exception while resolving variable 'name' in template 'unknown'.
Traceback (most recent call last):
  File "/home/alumno/Proyectos/myvenv/local/lib/python2.7/site-packages/django/template/base.py", line 905, in _resolve_lookup
    (bit, current))  # missing attribute
VariableDoesNotExist: Failed lookup for key [name] in u"<RegexURLResolver <module 'apps.space.urls' from '/home/alumno/Proyectos/CLIVET/apps/space/urls.pyc'> (None:space) ^space/>"
[2016-09-28 17:14:12] DEBUG [django.template:927] Exception while resolving variable 'name' in template 'unknown'.
Traceback (most recent call last):
  File "/home/alumno/Proyectos/myvenv/local/lib/python2.7/site-packages/django/template/base.py", line 905, in _resolve_lookup
    (bit, current))  # missing attribute
VariableDoesNotExist: Failed lookup for key [name] in u"<RegexURLResolver <module 'apps.sad.urls' from '/home/alumno/Proyectos/CLIVET/apps/sad/urls.pyc'> (None:sad) ^sad/>"
[2016-09-28 17:14:12] DEBUG [django.template:927] Exception while resolving variable 'name' in template 'unknown'.
Traceback (most recent call last):
  File "/home/alumno/Proyectos/myvenv/local/lib/python2.7/site-packages/django/template/base.py", line 905, in _resolve_lookup
    (bit, current))  # missing attribute
VariableDoesNotExist: Failed lookup for key [name] in u"<RegexURLResolver <module 'apps.mod_backend.urls' from '/home/alumno/Proyectos/CLIVET/apps/mod_backend/urls.pyc'> (None:mod_backend) ^mod_backend/>"
[2016-09-28 17:14:12] DEBUG [django.template:927] Exception while resolving variable 'name' in template 'unknown'.
Traceback (most recent call last):
  File "/home/alumno/Proyectos/myvenv/local/lib/python2.7/site-packages/django/template/base.py", line 905, in _resolve_lookup
    (bit, current))  # missing attribute
VariableDoesNotExist: Failed lookup for key [name] in u"<RegexURLResolver <module 'apps.accounts.urls' from '/home/alumno/Proyectos/CLIVET/apps/accounts/urls.pyc'> (None:None) ^accounts/>"
[2016-09-28 17:14:12] DEBUG [django.template:927] Exception while resolving variable 'name' in template 'unknown'.
Traceback (most recent call last):
  File "/home/alumno/Proyectos/myvenv/local/lib/python2.7/site-packages/django/template/base.py", line 905, in _resolve_lookup
    (bit, current))  # missing attribute
VariableDoesNotExist: Failed lookup for key [name] in u"<RegexURLResolver <module 'apps.clivet.urls' from '/home/alumno/Proyectos/CLIVET/apps/clivet/urls.pyc'> (None:None) ^clivet/>"
[2016-09-28 17:14:12] DEBUG [django.template:927] Exception while resolving variable 'name' in template 'unknown'.
Traceback (most recent call last):
  File "/home/alumno/Proyectos/myvenv/local/lib/python2.7/site-packages/django/template/base.py", line 905, in _resolve_lookup
    (bit, current))  # missing attribute
VariableDoesNotExist: Failed lookup for key [name] in u"<RegexURLResolver <module 'django.conf.urls.i18n' from '/home/alumno/Proyectos/myvenv/local/lib/python2.7/site-packages/django/conf/urls/i18n.pyc'> (None:None) ^i18n/>"
[2016-09-28 17:27:10] DEBUG [django.db.backends:89] (0.001) SELECT "django_session"."session_key", "django_session"."session_data", "django_session"."expire_date" FROM "django_session" WHERE ("django_session"."session_key" = 'sofiya3va6z3ic7px8yr71w3jovsmozs' AND "django_session"."expire_date" > '2016-09-28 17:27:10.790450'); args=('sofiya3va6z3ic7px8yr71w3jovsmozs', u'2016-09-28 17:27:10.790450')
[2016-09-28 17:30:18] DEBUG [django.db.backends:89] (0.001) SELECT "django_session"."session_key", "django_session"."session_data", "django_session"."expire_date" FROM "django_session" WHERE ("django_session"."session_key" = 'sofiya3va6z3ic7px8yr71w3jovsmozs' AND "django_session"."expire_date" > '2016-09-28 17:30:18.368347'); args=('sofiya3va6z3ic7px8yr71w3jovsmozs', u'2016-09-28 17:30:18.368347')
[2016-09-28 17:30:21] DEBUG [django.db.backends:89] (0.001) SELECT "django_session"."session_key", "django_session"."session_data", "django_session"."expire_date" FROM "django_session" WHERE ("django_session"."session_key" = 'sofiya3va6z3ic7px8yr71w3jovsmozs' AND "django_session"."expire_date" > '2016-09-28 17:30:21.042577'); args=('sofiya3va6z3ic7px8yr71w3jovsmozs', u'2016-09-28 17:30:21.042577')
[2016-09-28 17:30:21] WARNING [django.request:182] Not Found: /clivet/index-rtl.html
[2016-09-28 17:30:21] DEBUG [django.template:927] Exception while resolving variable 'name' in template 'unknown'.
Traceback (most recent call last):
  File "/home/alumno/Proyectos/myvenv/local/lib/python2.7/site-packages/django/template/base.py", line 905, in _resolve_lookup
    (bit, current))  # missing attribute
VariableDoesNotExist: Failed lookup for key [name] in u'<RegexURLResolver <RegexURLPattern list> (admin:admin) ^admin/>'
[2016-09-28 17:30:21] DEBUG [django.template:927] Exception while resolving variable 'name' in template 'unknown'.
Traceback (most recent call last):
  File "/home/alumno/Proyectos/myvenv/local/lib/python2.7/site-packages/django/template/base.py", line 905, in _resolve_lookup
    (bit, current))  # missing attribute
VariableDoesNotExist: Failed lookup for key [name] in u"<RegexURLResolver <module 'django.contrib.admindocs.urls' from '/home/alumno/Proyectos/myvenv/local/lib/python2.7/site-packages/django/contrib/admindocs/urls.pyc'> (None:None) ^admin/doc/>"
[2016-09-28 17:30:21] DEBUG [django.template:927] Exception while resolving variable 'name' in template 'unknown'.
Traceback (most recent call last):
  File "/home/alumno/Proyectos/myvenv/local/lib/python2.7/site-packages/django/template/base.py", line 905, in _resolve_lookup
    (bit, current))  # missing attribute
VariableDoesNotExist: Failed lookup for key [name] in u"<RegexURLResolver <module 'apps.home.urls' from '/home/alumno/Proyectos/CLIVET/apps/home/urls.pyc'> (None:home) ^home/>"
[2016-09-28 17:30:21] DEBUG [django.template:927] Exception while resolving variable 'name' in template 'unknown'.
Traceback (most recent call last):
  File "/home/alumno/Proyectos/myvenv/local/lib/python2.7/site-packages/django/template/base.py", line 905, in _resolve_lookup
    (bit, current))  # missing attribute
VariableDoesNotExist: Failed lookup for key [name] in u"<RegexURLResolver <module 'apps.space.urls' from '/home/alumno/Proyectos/CLIVET/apps/space/urls.pyc'> (None:space) ^space/>"
[2016-09-28 17:30:21] DEBUG [django.template:927] Exception while resolving variable 'name' in template 'unknown'.
Traceback (most recent call last):
  File "/home/alumno/Proyectos/myvenv/local/lib/python2.7/site-packages/django/template/base.py", line 905, in _resolve_lookup
    (bit, current))  # missing attribute
VariableDoesNotExist: Failed lookup for key [name] in u"<RegexURLResolver <module 'apps.sad.urls' from '/home/alumno/Proyectos/CLIVET/apps/sad/urls.pyc'> (None:sad) ^sad/>"
[2016-09-28 17:30:21] DEBUG [django.template:927] Exception while resolving variable 'name' in template 'unknown'.
Traceback (most recent call last):
  File "/home/alumno/Proyectos/myvenv/local/lib/python2.7/site-packages/django/template/base.py", line 905, in _resolve_lookup
    (bit, current))  # missing attribute
VariableDoesNotExist: Failed lookup for key [name] in u"<RegexURLResolver <module 'apps.mod_backend.urls' from '/home/alumno/Proyectos/CLIVET/apps/mod_backend/urls.pyc'> (None:mod_backend) ^mod_backend/>"
[2016-09-28 17:30:21] DEBUG [django.template:927] Exception while resolving variable 'name' in template 'unknown'.
Traceback (most recent call last):
  File "/home/alumno/Proyectos/myvenv/local/lib/python2.7/site-packages/django/template/base.py", line 905, in _resolve_lookup
    (bit, current))  # missing attribute
VariableDoesNotExist: Failed lookup for key [name] in u"<RegexURLResolver <module 'apps.accounts.urls' from '/home/alumno/Proyectos/CLIVET/apps/accounts/urls.pyc'> (None:None) ^accounts/>"
[2016-09-28 17:30:21] DEBUG [django.template:927] Exception while resolving variable 'name' in template 'unknown'.
Traceback (most recent call last):
  File "/home/alumno/Proyectos/myvenv/local/lib/python2.7/site-packages/django/template/base.py", line 905, in _resolve_lookup
    (bit, current))  # missing attribute
VariableDoesNotExist: Failed lookup for key [name] in u"<RegexURLResolver <module 'django.conf.urls.i18n' from '/home/alumno/Proyectos/myvenv/local/lib/python2.7/site-packages/django/conf/urls/i18n.pyc'> (None:None) ^i18n/>"
[2016-09-28 17:30:35] DEBUG [django.db.backends:89] (0.000) SELECT "django_session"."session_key", "django_session"."session_data", "django_session"."expire_date" FROM "django_session" WHERE ("django_session"."session_key" = 'sofiya3va6z3ic7px8yr71w3jovsmozs' AND "django_session"."expire_date" > '2016-09-28 17:30:35.617456'); args=('sofiya3va6z3ic7px8yr71w3jovsmozs', u'2016-09-28 17:30:35.617456')
[2016-09-28 17:30:35] WARNING [django.request:182] Not Found: /clivet/index.html
[2016-09-28 17:30:35] DEBUG [django.template:927] Exception while resolving variable 'name' in template 'unknown'.
Traceback (most recent call last):
  File "/home/alumno/Proyectos/myvenv/local/lib/python2.7/site-packages/django/template/base.py", line 905, in _resolve_lookup
    (bit, current))  # missing attribute
VariableDoesNotExist: Failed lookup for key [name] in u'<RegexURLResolver <RegexURLPattern list> (admin:admin) ^admin/>'
[2016-09-28 17:30:35] DEBUG [django.template:927] Exception while resolving variable 'name' in template 'unknown'.
Traceback (most recent call last):
  File "/home/alumno/Proyectos/myvenv/local/lib/python2.7/site-packages/django/template/base.py", line 905, in _resolve_lookup
    (bit, current))  # missing attribute
VariableDoesNotExist: Failed lookup for key [name] in u"<RegexURLResolver <module 'django.contrib.admindocs.urls' from '/home/alumno/Proyectos/myvenv/local/lib/python2.7/site-packages/django/contrib/admindocs/urls.pyc'> (None:None) ^admin/doc/>"
[2016-09-28 17:30:35] DEBUG [django.template:927] Exception while resolving variable 'name' in template 'unknown'.
Traceback (most recent call last):
  File "/home/alumno/Proyectos/myvenv/local/lib/python2.7/site-packages/django/template/base.py", line 905, in _resolve_lookup
    (bit, current))  # missing attribute
VariableDoesNotExist: Failed lookup for key [name] in u"<RegexURLResolver <module 'apps.home.urls' from '/home/alumno/Proyectos/CLIVET/apps/home/urls.pyc'> (None:home) ^home/>"
[2016-09-28 17:30:35] DEBUG [django.template:927] Exception while resolving variable 'name' in template 'unknown'.
Traceback (most recent call last):
  File "/home/alumno/Proyectos/myvenv/local/lib/python2.7/site-packages/django/template/base.py", line 905, in _resolve_lookup
    (bit, current))  # missing attribute
VariableDoesNotExist: Failed lookup for key [name] in u"<RegexURLResolver <module 'apps.space.urls' from '/home/alumno/Proyectos/CLIVET/apps/space/urls.pyc'> (None:space) ^space/>"
[2016-09-28 17:30:35] DEBUG [django.template:927] Exception while resolving variable 'name' in template 'unknown'.
Traceback (most recent call last):
  File "/home/alumno/Proyectos/myvenv/local/lib/python2.7/site-packages/django/template/base.py", line 905, in _resolve_lookup
    (bit, current))  # missing attribute
VariableDoesNotExist: Failed lookup for key [name] in u"<RegexURLResolver <module 'apps.sad.urls' from '/home/alumno/Proyectos/CLIVET/apps/sad/urls.pyc'> (None:sad) ^sad/>"
[2016-09-28 17:30:35] DEBUG [django.template:927] Exception while resolving variable 'name' in template 'unknown'.
Traceback (most recent call last):
  File "/home/alumno/Proyectos/myvenv/local/lib/python2.7/site-packages/django/template/base.py", line 905, in _resolve_lookup
    (bit, current))  # missing attribute
VariableDoesNotExist: Failed lookup for key [name] in u"<RegexURLResolver <module 'apps.mod_backend.urls' from '/home/alumno/Proyectos/CLIVET/apps/mod_backend/urls.pyc'> (None:mod_backend) ^mod_backend/>"
[2016-09-28 17:30:35] DEBUG [django.template:927] Exception while resolving variable 'name' in template 'unknown'.
Traceback (most recent call last):
  File "/home/alumno/Proyectos/myvenv/local/lib/python2.7/site-packages/django/template/base.py", line 905, in _resolve_lookup
    (bit, current))  # missing attribute
VariableDoesNotExist: Failed lookup for key [name] in u"<RegexURLResolver <module 'apps.accounts.urls' from '/home/alumno/Proyectos/CLIVET/apps/accounts/urls.pyc'> (None:None) ^accounts/>"
[2016-09-28 17:30:35] DEBUG [django.template:927] Exception while resolving variable 'name' in template 'unknown'.
Traceback (most recent call last):
  File "/home/alumno/Proyectos/myvenv/local/lib/python2.7/site-packages/django/template/base.py", line 905, in _resolve_lookup
    (bit, current))  # missing attribute
VariableDoesNotExist: Failed lookup for key [name] in u"<RegexURLResolver <module 'django.conf.urls.i18n' from '/home/alumno/Proyectos/myvenv/local/lib/python2.7/site-packages/django/conf/urls/i18n.pyc'> (None:None) ^i18n/>"
[2016-09-28 17:31:36] DEBUG [django.db.backends:89] (0.001) SELECT "django_session"."session_key", "django_session"."session_data", "django_session"."expire_date" FROM "django_session" WHERE ("django_session"."session_key" = 'sofiya3va6z3ic7px8yr71w3jovsmozs' AND "django_session"."expire_date" > '2016-09-28 17:31:36.472405'); args=('sofiya3va6z3ic7px8yr71w3jovsmozs', u'2016-09-28 17:31:36.472405')
[2016-09-28 17:31:52] DEBUG [django.db.backends:89] (0.001) SELECT "django_session"."session_key", "django_session"."session_data", "django_session"."expire_date" FROM "django_session" WHERE ("django_session"."session_key" = 'sofiya3va6z3ic7px8yr71w3jovsmozs' AND "django_session"."expire_date" > '2016-09-28 17:31:52.176746'); args=('sofiya3va6z3ic7px8yr71w3jovsmozs', u'2016-09-28 17:31:52.176746')
[2016-09-28 17:32:14] DEBUG [django.db.backends:89] (0.001) SELECT "django_session"."session_key", "django_session"."session_data", "django_session"."expire_date" FROM "django_session" WHERE ("django_session"."session_key" = 'sofiya3va6z3ic7px8yr71w3jovsmozs' AND "django_session"."expire_date" > '2016-09-28 17:32:14.066178'); args=('sofiya3va6z3ic7px8yr71w3jovsmozs', u'2016-09-28 17:32:14.066178')
[2016-09-28 17:32:21] DEBUG [django.db.backends:89] (0.001) SELECT "django_session"."session_key", "django_session"."session_data", "django_session"."expire_date" FROM "django_session" WHERE ("django_session"."session_key" = 'sofiya3va6z3ic7px8yr71w3jovsmozs' AND "django_session"."expire_date" > '2016-09-28 17:32:21.633103'); args=('sofiya3va6z3ic7px8yr71w3jovsmozs', u'2016-09-28 17:32:21.633103')
[2016-09-28 17:33:07] DEBUG [django.db.backends:89] (0.001) SELECT "django_session"."session_key", "django_session"."session_data", "django_session"."expire_date" FROM "django_session" WHERE ("django_session"."session_key" = 'sofiya3va6z3ic7px8yr71w3jovsmozs' AND "django_session"."expire_date" > '2016-09-28 17:33:07.826039'); args=('sofiya3va6z3ic7px8yr71w3jovsmozs', u'2016-09-28 17:33:07.826039')
[2016-09-28 17:34:10] DEBUG [django.db.backends:89] (0.001) SELECT "django_session"."session_key", "django_session"."session_data", "django_session"."expire_date" FROM "django_session" WHERE ("django_session"."session_key" = 'sofiya3va6z3ic7px8yr71w3jovsmozs' AND "django_session"."expire_date" > '2016-09-28 17:34:10.538816'); args=('sofiya3va6z3ic7px8yr71w3jovsmozs', u'2016-09-28 17:34:10.538816')
[2016-09-28 17:34:42] DEBUG [django.db.backends:89] (0.001) SELECT "django_session"."session_key", "django_session"."session_data", "django_session"."expire_date" FROM "django_session" WHERE ("django_session"."session_key" = 'sofiya3va6z3ic7px8yr71w3jovsmozs' AND "django_session"."expire_date" > '2016-09-28 17:34:42.811046'); args=('sofiya3va6z3ic7px8yr71w3jovsmozs', u'2016-09-28 17:34:42.811046')
[2016-09-28 17:34:55] DEBUG [django.db.backends:89] (0.001) SELECT "django_session"."session_key", "django_session"."session_data", "django_session"."expire_date" FROM "django_session" WHERE ("django_session"."session_key" = 'sofiya3va6z3ic7px8yr71w3jovsmozs' AND "django_session"."expire_date" > '2016-09-28 17:34:55.035347'); args=('sofiya3va6z3ic7px8yr71w3jovsmozs', u'2016-09-28 17:34:55.035347')
[2016-09-28 17:35:43] DEBUG [django.db.backends:89] (0.001) SELECT "django_session"."session_key", "django_session"."session_data", "django_session"."expire_date" FROM "django_session" WHERE ("django_session"."session_key" = 'sofiya3va6z3ic7px8yr71w3jovsmozs' AND "django_session"."expire_date" > '2016-09-28 17:35:43.532503'); args=('sofiya3va6z3ic7px8yr71w3jovsmozs', u'2016-09-28 17:35:43.532503')
[2016-09-28 17:36:21] DEBUG [django.db.backends:89] (0.000) SELECT "django_session"."session_key", "django_session"."session_data", "django_session"."expire_date" FROM "django_session" WHERE ("django_session"."session_key" = 'sofiya3va6z3ic7px8yr71w3jovsmozs' AND "django_session"."expire_date" > '2016-09-28 17:36:21.860439'); args=('sofiya3va6z3ic7px8yr71w3jovsmozs', u'2016-09-28 17:36:21.860439')
[2016-09-28 17:36:23] DEBUG [django.db.backends:89] (0.001) SELECT "django_session"."session_key", "django_session"."session_data", "django_session"."expire_date" FROM "django_session" WHERE ("django_session"."session_key" = 'sofiya3va6z3ic7px8yr71w3jovsmozs' AND "django_session"."expire_date" > '2016-09-28 17:36:23.277103'); args=('sofiya3va6z3ic7px8yr71w3jovsmozs', u'2016-09-28 17:36:23.277103')
[2016-09-28 17:36:54] DEBUG [django.db.backends:89] (0.001) SELECT "django_session"."session_key", "django_session"."session_data", "django_session"."expire_date" FROM "django_session" WHERE ("django_session"."session_key" = 'sofiya3va6z3ic7px8yr71w3jovsmozs' AND "django_session"."expire_date" > '2016-09-28 17:36:54.500798'); args=('sofiya3va6z3ic7px8yr71w3jovsmozs', u'2016-09-28 17:36:54.500798')
[2016-09-28 17:37:41] DEBUG [django.db.backends:89] (0.000) SELECT "django_session"."session_key", "django_session"."session_data", "django_session"."expire_date" FROM "django_session" WHERE ("django_session"."session_key" = 'sofiya3va6z3ic7px8yr71w3jovsmozs' AND "django_session"."expire_date" > '2016-09-28 17:37:41.103014'); args=('sofiya3va6z3ic7px8yr71w3jovsmozs', u'2016-09-28 17:37:41.103014')
[2016-09-28 17:38:34] DEBUG [django.db.backends:89] (0.001) SELECT "django_session"."session_key", "django_session"."session_data", "django_session"."expire_date" FROM "django_session" WHERE ("django_session"."session_key" = 'sofiya3va6z3ic7px8yr71w3jovsmozs' AND "django_session"."expire_date" > '2016-09-28 17:38:34.653218'); args=('sofiya3va6z3ic7px8yr71w3jovsmozs', u'2016-09-28 17:38:34.653218')
[2016-09-28 17:39:48] DEBUG [django.db.backends:89] (0.001) SELECT "django_session"."session_key", "django_session"."session_data", "django_session"."expire_date" FROM "django_session" WHERE ("django_session"."session_key" = 'sofiya3va6z3ic7px8yr71w3jovsmozs' AND "django_session"."expire_date" > '2016-09-28 17:39:48.584231'); args=('sofiya3va6z3ic7px8yr71w3jovsmozs', u'2016-09-28 17:39:48.584231')
[2016-09-28 17:40:41] DEBUG [django.db.backends:89] (0.001) SELECT "django_session"."session_key", "django_session"."session_data", "django_session"."expire_date" FROM "django_session" WHERE ("django_session"."session_key" = 'sofiya3va6z3ic7px8yr71w3jovsmozs' AND "django_session"."expire_date" > '2016-09-28 17:40:41.568415'); args=('sofiya3va6z3ic7px8yr71w3jovsmozs', u'2016-09-28 17:40:41.568415')
[2016-09-28 17:42:29] DEBUG [django.db.backends:89] (0.001) SELECT "django_session"."session_key", "django_session"."session_data", "django_session"."expire_date" FROM "django_session" WHERE ("django_session"."session_key" = 'sofiya3va6z3ic7px8yr71w3jovsmozs' AND "django_session"."expire_date" > '2016-09-28 17:42:29.297099'); args=('sofiya3va6z3ic7px8yr71w3jovsmozs', u'2016-09-28 17:42:29.297099')
[2016-09-28 17:42:46] DEBUG [django.db.backends:89] (0.001) SELECT "django_session"."session_key", "django_session"."session_data", "django_session"."expire_date" FROM "django_session" WHERE ("django_session"."session_key" = 'sofiya3va6z3ic7px8yr71w3jovsmozs' AND "django_session"."expire_date" > '2016-09-28 17:42:46.585390'); args=('sofiya3va6z3ic7px8yr71w3jovsmozs', u'2016-09-28 17:42:46.585390')
[2016-09-28 17:45:53] DEBUG [django.db.backends:89] (0.001) SELECT "django_session"."session_key", "django_session"."session_data", "django_session"."expire_date" FROM "django_session" WHERE ("django_session"."session_key" = 'sofiya3va6z3ic7px8yr71w3jovsmozs' AND "django_session"."expire_date" > '2016-09-28 17:45:53.219476'); args=('sofiya3va6z3ic7px8yr71w3jovsmozs', u'2016-09-28 17:45:53.219476')
[2016-09-28 17:49:54] DEBUG [django.db.backends:89] (0.001) SELECT "django_session"."session_key", "django_session"."session_data", "django_session"."expire_date" FROM "django_session" WHERE ("django_session"."session_key" = 'sofiya3va6z3ic7px8yr71w3jovsmozs' AND "django_session"."expire_date" > '2016-09-28 17:49:54.045334'); args=('sofiya3va6z3ic7px8yr71w3jovsmozs', u'2016-09-28 17:49:54.045334')
[2016-09-28 17:49:56] DEBUG [django.db.backends:89] (0.001) SELECT "django_session"."session_key", "django_session"."session_data", "django_session"."expire_date" FROM "django_session" WHERE ("django_session"."session_key" = 'sofiya3va6z3ic7px8yr71w3jovsmozs' AND "django_session"."expire_date" > '2016-09-28 17:49:56.853535'); args=('sofiya3va6z3ic7px8yr71w3jovsmozs', u'2016-09-28 17:49:56.853535')
[2016-09-28 17:49:57] DEBUG [django.db.backends:89] (0.001) SELECT "django_session"."session_key", "django_session"."session_data", "django_session"."expire_date" FROM "django_session" WHERE ("django_session"."session_key" = 'sofiya3va6z3ic7px8yr71w3jovsmozs' AND "django_session"."expire_date" > '2016-09-28 17:49:57.101567'); args=('sofiya3va6z3ic7px8yr71w3jovsmozs', u'2016-09-28 17:49:57.101567')
[2016-09-28 17:50:17] DEBUG [django.db.backends:89] (0.001) SELECT "django_session"."session_key", "django_session"."session_data", "django_session"."expire_date" FROM "django_session" WHERE ("django_session"."session_key" = 'sofiya3va6z3ic7px8yr71w3jovsmozs' AND "django_session"."expire_date" > '2016-09-28 17:50:17.725883'); args=('sofiya3va6z3ic7px8yr71w3jovsmozs', u'2016-09-28 17:50:17.725883')
[2016-09-28 17:50:23] DEBUG [django.db.backends:89] (0.001) SELECT "django_session"."session_key", "django_session"."session_data", "django_session"."expire_date" FROM "django_session" WHERE ("django_session"."session_key" = 'sofiya3va6z3ic7px8yr71w3jovsmozs' AND "django_session"."expire_date" > '2016-09-28 17:50:23.253671'); args=('sofiya3va6z3ic7px8yr71w3jovsmozs', u'2016-09-28 17:50:23.253671')
[2016-09-28 17:50:24] DEBUG [django.db.backends:89] (0.001) SELECT "django_session"."session_key", "django_session"."session_data", "django_session"."expire_date" FROM "django_session" WHERE ("django_session"."session_key" = 'sofiya3va6z3ic7px8yr71w3jovsmozs' AND "django_session"."expire_date" > '2016-09-28 17:50:24.342462'); args=('sofiya3va6z3ic7px8yr71w3jovsmozs', u'2016-09-28 17:50:24.342462')
[2016-09-28 17:50:24] DEBUG [django.db.backends:89] (0.001) SELECT "django_session"."session_key", "django_session"."session_data", "django_session"."expire_date" FROM "django_session" WHERE ("django_session"."session_key" = 'sofiya3va6z3ic7px8yr71w3jovsmozs' AND "django_session"."expire_date" > '2016-09-28 17:50:24.637584'); args=('sofiya3va6z3ic7px8yr71w3jovsmozs', u'2016-09-28 17:50:24.637584')
