[2016-10-05 00:00:26] DEBUG [django.db.backends:89] (0.001) 
            SELECT name, type FROM sqlite_master
            WHERE type in ('table', 'view') AND NOT name='sqlite_sequence'
            ORDER BY name; args=None
[2016-10-05 00:00:26] DEBUG [django.db.backends:89] (0.000) SELECT "django_migrations"."app", "django_migrations"."name" FROM "django_migrations"; args=()
[2016-10-05 00:00:27] DEBUG [django.db.backends:89] (0.001) 
            SELECT name, type FROM sqlite_master
            WHERE type in ('table', 'view') AND NOT name='sqlite_sequence'
            ORDER BY name; args=None
[2016-10-05 00:00:27] DEBUG [django.db.backends:89] (0.000) SELECT "django_migrations"."app", "django_migrations"."name" FROM "django_migrations"; args=()
[2016-10-05 00:00:30] DEBUG [django.db.backends:89] (0.001) 
            SELECT name, type FROM sqlite_master
            WHERE type in ('table', 'view') AND NOT name='sqlite_sequence'
            ORDER BY name; args=None
[2016-10-05 00:00:30] DEBUG [django.db.backends:89] (0.000) SELECT "django_migrations"."app", "django_migrations"."name" FROM "django_migrations"; args=()
[2016-10-05 00:00:36] DEBUG [django.db.backends:89] (0.001) SELECT "django_session"."session_key", "django_session"."session_data", "django_session"."expire_date" FROM "django_session" WHERE ("django_session"."expire_date" > '2016-10-05 00:00:36.760092' AND "django_session"."session_key" = '73tz8dalqomobmynelxwtkp1yjyaxv1o'); args=('2016-10-05 00:00:36.760092', '73tz8dalqomobmynelxwtkp1yjyaxv1o')
[2016-10-05 00:00:36] ERROR [django.request:284] Internal Server Error: /clivet/clivet/bootstrap-elements.html
Traceback (most recent call last):
  File "/home/rusbel/Proyectos/myvenv/lib/python3.5/site-packages/django/core/handlers/base.py", line 149, in get_response
    response = self.process_exception_by_middleware(e, request)
  File "/home/rusbel/Proyectos/myvenv/lib/python3.5/site-packages/django/core/handlers/base.py", line 147, in get_response
    response = wrapped_callback(request, *callback_args, **callback_kwargs)
  File "/home/rusbel/Proyectos/Django/CLIVET/apps/clivet/views.py", line 16, in clivet
    return render(request, 'clivet/clivet.html', {'posts': posts})
NameError: name 'posts' is not defined
[2016-10-05 00:00:36] DEBUG [django.db.backends:89] (0.000) SELECT "clivet_vacuna"."id", "clivet_vacuna"."vacuna_aplicada", "clivet_vacuna"."observacion", "clivet_vacuna"."created_date", "clivet_vacuna"."published_date" FROM "clivet_vacuna" WHERE "clivet_vacuna"."published_date" <= '2016-10-05 00:00:36.772528' ORDER BY "clivet_vacuna"."published_date" ASC LIMIT 21; args=('2016-10-05 00:00:36.772528',)
[2016-10-05 00:01:04] DEBUG [django.db.backends:89] (0.001) 
            SELECT name, type FROM sqlite_master
            WHERE type in ('table', 'view') AND NOT name='sqlite_sequence'
            ORDER BY name; args=None
[2016-10-05 00:01:04] DEBUG [django.db.backends:89] (0.000) SELECT "django_migrations"."app", "django_migrations"."name" FROM "django_migrations"; args=()
[2016-10-05 00:01:07] DEBUG [django.db.backends:89] (0.001) SELECT "django_session"."session_key", "django_session"."session_data", "django_session"."expire_date" FROM "django_session" WHERE ("django_session"."session_key" = '73tz8dalqomobmynelxwtkp1yjyaxv1o' AND "django_session"."expire_date" > '2016-10-05 00:01:07.834266'); args=('73tz8dalqomobmynelxwtkp1yjyaxv1o', '2016-10-05 00:01:07.834266')
[2016-10-05 00:01:07] DEBUG [django.db.backends:89] (0.001) SELECT "django_session"."session_key", "django_session"."session_data", "django_session"."expire_date" FROM "django_session" WHERE ("django_session"."session_key" = '73tz8dalqomobmynelxwtkp1yjyaxv1o' AND "django_session"."expire_date" > '2016-10-05 00:01:07.937441'); args=('73tz8dalqomobmynelxwtkp1yjyaxv1o', '2016-10-05 00:01:07.937441')
[2016-10-05 00:01:07] WARNING [django.request:182] Not Found: /bootstrap/images/kittens.jpg
[2016-10-05 00:01:07] DEBUG [django.template:927] Exception while resolving variable 'name' in template 'unknown'.
Traceback (most recent call last):
  File "/home/rusbel/Proyectos/myvenv/lib/python3.5/site-packages/django/core/handlers/base.py", line 134, in get_response
    resolver_match = resolver.resolve(request.path_info)
  File "/home/rusbel/Proyectos/myvenv/lib/python3.5/site-packages/django/core/urlresolvers.py", line 404, in resolve
    raise Resolver404({'tried': tried, 'path': new_path})
django.core.urlresolvers.Resolver404: {'tried': [[<RegexURLResolver <RegexURLPattern list> (admin:admin) ^admin/>], [<RegexURLResolver <module 'django.contrib.admindocs.urls' from '/home/rusbel/Proyectos/myvenv/lib/python3.5/site-packages/django/contrib/admindocs/urls.py'> (None:None) ^admin/doc/>], [<RegexURLResolver <module 'apps.home.urls' from '/home/rusbel/Proyectos/Django/CLIVET/apps/home/urls.py'> (None:home) ^home/>], [<RegexURLPattern index ^$>], [<RegexURLResolver <module 'apps.space.urls' from '/home/rusbel/Proyectos/Django/CLIVET/apps/space/urls.py'> (None:space) ^space/>], [<RegexURLResolver <module 'apps.sad.urls' from '/home/rusbel/Proyectos/Django/CLIVET/apps/sad/urls.py'> (None:sad) ^sad/>], [<RegexURLResolver <module 'apps.mod_backend.urls' from '/home/rusbel/Proyectos/Django/CLIVET/apps/mod_backend/urls.py'> (None:mod_backend) ^mod_backend/>], [<RegexURLResolver <module 'apps.accounts.urls' from '/home/rusbel/Proyectos/Django/CLIVET/apps/accounts/urls.py'> (None:None) ^accounts/>], [<RegexURLResolver <module 'apps.clivet.urls' from '/home/rusbel/Proyectos/Django/CLIVET/apps/clivet/urls.py'> (None:clivet) ^clivet/>], [<RegexURLResolver <module 'django.conf.urls.i18n' from '/home/rusbel/Proyectos/myvenv/lib/python3.5/site-packages/django/conf/urls/i18n.py'> (None:None) ^i18n/>], [<RegexURLPattern None ^jsi18n/>], [<RegexURLPattern None ^media\/(?P<path>.*)$>]], 'path': 'bootstrap/images/kittens.jpg'}

During handling of the above exception, another exception occurred:

Traceback (most recent call last):
  File "/home/rusbel/Proyectos/myvenv/lib/python3.5/site-packages/django/template/base.py", line 883, in _resolve_lookup
    current = current[bit]
TypeError: 'RegexURLResolver' object is not subscriptable

During handling of the above exception, another exception occurred:

Traceback (most recent call last):
  File "/home/rusbel/Proyectos/myvenv/lib/python3.5/site-packages/django/template/base.py", line 891, in _resolve_lookup
    current = getattr(current, bit)
AttributeError: 'RegexURLResolver' object has no attribute 'name'

During handling of the above exception, another exception occurred:

Traceback (most recent call last):
  File "/home/rusbel/Proyectos/myvenv/lib/python3.5/site-packages/django/template/base.py", line 898, in _resolve_lookup
    current = current[int(bit)]
ValueError: invalid literal for int() with base 10: 'name'

During handling of the above exception, another exception occurred:

Traceback (most recent call last):
  File "/home/rusbel/Proyectos/myvenv/lib/python3.5/site-packages/django/template/base.py", line 905, in _resolve_lookup
    (bit, current))  # missing attribute
django.template.base.VariableDoesNotExist: Failed lookup for key [name] in '<RegexURLResolver <RegexURLPattern list> (admin:admin) ^admin/>'
[2016-10-05 00:01:07] DEBUG [django.template:927] Exception while resolving variable 'name' in template 'unknown'.
Traceback (most recent call last):
  File "/home/rusbel/Proyectos/myvenv/lib/python3.5/site-packages/django/core/handlers/base.py", line 134, in get_response
    resolver_match = resolver.resolve(request.path_info)
  File "/home/rusbel/Proyectos/myvenv/lib/python3.5/site-packages/django/core/urlresolvers.py", line 404, in resolve
    raise Resolver404({'tried': tried, 'path': new_path})
django.core.urlresolvers.Resolver404: {'tried': [[<RegexURLResolver <RegexURLPattern list> (admin:admin) ^admin/>], [<RegexURLResolver <module 'django.contrib.admindocs.urls' from '/home/rusbel/Proyectos/myvenv/lib/python3.5/site-packages/django/contrib/admindocs/urls.py'> (None:None) ^admin/doc/>], [<RegexURLResolver <module 'apps.home.urls' from '/home/rusbel/Proyectos/Django/CLIVET/apps/home/urls.py'> (None:home) ^home/>], [<RegexURLPattern index ^$>], [<RegexURLResolver <module 'apps.space.urls' from '/home/rusbel/Proyectos/Django/CLIVET/apps/space/urls.py'> (None:space) ^space/>], [<RegexURLResolver <module 'apps.sad.urls' from '/home/rusbel/Proyectos/Django/CLIVET/apps/sad/urls.py'> (None:sad) ^sad/>], [<RegexURLResolver <module 'apps.mod_backend.urls' from '/home/rusbel/Proyectos/Django/CLIVET/apps/mod_backend/urls.py'> (None:mod_backend) ^mod_backend/>], [<RegexURLResolver <module 'apps.accounts.urls' from '/home/rusbel/Proyectos/Django/CLIVET/apps/accounts/urls.py'> (None:None) ^accounts/>], [<RegexURLResolver <module 'apps.clivet.urls' from '/home/rusbel/Proyectos/Django/CLIVET/apps/clivet/urls.py'> (None:clivet) ^clivet/>], [<RegexURLResolver <module 'django.conf.urls.i18n' from '/home/rusbel/Proyectos/myvenv/lib/python3.5/site-packages/django/conf/urls/i18n.py'> (None:None) ^i18n/>], [<RegexURLPattern None ^jsi18n/>], [<RegexURLPattern None ^media\/(?P<path>.*)$>]], 'path': 'bootstrap/images/kittens.jpg'}

During handling of the above exception, another exception occurred:

Traceback (most recent call last):
  File "/home/rusbel/Proyectos/myvenv/lib/python3.5/site-packages/django/template/base.py", line 883, in _resolve_lookup
    current = current[bit]
TypeError: 'RegexURLResolver' object is not subscriptable

During handling of the above exception, another exception occurred:

Traceback (most recent call last):
  File "/home/rusbel/Proyectos/myvenv/lib/python3.5/site-packages/django/template/base.py", line 891, in _resolve_lookup
    current = getattr(current, bit)
AttributeError: 'RegexURLResolver' object has no attribute 'name'

During handling of the above exception, another exception occurred:

Traceback (most recent call last):
  File "/home/rusbel/Proyectos/myvenv/lib/python3.5/site-packages/django/template/base.py", line 898, in _resolve_lookup
    current = current[int(bit)]
ValueError: invalid literal for int() with base 10: 'name'

During handling of the above exception, another exception occurred:

Traceback (most recent call last):
  File "/home/rusbel/Proyectos/myvenv/lib/python3.5/site-packages/django/template/base.py", line 905, in _resolve_lookup
    (bit, current))  # missing attribute
django.template.base.VariableDoesNotExist: Failed lookup for key [name] in "<RegexURLResolver <module 'django.contrib.admindocs.urls' from '/home/rusbel/Proyectos/myvenv/lib/python3.5/site-packages/django/contrib/admindocs/urls.py'> (None:None) ^admin/doc/>"
[2016-10-05 00:01:07] DEBUG [django.template:927] Exception while resolving variable 'name' in template 'unknown'.
Traceback (most recent call last):
  File "/home/rusbel/Proyectos/myvenv/lib/python3.5/site-packages/django/core/handlers/base.py", line 134, in get_response
    resolver_match = resolver.resolve(request.path_info)
  File "/home/rusbel/Proyectos/myvenv/lib/python3.5/site-packages/django/core/urlresolvers.py", line 404, in resolve
    raise Resolver404({'tried': tried, 'path': new_path})
django.core.urlresolvers.Resolver404: {'tried': [[<RegexURLResolver <RegexURLPattern list> (admin:admin) ^admin/>], [<RegexURLResolver <module 'django.contrib.admindocs.urls' from '/home/rusbel/Proyectos/myvenv/lib/python3.5/site-packages/django/contrib/admindocs/urls.py'> (None:None) ^admin/doc/>], [<RegexURLResolver <module 'apps.home.urls' from '/home/rusbel/Proyectos/Django/CLIVET/apps/home/urls.py'> (None:home) ^home/>], [<RegexURLPattern index ^$>], [<RegexURLResolver <module 'apps.space.urls' from '/home/rusbel/Proyectos/Django/CLIVET/apps/space/urls.py'> (None:space) ^space/>], [<RegexURLResolver <module 'apps.sad.urls' from '/home/rusbel/Proyectos/Django/CLIVET/apps/sad/urls.py'> (None:sad) ^sad/>], [<RegexURLResolver <module 'apps.mod_backend.urls' from '/home/rusbel/Proyectos/Django/CLIVET/apps/mod_backend/urls.py'> (None:mod_backend) ^mod_backend/>], [<RegexURLResolver <module 'apps.accounts.urls' from '/home/rusbel/Proyectos/Django/CLIVET/apps/accounts/urls.py'> (None:None) ^accounts/>], [<RegexURLResolver <module 'apps.clivet.urls' from '/home/rusbel/Proyectos/Django/CLIVET/apps/clivet/urls.py'> (None:clivet) ^clivet/>], [<RegexURLResolver <module 'django.conf.urls.i18n' from '/home/rusbel/Proyectos/myvenv/lib/python3.5/site-packages/django/conf/urls/i18n.py'> (None:None) ^i18n/>], [<RegexURLPattern None ^jsi18n/>], [<RegexURLPattern None ^media\/(?P<path>.*)$>]], 'path': 'bootstrap/images/kittens.jpg'}

During handling of the above exception, another exception occurred:

Traceback (most recent call last):
  File "/home/rusbel/Proyectos/myvenv/lib/python3.5/site-packages/django/template/base.py", line 883, in _resolve_lookup
    current = current[bit]
TypeError: 'RegexURLResolver' object is not subscriptable

During handling of the above exception, another exception occurred:

Traceback (most recent call last):
  File "/home/rusbel/Proyectos/myvenv/lib/python3.5/site-packages/django/template/base.py", line 891, in _resolve_lookup
    current = getattr(current, bit)
AttributeError: 'RegexURLResolver' object has no attribute 'name'

During handling of the above exception, another exception occurred:

Traceback (most recent call last):
  File "/home/rusbel/Proyectos/myvenv/lib/python3.5/site-packages/django/template/base.py", line 898, in _resolve_lookup
    current = current[int(bit)]
ValueError: invalid literal for int() with base 10: 'name'

During handling of the above exception, another exception occurred:

Traceback (most recent call last):
  File "/home/rusbel/Proyectos/myvenv/lib/python3.5/site-packages/django/template/base.py", line 905, in _resolve_lookup
    (bit, current))  # missing attribute
django.template.base.VariableDoesNotExist: Failed lookup for key [name] in "<RegexURLResolver <module 'apps.home.urls' from '/home/rusbel/Proyectos/Django/CLIVET/apps/home/urls.py'> (None:home) ^home/>"
[2016-10-05 00:01:07] DEBUG [django.template:927] Exception while resolving variable 'name' in template 'unknown'.
Traceback (most recent call last):
  File "/home/rusbel/Proyectos/myvenv/lib/python3.5/site-packages/django/core/handlers/base.py", line 134, in get_response
    resolver_match = resolver.resolve(request.path_info)
  File "/home/rusbel/Proyectos/myvenv/lib/python3.5/site-packages/django/core/urlresolvers.py", line 404, in resolve
    raise Resolver404({'tried': tried, 'path': new_path})
django.core.urlresolvers.Resolver404: {'tried': [[<RegexURLResolver <RegexURLPattern list> (admin:admin) ^admin/>], [<RegexURLResolver <module 'django.contrib.admindocs.urls' from '/home/rusbel/Proyectos/myvenv/lib/python3.5/site-packages/django/contrib/admindocs/urls.py'> (None:None) ^admin/doc/>], [<RegexURLResolver <module 'apps.home.urls' from '/home/rusbel/Proyectos/Django/CLIVET/apps/home/urls.py'> (None:home) ^home/>], [<RegexURLPattern index ^$>], [<RegexURLResolver <module 'apps.space.urls' from '/home/rusbel/Proyectos/Django/CLIVET/apps/space/urls.py'> (None:space) ^space/>], [<RegexURLResolver <module 'apps.sad.urls' from '/home/rusbel/Proyectos/Django/CLIVET/apps/sad/urls.py'> (None:sad) ^sad/>], [<RegexURLResolver <module 'apps.mod_backend.urls' from '/home/rusbel/Proyectos/Django/CLIVET/apps/mod_backend/urls.py'> (None:mod_backend) ^mod_backend/>], [<RegexURLResolver <module 'apps.accounts.urls' from '/home/rusbel/Proyectos/Django/CLIVET/apps/accounts/urls.py'> (None:None) ^accounts/>], [<RegexURLResolver <module 'apps.clivet.urls' from '/home/rusbel/Proyectos/Django/CLIVET/apps/clivet/urls.py'> (None:clivet) ^clivet/>], [<RegexURLResolver <module 'django.conf.urls.i18n' from '/home/rusbel/Proyectos/myvenv/lib/python3.5/site-packages/django/conf/urls/i18n.py'> (None:None) ^i18n/>], [<RegexURLPattern None ^jsi18n/>], [<RegexURLPattern None ^media\/(?P<path>.*)$>]], 'path': 'bootstrap/images/kittens.jpg'}

During handling of the above exception, another exception occurred:

Traceback (most recent call last):
  File "/home/rusbel/Proyectos/myvenv/lib/python3.5/site-packages/django/template/base.py", line 883, in _resolve_lookup
    current = current[bit]
TypeError: 'RegexURLResolver' object is not subscriptable

During handling of the above exception, another exception occurred:

Traceback (most recent call last):
  File "/home/rusbel/Proyectos/myvenv/lib/python3.5/site-packages/django/template/base.py", line 891, in _resolve_lookup
    current = getattr(current, bit)
AttributeError: 'RegexURLResolver' object has no attribute 'name'

During handling of the above exception, another exception occurred:

Traceback (most recent call last):
  File "/home/rusbel/Proyectos/myvenv/lib/python3.5/site-packages/django/template/base.py", line 898, in _resolve_lookup
    current = current[int(bit)]
ValueError: invalid literal for int() with base 10: 'name'

During handling of the above exception, another exception occurred:

Traceback (most recent call last):
  File "/home/rusbel/Proyectos/myvenv/lib/python3.5/site-packages/django/template/base.py", line 905, in _resolve_lookup
    (bit, current))  # missing attribute
django.template.base.VariableDoesNotExist: Failed lookup for key [name] in "<RegexURLResolver <module 'apps.space.urls' from '/home/rusbel/Proyectos/Django/CLIVET/apps/space/urls.py'> (None:space) ^space/>"
[2016-10-05 00:01:07] DEBUG [django.template:927] Exception while resolving variable 'name' in template 'unknown'.
Traceback (most recent call last):
  File "/home/rusbel/Proyectos/myvenv/lib/python3.5/site-packages/django/core/handlers/base.py", line 134, in get_response
    resolver_match = resolver.resolve(request.path_info)
  File "/home/rusbel/Proyectos/myvenv/lib/python3.5/site-packages/django/core/urlresolvers.py", line 404, in resolve
    raise Resolver404({'tried': tried, 'path': new_path})
django.core.urlresolvers.Resolver404: {'tried': [[<RegexURLResolver <RegexURLPattern list> (admin:admin) ^admin/>], [<RegexURLResolver <module 'django.contrib.admindocs.urls' from '/home/rusbel/Proyectos/myvenv/lib/python3.5/site-packages/django/contrib/admindocs/urls.py'> (None:None) ^admin/doc/>], [<RegexURLResolver <module 'apps.home.urls' from '/home/rusbel/Proyectos/Django/CLIVET/apps/home/urls.py'> (None:home) ^home/>], [<RegexURLPattern index ^$>], [<RegexURLResolver <module 'apps.space.urls' from '/home/rusbel/Proyectos/Django/CLIVET/apps/space/urls.py'> (None:space) ^space/>], [<RegexURLResolver <module 'apps.sad.urls' from '/home/rusbel/Proyectos/Django/CLIVET/apps/sad/urls.py'> (None:sad) ^sad/>], [<RegexURLResolver <module 'apps.mod_backend.urls' from '/home/rusbel/Proyectos/Django/CLIVET/apps/mod_backend/urls.py'> (None:mod_backend) ^mod_backend/>], [<RegexURLResolver <module 'apps.accounts.urls' from '/home/rusbel/Proyectos/Django/CLIVET/apps/accounts/urls.py'> (None:None) ^accounts/>], [<RegexURLResolver <module 'apps.clivet.urls' from '/home/rusbel/Proyectos/Django/CLIVET/apps/clivet/urls.py'> (None:clivet) ^clivet/>], [<RegexURLResolver <module 'django.conf.urls.i18n' from '/home/rusbel/Proyectos/myvenv/lib/python3.5/site-packages/django/conf/urls/i18n.py'> (None:None) ^i18n/>], [<RegexURLPattern None ^jsi18n/>], [<RegexURLPattern None ^media\/(?P<path>.*)$>]], 'path': 'bootstrap/images/kittens.jpg'}

During handling of the above exception, another exception occurred:

Traceback (most recent call last):
  File "/home/rusbel/Proyectos/myvenv/lib/python3.5/site-packages/django/template/base.py", line 883, in _resolve_lookup
    current = current[bit]
TypeError: 'RegexURLResolver' object is not subscriptable

During handling of the above exception, another exception occurred:

Traceback (most recent call last):
  File "/home/rusbel/Proyectos/myvenv/lib/python3.5/site-packages/django/template/base.py", line 891, in _resolve_lookup
    current = getattr(current, bit)
AttributeError: 'RegexURLResolver' object has no attribute 'name'

During handling of the above exception, another exception occurred:

Traceback (most recent call last):
  File "/home/rusbel/Proyectos/myvenv/lib/python3.5/site-packages/django/template/base.py", line 898, in _resolve_lookup
    current = current[int(bit)]
ValueError: invalid literal for int() with base 10: 'name'

During handling of the above exception, another exception occurred:

Traceback (most recent call last):
  File "/home/rusbel/Proyectos/myvenv/lib/python3.5/site-packages/django/template/base.py", line 905, in _resolve_lookup
    (bit, current))  # missing attribute
django.template.base.VariableDoesNotExist: Failed lookup for key [name] in "<RegexURLResolver <module 'apps.sad.urls' from '/home/rusbel/Proyectos/Django/CLIVET/apps/sad/urls.py'> (None:sad) ^sad/>"
[2016-10-05 00:01:07] DEBUG [django.template:927] Exception while resolving variable 'name' in template 'unknown'.
Traceback (most recent call last):
  File "/home/rusbel/Proyectos/myvenv/lib/python3.5/site-packages/django/core/handlers/base.py", line 134, in get_response
    resolver_match = resolver.resolve(request.path_info)
  File "/home/rusbel/Proyectos/myvenv/lib/python3.5/site-packages/django/core/urlresolvers.py", line 404, in resolve
    raise Resolver404({'tried': tried, 'path': new_path})
django.core.urlresolvers.Resolver404: {'tried': [[<RegexURLResolver <RegexURLPattern list> (admin:admin) ^admin/>], [<RegexURLResolver <module 'django.contrib.admindocs.urls' from '/home/rusbel/Proyectos/myvenv/lib/python3.5/site-packages/django/contrib/admindocs/urls.py'> (None:None) ^admin/doc/>], [<RegexURLResolver <module 'apps.home.urls' from '/home/rusbel/Proyectos/Django/CLIVET/apps/home/urls.py'> (None:home) ^home/>], [<RegexURLPattern index ^$>], [<RegexURLResolver <module 'apps.space.urls' from '/home/rusbel/Proyectos/Django/CLIVET/apps/space/urls.py'> (None:space) ^space/>], [<RegexURLResolver <module 'apps.sad.urls' from '/home/rusbel/Proyectos/Django/CLIVET/apps/sad/urls.py'> (None:sad) ^sad/>], [<RegexURLResolver <module 'apps.mod_backend.urls' from '/home/rusbel/Proyectos/Django/CLIVET/apps/mod_backend/urls.py'> (None:mod_backend) ^mod_backend/>], [<RegexURLResolver <module 'apps.accounts.urls' from '/home/rusbel/Proyectos/Django/CLIVET/apps/accounts/urls.py'> (None:None) ^accounts/>], [<RegexURLResolver <module 'apps.clivet.urls' from '/home/rusbel/Proyectos/Django/CLIVET/apps/clivet/urls.py'> (None:clivet) ^clivet/>], [<RegexURLResolver <module 'django.conf.urls.i18n' from '/home/rusbel/Proyectos/myvenv/lib/python3.5/site-packages/django/conf/urls/i18n.py'> (None:None) ^i18n/>], [<RegexURLPattern None ^jsi18n/>], [<RegexURLPattern None ^media\/(?P<path>.*)$>]], 'path': 'bootstrap/images/kittens.jpg'}

During handling of the above exception, another exception occurred:

Traceback (most recent call last):
  File "/home/rusbel/Proyectos/myvenv/lib/python3.5/site-packages/django/template/base.py", line 883, in _resolve_lookup
    current = current[bit]
TypeError: 'RegexURLResolver' object is not subscriptable

During handling of the above exception, another exception occurred:

Traceback (most recent call last):
  File "/home/rusbel/Proyectos/myvenv/lib/python3.5/site-packages/django/template/base.py", line 891, in _resolve_lookup
    current = getattr(current, bit)
AttributeError: 'RegexURLResolver' object has no attribute 'name'

During handling of the above exception, another exception occurred:

Traceback (most recent call last):
  File "/home/rusbel/Proyectos/myvenv/lib/python3.5/site-packages/django/template/base.py", line 898, in _resolve_lookup
    current = current[int(bit)]
ValueError: invalid literal for int() with base 10: 'name'

During handling of the above exception, another exception occurred:

Traceback (most recent call last):
  File "/home/rusbel/Proyectos/myvenv/lib/python3.5/site-packages/django/template/base.py", line 905, in _resolve_lookup
    (bit, current))  # missing attribute
django.template.base.VariableDoesNotExist: Failed lookup for key [name] in "<RegexURLResolver <module 'apps.mod_backend.urls' from '/home/rusbel/Proyectos/Django/CLIVET/apps/mod_backend/urls.py'> (None:mod_backend) ^mod_backend/>"
[2016-10-05 00:01:07] DEBUG [django.template:927] Exception while resolving variable 'name' in template 'unknown'.
Traceback (most recent call last):
  File "/home/rusbel/Proyectos/myvenv/lib/python3.5/site-packages/django/core/handlers/base.py", line 134, in get_response
    resolver_match = resolver.resolve(request.path_info)
  File "/home/rusbel/Proyectos/myvenv/lib/python3.5/site-packages/django/core/urlresolvers.py", line 404, in resolve
    raise Resolver404({'tried': tried, 'path': new_path})
django.core.urlresolvers.Resolver404: {'tried': [[<RegexURLResolver <RegexURLPattern list> (admin:admin) ^admin/>], [<RegexURLResolver <module 'django.contrib.admindocs.urls' from '/home/rusbel/Proyectos/myvenv/lib/python3.5/site-packages/django/contrib/admindocs/urls.py'> (None:None) ^admin/doc/>], [<RegexURLResolver <module 'apps.home.urls' from '/home/rusbel/Proyectos/Django/CLIVET/apps/home/urls.py'> (None:home) ^home/>], [<RegexURLPattern index ^$>], [<RegexURLResolver <module 'apps.space.urls' from '/home/rusbel/Proyectos/Django/CLIVET/apps/space/urls.py'> (None:space) ^space/>], [<RegexURLResolver <module 'apps.sad.urls' from '/home/rusbel/Proyectos/Django/CLIVET/apps/sad/urls.py'> (None:sad) ^sad/>], [<RegexURLResolver <module 'apps.mod_backend.urls' from '/home/rusbel/Proyectos/Django/CLIVET/apps/mod_backend/urls.py'> (None:mod_backend) ^mod_backend/>], [<RegexURLResolver <module 'apps.accounts.urls' from '/home/rusbel/Proyectos/Django/CLIVET/apps/accounts/urls.py'> (None:None) ^accounts/>], [<RegexURLResolver <module 'apps.clivet.urls' from '/home/rusbel/Proyectos/Django/CLIVET/apps/clivet/urls.py'> (None:clivet) ^clivet/>], [<RegexURLResolver <module 'django.conf.urls.i18n' from '/home/rusbel/Proyectos/myvenv/lib/python3.5/site-packages/django/conf/urls/i18n.py'> (None:None) ^i18n/>], [<RegexURLPattern None ^jsi18n/>], [<RegexURLPattern None ^media\/(?P<path>.*)$>]], 'path': 'bootstrap/images/kittens.jpg'}

During handling of the above exception, another exception occurred:

Traceback (most recent call last):
  File "/home/rusbel/Proyectos/myvenv/lib/python3.5/site-packages/django/template/base.py", line 883, in _resolve_lookup
    current = current[bit]
TypeError: 'RegexURLResolver' object is not subscriptable

During handling of the above exception, another exception occurred:

Traceback (most recent call last):
  File "/home/rusbel/Proyectos/myvenv/lib/python3.5/site-packages/django/template/base.py", line 891, in _resolve_lookup
    current = getattr(current, bit)
AttributeError: 'RegexURLResolver' object has no attribute 'name'

During handling of the above exception, another exception occurred:

Traceback (most recent call last):
  File "/home/rusbel/Proyectos/myvenv/lib/python3.5/site-packages/django/template/base.py", line 898, in _resolve_lookup
    current = current[int(bit)]
ValueError: invalid literal for int() with base 10: 'name'

During handling of the above exception, another exception occurred:

Traceback (most recent call last):
  File "/home/rusbel/Proyectos/myvenv/lib/python3.5/site-packages/django/template/base.py", line 905, in _resolve_lookup
    (bit, current))  # missing attribute
django.template.base.VariableDoesNotExist: Failed lookup for key [name] in "<RegexURLResolver <module 'apps.accounts.urls' from '/home/rusbel/Proyectos/Django/CLIVET/apps/accounts/urls.py'> (None:None) ^accounts/>"
[2016-10-05 00:01:07] DEBUG [django.db.backends:89] (0.002) SELECT "django_session"."session_key", "django_session"."session_data", "django_session"."expire_date" FROM "django_session" WHERE ("django_session"."session_key" = '73tz8dalqomobmynelxwtkp1yjyaxv1o' AND "django_session"."expire_date" > '2016-10-05 00:01:07.953237'); args=('73tz8dalqomobmynelxwtkp1yjyaxv1o', '2016-10-05 00:01:07.953237')
[2016-10-05 00:01:07] DEBUG [django.template:927] Exception while resolving variable 'name' in template 'unknown'.
Traceback (most recent call last):
  File "/home/rusbel/Proyectos/myvenv/lib/python3.5/site-packages/django/core/handlers/base.py", line 134, in get_response
    resolver_match = resolver.resolve(request.path_info)
  File "/home/rusbel/Proyectos/myvenv/lib/python3.5/site-packages/django/core/urlresolvers.py", line 404, in resolve
    raise Resolver404({'tried': tried, 'path': new_path})
django.core.urlresolvers.Resolver404: {'tried': [[<RegexURLResolver <RegexURLPattern list> (admin:admin) ^admin/>], [<RegexURLResolver <module 'django.contrib.admindocs.urls' from '/home/rusbel/Proyectos/myvenv/lib/python3.5/site-packages/django/contrib/admindocs/urls.py'> (None:None) ^admin/doc/>], [<RegexURLResolver <module 'apps.home.urls' from '/home/rusbel/Proyectos/Django/CLIVET/apps/home/urls.py'> (None:home) ^home/>], [<RegexURLPattern index ^$>], [<RegexURLResolver <module 'apps.space.urls' from '/home/rusbel/Proyectos/Django/CLIVET/apps/space/urls.py'> (None:space) ^space/>], [<RegexURLResolver <module 'apps.sad.urls' from '/home/rusbel/Proyectos/Django/CLIVET/apps/sad/urls.py'> (None:sad) ^sad/>], [<RegexURLResolver <module 'apps.mod_backend.urls' from '/home/rusbel/Proyectos/Django/CLIVET/apps/mod_backend/urls.py'> (None:mod_backend) ^mod_backend/>], [<RegexURLResolver <module 'apps.accounts.urls' from '/home/rusbel/Proyectos/Django/CLIVET/apps/accounts/urls.py'> (None:None) ^accounts/>], [<RegexURLResolver <module 'apps.clivet.urls' from '/home/rusbel/Proyectos/Django/CLIVET/apps/clivet/urls.py'> (None:clivet) ^clivet/>], [<RegexURLResolver <module 'django.conf.urls.i18n' from '/home/rusbel/Proyectos/myvenv/lib/python3.5/site-packages/django/conf/urls/i18n.py'> (None:None) ^i18n/>], [<RegexURLPattern None ^jsi18n/>], [<RegexURLPattern None ^media\/(?P<path>.*)$>]], 'path': 'bootstrap/images/kittens.jpg'}

During handling of the above exception, another exception occurred:

Traceback (most recent call last):
  File "/home/rusbel/Proyectos/myvenv/lib/python3.5/site-packages/django/template/base.py", line 883, in _resolve_lookup
    current = current[bit]
TypeError: 'RegexURLResolver' object is not subscriptable

During handling of the above exception, another exception occurred:

Traceback (most recent call last):
  File "/home/rusbel/Proyectos/myvenv/lib/python3.5/site-packages/django/template/base.py", line 891, in _resolve_lookup
    current = getattr(current, bit)
AttributeError: 'RegexURLResolver' object has no attribute 'name'

During handling of the above exception, another exception occurred:

Traceback (most recent call last):
  File "/home/rusbel/Proyectos/myvenv/lib/python3.5/site-packages/django/template/base.py", line 898, in _resolve_lookup
    current = current[int(bit)]
ValueError: invalid literal for int() with base 10: 'name'

During handling of the above exception, another exception occurred:

Traceback (most recent call last):
  File "/home/rusbel/Proyectos/myvenv/lib/python3.5/site-packages/django/template/base.py", line 905, in _resolve_lookup
    (bit, current))  # missing attribute
django.template.base.VariableDoesNotExist: Failed lookup for key [name] in "<RegexURLResolver <module 'apps.clivet.urls' from '/home/rusbel/Proyectos/Django/CLIVET/apps/clivet/urls.py'> (None:clivet) ^clivet/>"
[2016-10-05 00:01:07] DEBUG [django.template:927] Exception while resolving variable 'name' in template 'unknown'.
Traceback (most recent call last):
  File "/home/rusbel/Proyectos/myvenv/lib/python3.5/site-packages/django/core/handlers/base.py", line 134, in get_response
    resolver_match = resolver.resolve(request.path_info)
  File "/home/rusbel/Proyectos/myvenv/lib/python3.5/site-packages/django/core/urlresolvers.py", line 404, in resolve
    raise Resolver404({'tried': tried, 'path': new_path})
django.core.urlresolvers.Resolver404: {'tried': [[<RegexURLResolver <RegexURLPattern list> (admin:admin) ^admin/>], [<RegexURLResolver <module 'django.contrib.admindocs.urls' from '/home/rusbel/Proyectos/myvenv/lib/python3.5/site-packages/django/contrib/admindocs/urls.py'> (None:None) ^admin/doc/>], [<RegexURLResolver <module 'apps.home.urls' from '/home/rusbel/Proyectos/Django/CLIVET/apps/home/urls.py'> (None:home) ^home/>], [<RegexURLPattern index ^$>], [<RegexURLResolver <module 'apps.space.urls' from '/home/rusbel/Proyectos/Django/CLIVET/apps/space/urls.py'> (None:space) ^space/>], [<RegexURLResolver <module 'apps.sad.urls' from '/home/rusbel/Proyectos/Django/CLIVET/apps/sad/urls.py'> (None:sad) ^sad/>], [<RegexURLResolver <module 'apps.mod_backend.urls' from '/home/rusbel/Proyectos/Django/CLIVET/apps/mod_backend/urls.py'> (None:mod_backend) ^mod_backend/>], [<RegexURLResolver <module 'apps.accounts.urls' from '/home/rusbel/Proyectos/Django/CLIVET/apps/accounts/urls.py'> (None:None) ^accounts/>], [<RegexURLResolver <module 'apps.clivet.urls' from '/home/rusbel/Proyectos/Django/CLIVET/apps/clivet/urls.py'> (None:clivet) ^clivet/>], [<RegexURLResolver <module 'django.conf.urls.i18n' from '/home/rusbel/Proyectos/myvenv/lib/python3.5/site-packages/django/conf/urls/i18n.py'> (None:None) ^i18n/>], [<RegexURLPattern None ^jsi18n/>], [<RegexURLPattern None ^media\/(?P<path>.*)$>]], 'path': 'bootstrap/images/kittens.jpg'}

During handling of the above exception, another exception occurred:

Traceback (most recent call last):
  File "/home/rusbel/Proyectos/myvenv/lib/python3.5/site-packages/django/template/base.py", line 883, in _resolve_lookup
    current = current[bit]
TypeError: 'RegexURLResolver' object is not subscriptable

During handling of the above exception, another exception occurred:

Traceback (most recent call last):
  File "/home/rusbel/Proyectos/myvenv/lib/python3.5/site-packages/django/template/base.py", line 891, in _resolve_lookup
    current = getattr(current, bit)
AttributeError: 'RegexURLResolver' object has no attribute 'name'

During handling of the above exception, another exception occurred:

Traceback (most recent call last):
  File "/home/rusbel/Proyectos/myvenv/lib/python3.5/site-packages/django/template/base.py", line 898, in _resolve_lookup
    current = current[int(bit)]
ValueError: invalid literal for int() with base 10: 'name'

During handling of the above exception, another exception occurred:

Traceback (most recent call last):
  File "/home/rusbel/Proyectos/myvenv/lib/python3.5/site-packages/django/template/base.py", line 905, in _resolve_lookup
    (bit, current))  # missing attribute
django.template.base.VariableDoesNotExist: Failed lookup for key [name] in "<RegexURLResolver <module 'django.conf.urls.i18n' from '/home/rusbel/Proyectos/myvenv/lib/python3.5/site-packages/django/conf/urls/i18n.py'> (None:None) ^i18n/>"
[2016-10-05 00:01:14] DEBUG [django.db.backends:89] (0.001) SELECT "django_session"."session_key", "django_session"."session_data", "django_session"."expire_date" FROM "django_session" WHERE ("django_session"."session_key" = '73tz8dalqomobmynelxwtkp1yjyaxv1o' AND "django_session"."expire_date" > '2016-10-05 00:01:14.742025'); args=('73tz8dalqomobmynelxwtkp1yjyaxv1o', '2016-10-05 00:01:14.742025')
[2016-10-05 00:01:14] DEBUG [django.db.backends:89] (0.001) SELECT "django_session"."session_key", "django_session"."session_data", "django_session"."expire_date" FROM "django_session" WHERE ("django_session"."session_key" = '73tz8dalqomobmynelxwtkp1yjyaxv1o' AND "django_session"."expire_date" > '2016-10-05 00:01:14.827824'); args=('73tz8dalqomobmynelxwtkp1yjyaxv1o', '2016-10-05 00:01:14.827824')
[2016-10-05 00:01:14] WARNING [django.request:182] Not Found: /bootstrap/images/kittens.jpg
[2016-10-05 00:01:14] DEBUG [django.template:927] Exception while resolving variable 'name' in template 'unknown'.
Traceback (most recent call last):
  File "/home/rusbel/Proyectos/myvenv/lib/python3.5/site-packages/django/core/handlers/base.py", line 134, in get_response
    resolver_match = resolver.resolve(request.path_info)
  File "/home/rusbel/Proyectos/myvenv/lib/python3.5/site-packages/django/core/urlresolvers.py", line 404, in resolve
    raise Resolver404({'tried': tried, 'path': new_path})
django.core.urlresolvers.Resolver404: {'tried': [[<RegexURLResolver <RegexURLPattern list> (admin:admin) ^admin/>], [<RegexURLResolver <module 'django.contrib.admindocs.urls' from '/home/rusbel/Proyectos/myvenv/lib/python3.5/site-packages/django/contrib/admindocs/urls.py'> (None:None) ^admin/doc/>], [<RegexURLResolver <module 'apps.home.urls' from '/home/rusbel/Proyectos/Django/CLIVET/apps/home/urls.py'> (None:home) ^home/>], [<RegexURLPattern index ^$>], [<RegexURLResolver <module 'apps.space.urls' from '/home/rusbel/Proyectos/Django/CLIVET/apps/space/urls.py'> (None:space) ^space/>], [<RegexURLResolver <module 'apps.sad.urls' from '/home/rusbel/Proyectos/Django/CLIVET/apps/sad/urls.py'> (None:sad) ^sad/>], [<RegexURLResolver <module 'apps.mod_backend.urls' from '/home/rusbel/Proyectos/Django/CLIVET/apps/mod_backend/urls.py'> (None:mod_backend) ^mod_backend/>], [<RegexURLResolver <module 'apps.accounts.urls' from '/home/rusbel/Proyectos/Django/CLIVET/apps/accounts/urls.py'> (None:None) ^accounts/>], [<RegexURLResolver <module 'apps.clivet.urls' from '/home/rusbel/Proyectos/Django/CLIVET/apps/clivet/urls.py'> (None:clivet) ^clivet/>], [<RegexURLResolver <module 'django.conf.urls.i18n' from '/home/rusbel/Proyectos/myvenv/lib/python3.5/site-packages/django/conf/urls/i18n.py'> (None:None) ^i18n/>], [<RegexURLPattern None ^jsi18n/>], [<RegexURLPattern None ^media\/(?P<path>.*)$>]], 'path': 'bootstrap/images/kittens.jpg'}

During handling of the above exception, another exception occurred:

Traceback (most recent call last):
  File "/home/rusbel/Proyectos/myvenv/lib/python3.5/site-packages/django/template/base.py", line 883, in _resolve_lookup
    current = current[bit]
TypeError: 'RegexURLResolver' object is not subscriptable

During handling of the above exception, another exception occurred:

Traceback (most recent call last):
  File "/home/rusbel/Proyectos/myvenv/lib/python3.5/site-packages/django/template/base.py", line 891, in _resolve_lookup
    current = getattr(current, bit)
AttributeError: 'RegexURLResolver' object has no attribute 'name'

During handling of the above exception, another exception occurred:

Traceback (most recent call last):
  File "/home/rusbel/Proyectos/myvenv/lib/python3.5/site-packages/django/template/base.py", line 898, in _resolve_lookup
    current = current[int(bit)]
ValueError: invalid literal for int() with base 10: 'name'

During handling of the above exception, another exception occurred:

Traceback (most recent call last):
  File "/home/rusbel/Proyectos/myvenv/lib/python3.5/site-packages/django/template/base.py", line 905, in _resolve_lookup
    (bit, current))  # missing attribute
django.template.base.VariableDoesNotExist: Failed lookup for key [name] in '<RegexURLResolver <RegexURLPattern list> (admin:admin) ^admin/>'
[2016-10-05 00:01:14] DEBUG [django.template:927] Exception while resolving variable 'name' in template 'unknown'.
Traceback (most recent call last):
  File "/home/rusbel/Proyectos/myvenv/lib/python3.5/site-packages/django/core/handlers/base.py", line 134, in get_response
    resolver_match = resolver.resolve(request.path_info)
  File "/home/rusbel/Proyectos/myvenv/lib/python3.5/site-packages/django/core/urlresolvers.py", line 404, in resolve
    raise Resolver404({'tried': tried, 'path': new_path})
django.core.urlresolvers.Resolver404: {'tried': [[<RegexURLResolver <RegexURLPattern list> (admin:admin) ^admin/>], [<RegexURLResolver <module 'django.contrib.admindocs.urls' from '/home/rusbel/Proyectos/myvenv/lib/python3.5/site-packages/django/contrib/admindocs/urls.py'> (None:None) ^admin/doc/>], [<RegexURLResolver <module 'apps.home.urls' from '/home/rusbel/Proyectos/Django/CLIVET/apps/home/urls.py'> (None:home) ^home/>], [<RegexURLPattern index ^$>], [<RegexURLResolver <module 'apps.space.urls' from '/home/rusbel/Proyectos/Django/CLIVET/apps/space/urls.py'> (None:space) ^space/>], [<RegexURLResolver <module 'apps.sad.urls' from '/home/rusbel/Proyectos/Django/CLIVET/apps/sad/urls.py'> (None:sad) ^sad/>], [<RegexURLResolver <module 'apps.mod_backend.urls' from '/home/rusbel/Proyectos/Django/CLIVET/apps/mod_backend/urls.py'> (None:mod_backend) ^mod_backend/>], [<RegexURLResolver <module 'apps.accounts.urls' from '/home/rusbel/Proyectos/Django/CLIVET/apps/accounts/urls.py'> (None:None) ^accounts/>], [<RegexURLResolver <module 'apps.clivet.urls' from '/home/rusbel/Proyectos/Django/CLIVET/apps/clivet/urls.py'> (None:clivet) ^clivet/>], [<RegexURLResolver <module 'django.conf.urls.i18n' from '/home/rusbel/Proyectos/myvenv/lib/python3.5/site-packages/django/conf/urls/i18n.py'> (None:None) ^i18n/>], [<RegexURLPattern None ^jsi18n/>], [<RegexURLPattern None ^media\/(?P<path>.*)$>]], 'path': 'bootstrap/images/kittens.jpg'}

During handling of the above exception, another exception occurred:

Traceback (most recent call last):
  File "/home/rusbel/Proyectos/myvenv/lib/python3.5/site-packages/django/template/base.py", line 883, in _resolve_lookup
    current = current[bit]
TypeError: 'RegexURLResolver' object is not subscriptable

During handling of the above exception, another exception occurred:

Traceback (most recent call last):
  File "/home/rusbel/Proyectos/myvenv/lib/python3.5/site-packages/django/template/base.py", line 891, in _resolve_lookup
    current = getattr(current, bit)
AttributeError: 'RegexURLResolver' object has no attribute 'name'

During handling of the above exception, another exception occurred:

Traceback (most recent call last):
  File "/home/rusbel/Proyectos/myvenv/lib/python3.5/site-packages/django/template/base.py", line 898, in _resolve_lookup
    current = current[int(bit)]
ValueError: invalid literal for int() with base 10: 'name'

During handling of the above exception, another exception occurred:

Traceback (most recent call last):
  File "/home/rusbel/Proyectos/myvenv/lib/python3.5/site-packages/django/template/base.py", line 905, in _resolve_lookup
    (bit, current))  # missing attribute
django.template.base.VariableDoesNotExist: Failed lookup for key [name] in "<RegexURLResolver <module 'django.contrib.admindocs.urls' from '/home/rusbel/Proyectos/myvenv/lib/python3.5/site-packages/django/contrib/admindocs/urls.py'> (None:None) ^admin/doc/>"
[2016-10-05 00:01:14] DEBUG [django.template:927] Exception while resolving variable 'name' in template 'unknown'.
Traceback (most recent call last):
  File "/home/rusbel/Proyectos/myvenv/lib/python3.5/site-packages/django/core/handlers/base.py", line 134, in get_response
    resolver_match = resolver.resolve(request.path_info)
  File "/home/rusbel/Proyectos/myvenv/lib/python3.5/site-packages/django/core/urlresolvers.py", line 404, in resolve
    raise Resolver404({'tried': tried, 'path': new_path})
django.core.urlresolvers.Resolver404: {'tried': [[<RegexURLResolver <RegexURLPattern list> (admin:admin) ^admin/>], [<RegexURLResolver <module 'django.contrib.admindocs.urls' from '/home/rusbel/Proyectos/myvenv/lib/python3.5/site-packages/django/contrib/admindocs/urls.py'> (None:None) ^admin/doc/>], [<RegexURLResolver <module 'apps.home.urls' from '/home/rusbel/Proyectos/Django/CLIVET/apps/home/urls.py'> (None:home) ^home/>], [<RegexURLPattern index ^$>], [<RegexURLResolver <module 'apps.space.urls' from '/home/rusbel/Proyectos/Django/CLIVET/apps/space/urls.py'> (None:space) ^space/>], [<RegexURLResolver <module 'apps.sad.urls' from '/home/rusbel/Proyectos/Django/CLIVET/apps/sad/urls.py'> (None:sad) ^sad/>], [<RegexURLResolver <module 'apps.mod_backend.urls' from '/home/rusbel/Proyectos/Django/CLIVET/apps/mod_backend/urls.py'> (None:mod_backend) ^mod_backend/>], [<RegexURLResolver <module 'apps.accounts.urls' from '/home/rusbel/Proyectos/Django/CLIVET/apps/accounts/urls.py'> (None:None) ^accounts/>], [<RegexURLResolver <module 'apps.clivet.urls' from '/home/rusbel/Proyectos/Django/CLIVET/apps/clivet/urls.py'> (None:clivet) ^clivet/>], [<RegexURLResolver <module 'django.conf.urls.i18n' from '/home/rusbel/Proyectos/myvenv/lib/python3.5/site-packages/django/conf/urls/i18n.py'> (None:None) ^i18n/>], [<RegexURLPattern None ^jsi18n/>], [<RegexURLPattern None ^media\/(?P<path>.*)$>]], 'path': 'bootstrap/images/kittens.jpg'}

During handling of the above exception, another exception occurred:

Traceback (most recent call last):
  File "/home/rusbel/Proyectos/myvenv/lib/python3.5/site-packages/django/template/base.py", line 883, in _resolve_lookup
    current = current[bit]
TypeError: 'RegexURLResolver' object is not subscriptable

During handling of the above exception, another exception occurred:

Traceback (most recent call last):
  File "/home/rusbel/Proyectos/myvenv/lib/python3.5/site-packages/django/template/base.py", line 891, in _resolve_lookup
    current = getattr(current, bit)
AttributeError: 'RegexURLResolver' object has no attribute 'name'

During handling of the above exception, another exception occurred:

Traceback (most recent call last):
  File "/home/rusbel/Proyectos/myvenv/lib/python3.5/site-packages/django/template/base.py", line 898, in _resolve_lookup
    current = current[int(bit)]
ValueError: invalid literal for int() with base 10: 'name'

During handling of the above exception, another exception occurred:

Traceback (most recent call last):
  File "/home/rusbel/Proyectos/myvenv/lib/python3.5/site-packages/django/template/base.py", line 905, in _resolve_lookup
    (bit, current))  # missing attribute
django.template.base.VariableDoesNotExist: Failed lookup for key [name] in "<RegexURLResolver <module 'apps.home.urls' from '/home/rusbel/Proyectos/Django/CLIVET/apps/home/urls.py'> (None:home) ^home/>"
[2016-10-05 00:01:14] DEBUG [django.template:927] Exception while resolving variable 'name' in template 'unknown'.
Traceback (most recent call last):
  File "/home/rusbel/Proyectos/myvenv/lib/python3.5/site-packages/django/core/handlers/base.py", line 134, in get_response
    resolver_match = resolver.resolve(request.path_info)
  File "/home/rusbel/Proyectos/myvenv/lib/python3.5/site-packages/django/core/urlresolvers.py", line 404, in resolve
    raise Resolver404({'tried': tried, 'path': new_path})
django.core.urlresolvers.Resolver404: {'tried': [[<RegexURLResolver <RegexURLPattern list> (admin:admin) ^admin/>], [<RegexURLResolver <module 'django.contrib.admindocs.urls' from '/home/rusbel/Proyectos/myvenv/lib/python3.5/site-packages/django/contrib/admindocs/urls.py'> (None:None) ^admin/doc/>], [<RegexURLResolver <module 'apps.home.urls' from '/home/rusbel/Proyectos/Django/CLIVET/apps/home/urls.py'> (None:home) ^home/>], [<RegexURLPattern index ^$>], [<RegexURLResolver <module 'apps.space.urls' from '/home/rusbel/Proyectos/Django/CLIVET/apps/space/urls.py'> (None:space) ^space/>], [<RegexURLResolver <module 'apps.sad.urls' from '/home/rusbel/Proyectos/Django/CLIVET/apps/sad/urls.py'> (None:sad) ^sad/>], [<RegexURLResolver <module 'apps.mod_backend.urls' from '/home/rusbel/Proyectos/Django/CLIVET/apps/mod_backend/urls.py'> (None:mod_backend) ^mod_backend/>], [<RegexURLResolver <module 'apps.accounts.urls' from '/home/rusbel/Proyectos/Django/CLIVET/apps/accounts/urls.py'> (None:None) ^accounts/>], [<RegexURLResolver <module 'apps.clivet.urls' from '/home/rusbel/Proyectos/Django/CLIVET/apps/clivet/urls.py'> (None:clivet) ^clivet/>], [<RegexURLResolver <module 'django.conf.urls.i18n' from '/home/rusbel/Proyectos/myvenv/lib/python3.5/site-packages/django/conf/urls/i18n.py'> (None:None) ^i18n/>], [<RegexURLPattern None ^jsi18n/>], [<RegexURLPattern None ^media\/(?P<path>.*)$>]], 'path': 'bootstrap/images/kittens.jpg'}

During handling of the above exception, another exception occurred:

Traceback (most recent call last):
  File "/home/rusbel/Proyectos/myvenv/lib/python3.5/site-packages/django/template/base.py", line 883, in _resolve_lookup
    current = current[bit]
TypeError: 'RegexURLResolver' object is not subscriptable

During handling of the above exception, another exception occurred:

Traceback (most recent call last):
  File "/home/rusbel/Proyectos/myvenv/lib/python3.5/site-packages/django/template/base.py", line 891, in _resolve_lookup
    current = getattr(current, bit)
AttributeError: 'RegexURLResolver' object has no attribute 'name'

During handling of the above exception, another exception occurred:

Traceback (most recent call last):
  File "/home/rusbel/Proyectos/myvenv/lib/python3.5/site-packages/django/template/base.py", line 898, in _resolve_lookup
    current = current[int(bit)]
ValueError: invalid literal for int() with base 10: 'name'

During handling of the above exception, another exception occurred:

Traceback (most recent call last):
  File "/home/rusbel/Proyectos/myvenv/lib/python3.5/site-packages/django/template/base.py", line 905, in _resolve_lookup
    (bit, current))  # missing attribute
django.template.base.VariableDoesNotExist: Failed lookup for key [name] in "<RegexURLResolver <module 'apps.space.urls' from '/home/rusbel/Proyectos/Django/CLIVET/apps/space/urls.py'> (None:space) ^space/>"
[2016-10-05 00:01:14] DEBUG [django.template:927] Exception while resolving variable 'name' in template 'unknown'.
Traceback (most recent call last):
  File "/home/rusbel/Proyectos/myvenv/lib/python3.5/site-packages/django/core/handlers/base.py", line 134, in get_response
    resolver_match = resolver.resolve(request.path_info)
  File "/home/rusbel/Proyectos/myvenv/lib/python3.5/site-packages/django/core/urlresolvers.py", line 404, in resolve
    raise Resolver404({'tried': tried, 'path': new_path})
django.core.urlresolvers.Resolver404: {'tried': [[<RegexURLResolver <RegexURLPattern list> (admin:admin) ^admin/>], [<RegexURLResolver <module 'django.contrib.admindocs.urls' from '/home/rusbel/Proyectos/myvenv/lib/python3.5/site-packages/django/contrib/admindocs/urls.py'> (None:None) ^admin/doc/>], [<RegexURLResolver <module 'apps.home.urls' from '/home/rusbel/Proyectos/Django/CLIVET/apps/home/urls.py'> (None:home) ^home/>], [<RegexURLPattern index ^$>], [<RegexURLResolver <module 'apps.space.urls' from '/home/rusbel/Proyectos/Django/CLIVET/apps/space/urls.py'> (None:space) ^space/>], [<RegexURLResolver <module 'apps.sad.urls' from '/home/rusbel/Proyectos/Django/CLIVET/apps/sad/urls.py'> (None:sad) ^sad/>], [<RegexURLResolver <module 'apps.mod_backend.urls' from '/home/rusbel/Proyectos/Django/CLIVET/apps/mod_backend/urls.py'> (None:mod_backend) ^mod_backend/>], [<RegexURLResolver <module 'apps.accounts.urls' from '/home/rusbel/Proyectos/Django/CLIVET/apps/accounts/urls.py'> (None:None) ^accounts/>], [<RegexURLResolver <module 'apps.clivet.urls' from '/home/rusbel/Proyectos/Django/CLIVET/apps/clivet/urls.py'> (None:clivet) ^clivet/>], [<RegexURLResolver <module 'django.conf.urls.i18n' from '/home/rusbel/Proyectos/myvenv/lib/python3.5/site-packages/django/conf/urls/i18n.py'> (None:None) ^i18n/>], [<RegexURLPattern None ^jsi18n/>], [<RegexURLPattern None ^media\/(?P<path>.*)$>]], 'path': 'bootstrap/images/kittens.jpg'}

During handling of the above exception, another exception occurred:

Traceback (most recent call last):
  File "/home/rusbel/Proyectos/myvenv/lib/python3.5/site-packages/django/template/base.py", line 883, in _resolve_lookup
    current = current[bit]
TypeError: 'RegexURLResolver' object is not subscriptable

During handling of the above exception, another exception occurred:

Traceback (most recent call last):
  File "/home/rusbel/Proyectos/myvenv/lib/python3.5/site-packages/django/template/base.py", line 891, in _resolve_lookup
    current = getattr(current, bit)
AttributeError: 'RegexURLResolver' object has no attribute 'name'

During handling of the above exception, another exception occurred:

Traceback (most recent call last):
  File "/home/rusbel/Proyectos/myvenv/lib/python3.5/site-packages/django/template/base.py", line 898, in _resolve_lookup
    current = current[int(bit)]
ValueError: invalid literal for int() with base 10: 'name'

During handling of the above exception, another exception occurred:

Traceback (most recent call last):
  File "/home/rusbel/Proyectos/myvenv/lib/python3.5/site-packages/django/template/base.py", line 905, in _resolve_lookup
    (bit, current))  # missing attribute
django.template.base.VariableDoesNotExist: Failed lookup for key [name] in "<RegexURLResolver <module 'apps.sad.urls' from '/home/rusbel/Proyectos/Django/CLIVET/apps/sad/urls.py'> (None:sad) ^sad/>"
[2016-10-05 00:01:14] DEBUG [django.template:927] Exception while resolving variable 'name' in template 'unknown'.
Traceback (most recent call last):
  File "/home/rusbel/Proyectos/myvenv/lib/python3.5/site-packages/django/core/handlers/base.py", line 134, in get_response
    resolver_match = resolver.resolve(request.path_info)
  File "/home/rusbel/Proyectos/myvenv/lib/python3.5/site-packages/django/core/urlresolvers.py", line 404, in resolve
    raise Resolver404({'tried': tried, 'path': new_path})
django.core.urlresolvers.Resolver404: {'tried': [[<RegexURLResolver <RegexURLPattern list> (admin:admin) ^admin/>], [<RegexURLResolver <module 'django.contrib.admindocs.urls' from '/home/rusbel/Proyectos/myvenv/lib/python3.5/site-packages/django/contrib/admindocs/urls.py'> (None:None) ^admin/doc/>], [<RegexURLResolver <module 'apps.home.urls' from '/home/rusbel/Proyectos/Django/CLIVET/apps/home/urls.py'> (None:home) ^home/>], [<RegexURLPattern index ^$>], [<RegexURLResolver <module 'apps.space.urls' from '/home/rusbel/Proyectos/Django/CLIVET/apps/space/urls.py'> (None:space) ^space/>], [<RegexURLResolver <module 'apps.sad.urls' from '/home/rusbel/Proyectos/Django/CLIVET/apps/sad/urls.py'> (None:sad) ^sad/>], [<RegexURLResolver <module 'apps.mod_backend.urls' from '/home/rusbel/Proyectos/Django/CLIVET/apps/mod_backend/urls.py'> (None:mod_backend) ^mod_backend/>], [<RegexURLResolver <module 'apps.accounts.urls' from '/home/rusbel/Proyectos/Django/CLIVET/apps/accounts/urls.py'> (None:None) ^accounts/>], [<RegexURLResolver <module 'apps.clivet.urls' from '/home/rusbel/Proyectos/Django/CLIVET/apps/clivet/urls.py'> (None:clivet) ^clivet/>], [<RegexURLResolver <module 'django.conf.urls.i18n' from '/home/rusbel/Proyectos/myvenv/lib/python3.5/site-packages/django/conf/urls/i18n.py'> (None:None) ^i18n/>], [<RegexURLPattern None ^jsi18n/>], [<RegexURLPattern None ^media\/(?P<path>.*)$>]], 'path': 'bootstrap/images/kittens.jpg'}

During handling of the above exception, another exception occurred:

Traceback (most recent call last):
  File "/home/rusbel/Proyectos/myvenv/lib/python3.5/site-packages/django/template/base.py", line 883, in _resolve_lookup
    current = current[bit]
TypeError: 'RegexURLResolver' object is not subscriptable

During handling of the above exception, another exception occurred:

Traceback (most recent call last):
  File "/home/rusbel/Proyectos/myvenv/lib/python3.5/site-packages/django/template/base.py", line 891, in _resolve_lookup
    current = getattr(current, bit)
AttributeError: 'RegexURLResolver' object has no attribute 'name'

During handling of the above exception, another exception occurred:

Traceback (most recent call last):
  File "/home/rusbel/Proyectos/myvenv/lib/python3.5/site-packages/django/template/base.py", line 898, in _resolve_lookup
    current = current[int(bit)]
ValueError: invalid literal for int() with base 10: 'name'

During handling of the above exception, another exception occurred:

Traceback (most recent call last):
  File "/home/rusbel/Proyectos/myvenv/lib/python3.5/site-packages/django/template/base.py", line 905, in _resolve_lookup
    (bit, current))  # missing attribute
django.template.base.VariableDoesNotExist: Failed lookup for key [name] in "<RegexURLResolver <module 'apps.mod_backend.urls' from '/home/rusbel/Proyectos/Django/CLIVET/apps/mod_backend/urls.py'> (None:mod_backend) ^mod_backend/>"
[2016-10-05 00:01:14] DEBUG [django.template:927] Exception while resolving variable 'name' in template 'unknown'.
Traceback (most recent call last):
  File "/home/rusbel/Proyectos/myvenv/lib/python3.5/site-packages/django/core/handlers/base.py", line 134, in get_response
    resolver_match = resolver.resolve(request.path_info)
  File "/home/rusbel/Proyectos/myvenv/lib/python3.5/site-packages/django/core/urlresolvers.py", line 404, in resolve
    raise Resolver404({'tried': tried, 'path': new_path})
django.core.urlresolvers.Resolver404: {'tried': [[<RegexURLResolver <RegexURLPattern list> (admin:admin) ^admin/>], [<RegexURLResolver <module 'django.contrib.admindocs.urls' from '/home/rusbel/Proyectos/myvenv/lib/python3.5/site-packages/django/contrib/admindocs/urls.py'> (None:None) ^admin/doc/>], [<RegexURLResolver <module 'apps.home.urls' from '/home/rusbel/Proyectos/Django/CLIVET/apps/home/urls.py'> (None:home) ^home/>], [<RegexURLPattern index ^$>], [<RegexURLResolver <module 'apps.space.urls' from '/home/rusbel/Proyectos/Django/CLIVET/apps/space/urls.py'> (None:space) ^space/>], [<RegexURLResolver <module 'apps.sad.urls' from '/home/rusbel/Proyectos/Django/CLIVET/apps/sad/urls.py'> (None:sad) ^sad/>], [<RegexURLResolver <module 'apps.mod_backend.urls' from '/home/rusbel/Proyectos/Django/CLIVET/apps/mod_backend/urls.py'> (None:mod_backend) ^mod_backend/>], [<RegexURLResolver <module 'apps.accounts.urls' from '/home/rusbel/Proyectos/Django/CLIVET/apps/accounts/urls.py'> (None:None) ^accounts/>], [<RegexURLResolver <module 'apps.clivet.urls' from '/home/rusbel/Proyectos/Django/CLIVET/apps/clivet/urls.py'> (None:clivet) ^clivet/>], [<RegexURLResolver <module 'django.conf.urls.i18n' from '/home/rusbel/Proyectos/myvenv/lib/python3.5/site-packages/django/conf/urls/i18n.py'> (None:None) ^i18n/>], [<RegexURLPattern None ^jsi18n/>], [<RegexURLPattern None ^media\/(?P<path>.*)$>]], 'path': 'bootstrap/images/kittens.jpg'}

During handling of the above exception, another exception occurred:

Traceback (most recent call last):
  File "/home/rusbel/Proyectos/myvenv/lib/python3.5/site-packages/django/template/base.py", line 883, in _resolve_lookup
    current = current[bit]
TypeError: 'RegexURLResolver' object is not subscriptable

During handling of the above exception, another exception occurred:

Traceback (most recent call last):
  File "/home/rusbel/Proyectos/myvenv/lib/python3.5/site-packages/django/template/base.py", line 891, in _resolve_lookup
    current = getattr(current, bit)
AttributeError: 'RegexURLResolver' object has no attribute 'name'

During handling of the above exception, another exception occurred:

Traceback (most recent call last):
  File "/home/rusbel/Proyectos/myvenv/lib/python3.5/site-packages/django/template/base.py", line 898, in _resolve_lookup
    current = current[int(bit)]
ValueError: invalid literal for int() with base 10: 'name'

During handling of the above exception, another exception occurred:

Traceback (most recent call last):
  File "/home/rusbel/Proyectos/myvenv/lib/python3.5/site-packages/django/template/base.py", line 905, in _resolve_lookup
    (bit, current))  # missing attribute
django.template.base.VariableDoesNotExist: Failed lookup for key [name] in "<RegexURLResolver <module 'apps.accounts.urls' from '/home/rusbel/Proyectos/Django/CLIVET/apps/accounts/urls.py'> (None:None) ^accounts/>"
[2016-10-05 00:01:14] DEBUG [django.template:927] Exception while resolving variable 'name' in template 'unknown'.
Traceback (most recent call last):
  File "/home/rusbel/Proyectos/myvenv/lib/python3.5/site-packages/django/core/handlers/base.py", line 134, in get_response
    resolver_match = resolver.resolve(request.path_info)
  File "/home/rusbel/Proyectos/myvenv/lib/python3.5/site-packages/django/core/urlresolvers.py", line 404, in resolve
    raise Resolver404({'tried': tried, 'path': new_path})
django.core.urlresolvers.Resolver404: {'tried': [[<RegexURLResolver <RegexURLPattern list> (admin:admin) ^admin/>], [<RegexURLResolver <module 'django.contrib.admindocs.urls' from '/home/rusbel/Proyectos/myvenv/lib/python3.5/site-packages/django/contrib/admindocs/urls.py'> (None:None) ^admin/doc/>], [<RegexURLResolver <module 'apps.home.urls' from '/home/rusbel/Proyectos/Django/CLIVET/apps/home/urls.py'> (None:home) ^home/>], [<RegexURLPattern index ^$>], [<RegexURLResolver <module 'apps.space.urls' from '/home/rusbel/Proyectos/Django/CLIVET/apps/space/urls.py'> (None:space) ^space/>], [<RegexURLResolver <module 'apps.sad.urls' from '/home/rusbel/Proyectos/Django/CLIVET/apps/sad/urls.py'> (None:sad) ^sad/>], [<RegexURLResolver <module 'apps.mod_backend.urls' from '/home/rusbel/Proyectos/Django/CLIVET/apps/mod_backend/urls.py'> (None:mod_backend) ^mod_backend/>], [<RegexURLResolver <module 'apps.accounts.urls' from '/home/rusbel/Proyectos/Django/CLIVET/apps/accounts/urls.py'> (None:None) ^accounts/>], [<RegexURLResolver <module 'apps.clivet.urls' from '/home/rusbel/Proyectos/Django/CLIVET/apps/clivet/urls.py'> (None:clivet) ^clivet/>], [<RegexURLResolver <module 'django.conf.urls.i18n' from '/home/rusbel/Proyectos/myvenv/lib/python3.5/site-packages/django/conf/urls/i18n.py'> (None:None) ^i18n/>], [<RegexURLPattern None ^jsi18n/>], [<RegexURLPattern None ^media\/(?P<path>.*)$>]], 'path': 'bootstrap/images/kittens.jpg'}

During handling of the above exception, another exception occurred:

Traceback (most recent call last):
  File "/home/rusbel/Proyectos/myvenv/lib/python3.5/site-packages/django/template/base.py", line 883, in _resolve_lookup
    current = current[bit]
TypeError: 'RegexURLResolver' object is not subscriptable

During handling of the above exception, another exception occurred:

Traceback (most recent call last):
  File "/home/rusbel/Proyectos/myvenv/lib/python3.5/site-packages/django/template/base.py", line 891, in _resolve_lookup
    current = getattr(current, bit)
AttributeError: 'RegexURLResolver' object has no attribute 'name'

During handling of the above exception, another exception occurred:

Traceback (most recent call last):
  File "/home/rusbel/Proyectos/myvenv/lib/python3.5/site-packages/django/template/base.py", line 898, in _resolve_lookup
    current = current[int(bit)]
ValueError: invalid literal for int() with base 10: 'name'

During handling of the above exception, another exception occurred:

Traceback (most recent call last):
  File "/home/rusbel/Proyectos/myvenv/lib/python3.5/site-packages/django/template/base.py", line 905, in _resolve_lookup
    (bit, current))  # missing attribute
django.template.base.VariableDoesNotExist: Failed lookup for key [name] in "<RegexURLResolver <module 'apps.clivet.urls' from '/home/rusbel/Proyectos/Django/CLIVET/apps/clivet/urls.py'> (None:clivet) ^clivet/>"
[2016-10-05 00:01:14] DEBUG [django.template:927] Exception while resolving variable 'name' in template 'unknown'.
Traceback (most recent call last):
  File "/home/rusbel/Proyectos/myvenv/lib/python3.5/site-packages/django/core/handlers/base.py", line 134, in get_response
    resolver_match = resolver.resolve(request.path_info)
  File "/home/rusbel/Proyectos/myvenv/lib/python3.5/site-packages/django/core/urlresolvers.py", line 404, in resolve
    raise Resolver404({'tried': tried, 'path': new_path})
django.core.urlresolvers.Resolver404: {'tried': [[<RegexURLResolver <RegexURLPattern list> (admin:admin) ^admin/>], [<RegexURLResolver <module 'django.contrib.admindocs.urls' from '/home/rusbel/Proyectos/myvenv/lib/python3.5/site-packages/django/contrib/admindocs/urls.py'> (None:None) ^admin/doc/>], [<RegexURLResolver <module 'apps.home.urls' from '/home/rusbel/Proyectos/Django/CLIVET/apps/home/urls.py'> (None:home) ^home/>], [<RegexURLPattern index ^$>], [<RegexURLResolver <module 'apps.space.urls' from '/home/rusbel/Proyectos/Django/CLIVET/apps/space/urls.py'> (None:space) ^space/>], [<RegexURLResolver <module 'apps.sad.urls' from '/home/rusbel/Proyectos/Django/CLIVET/apps/sad/urls.py'> (None:sad) ^sad/>], [<RegexURLResolver <module 'apps.mod_backend.urls' from '/home/rusbel/Proyectos/Django/CLIVET/apps/mod_backend/urls.py'> (None:mod_backend) ^mod_backend/>], [<RegexURLResolver <module 'apps.accounts.urls' from '/home/rusbel/Proyectos/Django/CLIVET/apps/accounts/urls.py'> (None:None) ^accounts/>], [<RegexURLResolver <module 'apps.clivet.urls' from '/home/rusbel/Proyectos/Django/CLIVET/apps/clivet/urls.py'> (None:clivet) ^clivet/>], [<RegexURLResolver <module 'django.conf.urls.i18n' from '/home/rusbel/Proyectos/myvenv/lib/python3.5/site-packages/django/conf/urls/i18n.py'> (None:None) ^i18n/>], [<RegexURLPattern None ^jsi18n/>], [<RegexURLPattern None ^media\/(?P<path>.*)$>]], 'path': 'bootstrap/images/kittens.jpg'}

During handling of the above exception, another exception occurred:

Traceback (most recent call last):
  File "/home/rusbel/Proyectos/myvenv/lib/python3.5/site-packages/django/template/base.py", line 883, in _resolve_lookup
    current = current[bit]
TypeError: 'RegexURLResolver' object is not subscriptable

During handling of the above exception, another exception occurred:

Traceback (most recent call last):
  File "/home/rusbel/Proyectos/myvenv/lib/python3.5/site-packages/django/template/base.py", line 891, in _resolve_lookup
    current = getattr(current, bit)
AttributeError: 'RegexURLResolver' object has no attribute 'name'

During handling of the above exception, another exception occurred:

Traceback (most recent call last):
  File "/home/rusbel/Proyectos/myvenv/lib/python3.5/site-packages/django/template/base.py", line 898, in _resolve_lookup
    current = current[int(bit)]
ValueError: invalid literal for int() with base 10: 'name'

During handling of the above exception, another exception occurred:

Traceback (most recent call last):
  File "/home/rusbel/Proyectos/myvenv/lib/python3.5/site-packages/django/template/base.py", line 905, in _resolve_lookup
    (bit, current))  # missing attribute
django.template.base.VariableDoesNotExist: Failed lookup for key [name] in "<RegexURLResolver <module 'django.conf.urls.i18n' from '/home/rusbel/Proyectos/myvenv/lib/python3.5/site-packages/django/conf/urls/i18n.py'> (None:None) ^i18n/>"
[2016-10-05 00:01:14] DEBUG [django.db.backends:89] (0.001) SELECT "django_session"."session_key", "django_session"."session_data", "django_session"."expire_date" FROM "django_session" WHERE ("django_session"."session_key" = '73tz8dalqomobmynelxwtkp1yjyaxv1o' AND "django_session"."expire_date" > '2016-10-05 00:01:14.929796'); args=('73tz8dalqomobmynelxwtkp1yjyaxv1o', '2016-10-05 00:01:14.929796')
[2016-10-05 00:01:14] WARNING [django.request:182] Not Found: /bootstrap/images/kittens.jpg
[2016-10-05 00:01:14] DEBUG [django.template:927] Exception while resolving variable 'name' in template 'unknown'.
Traceback (most recent call last):
  File "/home/rusbel/Proyectos/myvenv/lib/python3.5/site-packages/django/core/handlers/base.py", line 134, in get_response
    resolver_match = resolver.resolve(request.path_info)
  File "/home/rusbel/Proyectos/myvenv/lib/python3.5/site-packages/django/core/urlresolvers.py", line 404, in resolve
    raise Resolver404({'tried': tried, 'path': new_path})
django.core.urlresolvers.Resolver404: {'tried': [[<RegexURLResolver <RegexURLPattern list> (admin:admin) ^admin/>], [<RegexURLResolver <module 'django.contrib.admindocs.urls' from '/home/rusbel/Proyectos/myvenv/lib/python3.5/site-packages/django/contrib/admindocs/urls.py'> (None:None) ^admin/doc/>], [<RegexURLResolver <module 'apps.home.urls' from '/home/rusbel/Proyectos/Django/CLIVET/apps/home/urls.py'> (None:home) ^home/>], [<RegexURLPattern index ^$>], [<RegexURLResolver <module 'apps.space.urls' from '/home/rusbel/Proyectos/Django/CLIVET/apps/space/urls.py'> (None:space) ^space/>], [<RegexURLResolver <module 'apps.sad.urls' from '/home/rusbel/Proyectos/Django/CLIVET/apps/sad/urls.py'> (None:sad) ^sad/>], [<RegexURLResolver <module 'apps.mod_backend.urls' from '/home/rusbel/Proyectos/Django/CLIVET/apps/mod_backend/urls.py'> (None:mod_backend) ^mod_backend/>], [<RegexURLResolver <module 'apps.accounts.urls' from '/home/rusbel/Proyectos/Django/CLIVET/apps/accounts/urls.py'> (None:None) ^accounts/>], [<RegexURLResolver <module 'apps.clivet.urls' from '/home/rusbel/Proyectos/Django/CLIVET/apps/clivet/urls.py'> (None:clivet) ^clivet/>], [<RegexURLResolver <module 'django.conf.urls.i18n' from '/home/rusbel/Proyectos/myvenv/lib/python3.5/site-packages/django/conf/urls/i18n.py'> (None:None) ^i18n/>], [<RegexURLPattern None ^jsi18n/>], [<RegexURLPattern None ^media\/(?P<path>.*)$>]], 'path': 'bootstrap/images/kittens.jpg'}

During handling of the above exception, another exception occurred:

Traceback (most recent call last):
  File "/home/rusbel/Proyectos/myvenv/lib/python3.5/site-packages/django/template/base.py", line 883, in _resolve_lookup
    current = current[bit]
TypeError: 'RegexURLResolver' object is not subscriptable

During handling of the above exception, another exception occurred:

Traceback (most recent call last):
  File "/home/rusbel/Proyectos/myvenv/lib/python3.5/site-packages/django/template/base.py", line 891, in _resolve_lookup
    current = getattr(current, bit)
AttributeError: 'RegexURLResolver' object has no attribute 'name'

During handling of the above exception, another exception occurred:

Traceback (most recent call last):
  File "/home/rusbel/Proyectos/myvenv/lib/python3.5/site-packages/django/template/base.py", line 898, in _resolve_lookup
    current = current[int(bit)]
ValueError: invalid literal for int() with base 10: 'name'

During handling of the above exception, another exception occurred:

Traceback (most recent call last):
  File "/home/rusbel/Proyectos/myvenv/lib/python3.5/site-packages/django/template/base.py", line 905, in _resolve_lookup
    (bit, current))  # missing attribute
django.template.base.VariableDoesNotExist: Failed lookup for key [name] in '<RegexURLResolver <RegexURLPattern list> (admin:admin) ^admin/>'
[2016-10-05 00:01:14] DEBUG [django.template:927] Exception while resolving variable 'name' in template 'unknown'.
Traceback (most recent call last):
  File "/home/rusbel/Proyectos/myvenv/lib/python3.5/site-packages/django/core/handlers/base.py", line 134, in get_response
    resolver_match = resolver.resolve(request.path_info)
  File "/home/rusbel/Proyectos/myvenv/lib/python3.5/site-packages/django/core/urlresolvers.py", line 404, in resolve
    raise Resolver404({'tried': tried, 'path': new_path})
django.core.urlresolvers.Resolver404: {'tried': [[<RegexURLResolver <RegexURLPattern list> (admin:admin) ^admin/>], [<RegexURLResolver <module 'django.contrib.admindocs.urls' from '/home/rusbel/Proyectos/myvenv/lib/python3.5/site-packages/django/contrib/admindocs/urls.py'> (None:None) ^admin/doc/>], [<RegexURLResolver <module 'apps.home.urls' from '/home/rusbel/Proyectos/Django/CLIVET/apps/home/urls.py'> (None:home) ^home/>], [<RegexURLPattern index ^$>], [<RegexURLResolver <module 'apps.space.urls' from '/home/rusbel/Proyectos/Django/CLIVET/apps/space/urls.py'> (None:space) ^space/>], [<RegexURLResolver <module 'apps.sad.urls' from '/home/rusbel/Proyectos/Django/CLIVET/apps/sad/urls.py'> (None:sad) ^sad/>], [<RegexURLResolver <module 'apps.mod_backend.urls' from '/home/rusbel/Proyectos/Django/CLIVET/apps/mod_backend/urls.py'> (None:mod_backend) ^mod_backend/>], [<RegexURLResolver <module 'apps.accounts.urls' from '/home/rusbel/Proyectos/Django/CLIVET/apps/accounts/urls.py'> (None:None) ^accounts/>], [<RegexURLResolver <module 'apps.clivet.urls' from '/home/rusbel/Proyectos/Django/CLIVET/apps/clivet/urls.py'> (None:clivet) ^clivet/>], [<RegexURLResolver <module 'django.conf.urls.i18n' from '/home/rusbel/Proyectos/myvenv/lib/python3.5/site-packages/django/conf/urls/i18n.py'> (None:None) ^i18n/>], [<RegexURLPattern None ^jsi18n/>], [<RegexURLPattern None ^media\/(?P<path>.*)$>]], 'path': 'bootstrap/images/kittens.jpg'}

During handling of the above exception, another exception occurred:

Traceback (most recent call last):
  File "/home/rusbel/Proyectos/myvenv/lib/python3.5/site-packages/django/template/base.py", line 883, in _resolve_lookup
    current = current[bit]
TypeError: 'RegexURLResolver' object is not subscriptable

During handling of the above exception, another exception occurred:

Traceback (most recent call last):
  File "/home/rusbel/Proyectos/myvenv/lib/python3.5/site-packages/django/template/base.py", line 891, in _resolve_lookup
    current = getattr(current, bit)
AttributeError: 'RegexURLResolver' object has no attribute 'name'

During handling of the above exception, another exception occurred:

Traceback (most recent call last):
  File "/home/rusbel/Proyectos/myvenv/lib/python3.5/site-packages/django/template/base.py", line 898, in _resolve_lookup
    current = current[int(bit)]
ValueError: invalid literal for int() with base 10: 'name'

During handling of the above exception, another exception occurred:

Traceback (most recent call last):
  File "/home/rusbel/Proyectos/myvenv/lib/python3.5/site-packages/django/template/base.py", line 905, in _resolve_lookup
    (bit, current))  # missing attribute
django.template.base.VariableDoesNotExist: Failed lookup for key [name] in "<RegexURLResolver <module 'django.contrib.admindocs.urls' from '/home/rusbel/Proyectos/myvenv/lib/python3.5/site-packages/django/contrib/admindocs/urls.py'> (None:None) ^admin/doc/>"
[2016-10-05 00:01:14] DEBUG [django.template:927] Exception while resolving variable 'name' in template 'unknown'.
Traceback (most recent call last):
  File "/home/rusbel/Proyectos/myvenv/lib/python3.5/site-packages/django/core/handlers/base.py", line 134, in get_response
    resolver_match = resolver.resolve(request.path_info)
  File "/home/rusbel/Proyectos/myvenv/lib/python3.5/site-packages/django/core/urlresolvers.py", line 404, in resolve
    raise Resolver404({'tried': tried, 'path': new_path})
django.core.urlresolvers.Resolver404: {'tried': [[<RegexURLResolver <RegexURLPattern list> (admin:admin) ^admin/>], [<RegexURLResolver <module 'django.contrib.admindocs.urls' from '/home/rusbel/Proyectos/myvenv/lib/python3.5/site-packages/django/contrib/admindocs/urls.py'> (None:None) ^admin/doc/>], [<RegexURLResolver <module 'apps.home.urls' from '/home/rusbel/Proyectos/Django/CLIVET/apps/home/urls.py'> (None:home) ^home/>], [<RegexURLPattern index ^$>], [<RegexURLResolver <module 'apps.space.urls' from '/home/rusbel/Proyectos/Django/CLIVET/apps/space/urls.py'> (None:space) ^space/>], [<RegexURLResolver <module 'apps.sad.urls' from '/home/rusbel/Proyectos/Django/CLIVET/apps/sad/urls.py'> (None:sad) ^sad/>], [<RegexURLResolver <module 'apps.mod_backend.urls' from '/home/rusbel/Proyectos/Django/CLIVET/apps/mod_backend/urls.py'> (None:mod_backend) ^mod_backend/>], [<RegexURLResolver <module 'apps.accounts.urls' from '/home/rusbel/Proyectos/Django/CLIVET/apps/accounts/urls.py'> (None:None) ^accounts/>], [<RegexURLResolver <module 'apps.clivet.urls' from '/home/rusbel/Proyectos/Django/CLIVET/apps/clivet/urls.py'> (None:clivet) ^clivet/>], [<RegexURLResolver <module 'django.conf.urls.i18n' from '/home/rusbel/Proyectos/myvenv/lib/python3.5/site-packages/django/conf/urls/i18n.py'> (None:None) ^i18n/>], [<RegexURLPattern None ^jsi18n/>], [<RegexURLPattern None ^media\/(?P<path>.*)$>]], 'path': 'bootstrap/images/kittens.jpg'}

During handling of the above exception, another exception occurred:

Traceback (most recent call last):
  File "/home/rusbel/Proyectos/myvenv/lib/python3.5/site-packages/django/template/base.py", line 883, in _resolve_lookup
    current = current[bit]
TypeError: 'RegexURLResolver' object is not subscriptable

During handling of the above exception, another exception occurred:

Traceback (most recent call last):
  File "/home/rusbel/Proyectos/myvenv/lib/python3.5/site-packages/django/template/base.py", line 891, in _resolve_lookup
    current = getattr(current, bit)
AttributeError: 'RegexURLResolver' object has no attribute 'name'

During handling of the above exception, another exception occurred:

Traceback (most recent call last):
  File "/home/rusbel/Proyectos/myvenv/lib/python3.5/site-packages/django/template/base.py", line 898, in _resolve_lookup
    current = current[int(bit)]
ValueError: invalid literal for int() with base 10: 'name'

During handling of the above exception, another exception occurred:

Traceback (most recent call last):
  File "/home/rusbel/Proyectos/myvenv/lib/python3.5/site-packages/django/template/base.py", line 905, in _resolve_lookup
    (bit, current))  # missing attribute
django.template.base.VariableDoesNotExist: Failed lookup for key [name] in "<RegexURLResolver <module 'apps.home.urls' from '/home/rusbel/Proyectos/Django/CLIVET/apps/home/urls.py'> (None:home) ^home/>"
[2016-10-05 00:01:14] DEBUG [django.template:927] Exception while resolving variable 'name' in template 'unknown'.
Traceback (most recent call last):
  File "/home/rusbel/Proyectos/myvenv/lib/python3.5/site-packages/django/core/handlers/base.py", line 134, in get_response
    resolver_match = resolver.resolve(request.path_info)
  File "/home/rusbel/Proyectos/myvenv/lib/python3.5/site-packages/django/core/urlresolvers.py", line 404, in resolve
    raise Resolver404({'tried': tried, 'path': new_path})
django.core.urlresolvers.Resolver404: {'tried': [[<RegexURLResolver <RegexURLPattern list> (admin:admin) ^admin/>], [<RegexURLResolver <module 'django.contrib.admindocs.urls' from '/home/rusbel/Proyectos/myvenv/lib/python3.5/site-packages/django/contrib/admindocs/urls.py'> (None:None) ^admin/doc/>], [<RegexURLResolver <module 'apps.home.urls' from '/home/rusbel/Proyectos/Django/CLIVET/apps/home/urls.py'> (None:home) ^home/>], [<RegexURLPattern index ^$>], [<RegexURLResolver <module 'apps.space.urls' from '/home/rusbel/Proyectos/Django/CLIVET/apps/space/urls.py'> (None:space) ^space/>], [<RegexURLResolver <module 'apps.sad.urls' from '/home/rusbel/Proyectos/Django/CLIVET/apps/sad/urls.py'> (None:sad) ^sad/>], [<RegexURLResolver <module 'apps.mod_backend.urls' from '/home/rusbel/Proyectos/Django/CLIVET/apps/mod_backend/urls.py'> (None:mod_backend) ^mod_backend/>], [<RegexURLResolver <module 'apps.accounts.urls' from '/home/rusbel/Proyectos/Django/CLIVET/apps/accounts/urls.py'> (None:None) ^accounts/>], [<RegexURLResolver <module 'apps.clivet.urls' from '/home/rusbel/Proyectos/Django/CLIVET/apps/clivet/urls.py'> (None:clivet) ^clivet/>], [<RegexURLResolver <module 'django.conf.urls.i18n' from '/home/rusbel/Proyectos/myvenv/lib/python3.5/site-packages/django/conf/urls/i18n.py'> (None:None) ^i18n/>], [<RegexURLPattern None ^jsi18n/>], [<RegexURLPattern None ^media\/(?P<path>.*)$>]], 'path': 'bootstrap/images/kittens.jpg'}

During handling of the above exception, another exception occurred:

Traceback (most recent call last):
  File "/home/rusbel/Proyectos/myvenv/lib/python3.5/site-packages/django/template/base.py", line 883, in _resolve_lookup
    current = current[bit]
TypeError: 'RegexURLResolver' object is not subscriptable

During handling of the above exception, another exception occurred:

Traceback (most recent call last):
  File "/home/rusbel/Proyectos/myvenv/lib/python3.5/site-packages/django/template/base.py", line 891, in _resolve_lookup
    current = getattr(current, bit)
AttributeError: 'RegexURLResolver' object has no attribute 'name'

During handling of the above exception, another exception occurred:

Traceback (most recent call last):
  File "/home/rusbel/Proyectos/myvenv/lib/python3.5/site-packages/django/template/base.py", line 898, in _resolve_lookup
    current = current[int(bit)]
ValueError: invalid literal for int() with base 10: 'name'

During handling of the above exception, another exception occurred:

Traceback (most recent call last):
  File "/home/rusbel/Proyectos/myvenv/lib/python3.5/site-packages/django/template/base.py", line 905, in _resolve_lookup
    (bit, current))  # missing attribute
django.template.base.VariableDoesNotExist: Failed lookup for key [name] in "<RegexURLResolver <module 'apps.space.urls' from '/home/rusbel/Proyectos/Django/CLIVET/apps/space/urls.py'> (None:space) ^space/>"
[2016-10-05 00:01:14] DEBUG [django.template:927] Exception while resolving variable 'name' in template 'unknown'.
Traceback (most recent call last):
  File "/home/rusbel/Proyectos/myvenv/lib/python3.5/site-packages/django/core/handlers/base.py", line 134, in get_response
    resolver_match = resolver.resolve(request.path_info)
  File "/home/rusbel/Proyectos/myvenv/lib/python3.5/site-packages/django/core/urlresolvers.py", line 404, in resolve
    raise Resolver404({'tried': tried, 'path': new_path})
django.core.urlresolvers.Resolver404: {'tried': [[<RegexURLResolver <RegexURLPattern list> (admin:admin) ^admin/>], [<RegexURLResolver <module 'django.contrib.admindocs.urls' from '/home/rusbel/Proyectos/myvenv/lib/python3.5/site-packages/django/contrib/admindocs/urls.py'> (None:None) ^admin/doc/>], [<RegexURLResolver <module 'apps.home.urls' from '/home/rusbel/Proyectos/Django/CLIVET/apps/home/urls.py'> (None:home) ^home/>], [<RegexURLPattern index ^$>], [<RegexURLResolver <module 'apps.space.urls' from '/home/rusbel/Proyectos/Django/CLIVET/apps/space/urls.py'> (None:space) ^space/>], [<RegexURLResolver <module 'apps.sad.urls' from '/home/rusbel/Proyectos/Django/CLIVET/apps/sad/urls.py'> (None:sad) ^sad/>], [<RegexURLResolver <module 'apps.mod_backend.urls' from '/home/rusbel/Proyectos/Django/CLIVET/apps/mod_backend/urls.py'> (None:mod_backend) ^mod_backend/>], [<RegexURLResolver <module 'apps.accounts.urls' from '/home/rusbel/Proyectos/Django/CLIVET/apps/accounts/urls.py'> (None:None) ^accounts/>], [<RegexURLResolver <module 'apps.clivet.urls' from '/home/rusbel/Proyectos/Django/CLIVET/apps/clivet/urls.py'> (None:clivet) ^clivet/>], [<RegexURLResolver <module 'django.conf.urls.i18n' from '/home/rusbel/Proyectos/myvenv/lib/python3.5/site-packages/django/conf/urls/i18n.py'> (None:None) ^i18n/>], [<RegexURLPattern None ^jsi18n/>], [<RegexURLPattern None ^media\/(?P<path>.*)$>]], 'path': 'bootstrap/images/kittens.jpg'}

During handling of the above exception, another exception occurred:

Traceback (most recent call last):
  File "/home/rusbel/Proyectos/myvenv/lib/python3.5/site-packages/django/template/base.py", line 883, in _resolve_lookup
    current = current[bit]
TypeError: 'RegexURLResolver' object is not subscriptable

During handling of the above exception, another exception occurred:

Traceback (most recent call last):
  File "/home/rusbel/Proyectos/myvenv/lib/python3.5/site-packages/django/template/base.py", line 891, in _resolve_lookup
    current = getattr(current, bit)
AttributeError: 'RegexURLResolver' object has no attribute 'name'

During handling of the above exception, another exception occurred:

Traceback (most recent call last):
  File "/home/rusbel/Proyectos/myvenv/lib/python3.5/site-packages/django/template/base.py", line 898, in _resolve_lookup
    current = current[int(bit)]
ValueError: invalid literal for int() with base 10: 'name'

During handling of the above exception, another exception occurred:

Traceback (most recent call last):
  File "/home/rusbel/Proyectos/myvenv/lib/python3.5/site-packages/django/template/base.py", line 905, in _resolve_lookup
    (bit, current))  # missing attribute
django.template.base.VariableDoesNotExist: Failed lookup for key [name] in "<RegexURLResolver <module 'apps.sad.urls' from '/home/rusbel/Proyectos/Django/CLIVET/apps/sad/urls.py'> (None:sad) ^sad/>"
[2016-10-05 00:01:14] DEBUG [django.template:927] Exception while resolving variable 'name' in template 'unknown'.
Traceback (most recent call last):
  File "/home/rusbel/Proyectos/myvenv/lib/python3.5/site-packages/django/core/handlers/base.py", line 134, in get_response
    resolver_match = resolver.resolve(request.path_info)
  File "/home/rusbel/Proyectos/myvenv/lib/python3.5/site-packages/django/core/urlresolvers.py", line 404, in resolve
    raise Resolver404({'tried': tried, 'path': new_path})
django.core.urlresolvers.Resolver404: {'tried': [[<RegexURLResolver <RegexURLPattern list> (admin:admin) ^admin/>], [<RegexURLResolver <module 'django.contrib.admindocs.urls' from '/home/rusbel/Proyectos/myvenv/lib/python3.5/site-packages/django/contrib/admindocs/urls.py'> (None:None) ^admin/doc/>], [<RegexURLResolver <module 'apps.home.urls' from '/home/rusbel/Proyectos/Django/CLIVET/apps/home/urls.py'> (None:home) ^home/>], [<RegexURLPattern index ^$>], [<RegexURLResolver <module 'apps.space.urls' from '/home/rusbel/Proyectos/Django/CLIVET/apps/space/urls.py'> (None:space) ^space/>], [<RegexURLResolver <module 'apps.sad.urls' from '/home/rusbel/Proyectos/Django/CLIVET/apps/sad/urls.py'> (None:sad) ^sad/>], [<RegexURLResolver <module 'apps.mod_backend.urls' from '/home/rusbel/Proyectos/Django/CLIVET/apps/mod_backend/urls.py'> (None:mod_backend) ^mod_backend/>], [<RegexURLResolver <module 'apps.accounts.urls' from '/home/rusbel/Proyectos/Django/CLIVET/apps/accounts/urls.py'> (None:None) ^accounts/>], [<RegexURLResolver <module 'apps.clivet.urls' from '/home/rusbel/Proyectos/Django/CLIVET/apps/clivet/urls.py'> (None:clivet) ^clivet/>], [<RegexURLResolver <module 'django.conf.urls.i18n' from '/home/rusbel/Proyectos/myvenv/lib/python3.5/site-packages/django/conf/urls/i18n.py'> (None:None) ^i18n/>], [<RegexURLPattern None ^jsi18n/>], [<RegexURLPattern None ^media\/(?P<path>.*)$>]], 'path': 'bootstrap/images/kittens.jpg'}

During handling of the above exception, another exception occurred:

Traceback (most recent call last):
  File "/home/rusbel/Proyectos/myvenv/lib/python3.5/site-packages/django/template/base.py", line 883, in _resolve_lookup
    current = current[bit]
TypeError: 'RegexURLResolver' object is not subscriptable

During handling of the above exception, another exception occurred:

Traceback (most recent call last):
  File "/home/rusbel/Proyectos/myvenv/lib/python3.5/site-packages/django/template/base.py", line 891, in _resolve_lookup
    current = getattr(current, bit)
AttributeError: 'RegexURLResolver' object has no attribute 'name'

During handling of the above exception, another exception occurred:

Traceback (most recent call last):
  File "/home/rusbel/Proyectos/myvenv/lib/python3.5/site-packages/django/template/base.py", line 898, in _resolve_lookup
    current = current[int(bit)]
ValueError: invalid literal for int() with base 10: 'name'

During handling of the above exception, another exception occurred:

Traceback (most recent call last):
  File "/home/rusbel/Proyectos/myvenv/lib/python3.5/site-packages/django/template/base.py", line 905, in _resolve_lookup
    (bit, current))  # missing attribute
django.template.base.VariableDoesNotExist: Failed lookup for key [name] in "<RegexURLResolver <module 'apps.mod_backend.urls' from '/home/rusbel/Proyectos/Django/CLIVET/apps/mod_backend/urls.py'> (None:mod_backend) ^mod_backend/>"
[2016-10-05 00:01:14] DEBUG [django.template:927] Exception while resolving variable 'name' in template 'unknown'.
Traceback (most recent call last):
  File "/home/rusbel/Proyectos/myvenv/lib/python3.5/site-packages/django/core/handlers/base.py", line 134, in get_response
    resolver_match = resolver.resolve(request.path_info)
  File "/home/rusbel/Proyectos/myvenv/lib/python3.5/site-packages/django/core/urlresolvers.py", line 404, in resolve
    raise Resolver404({'tried': tried, 'path': new_path})
django.core.urlresolvers.Resolver404: {'tried': [[<RegexURLResolver <RegexURLPattern list> (admin:admin) ^admin/>], [<RegexURLResolver <module 'django.contrib.admindocs.urls' from '/home/rusbel/Proyectos/myvenv/lib/python3.5/site-packages/django/contrib/admindocs/urls.py'> (None:None) ^admin/doc/>], [<RegexURLResolver <module 'apps.home.urls' from '/home/rusbel/Proyectos/Django/CLIVET/apps/home/urls.py'> (None:home) ^home/>], [<RegexURLPattern index ^$>], [<RegexURLResolver <module 'apps.space.urls' from '/home/rusbel/Proyectos/Django/CLIVET/apps/space/urls.py'> (None:space) ^space/>], [<RegexURLResolver <module 'apps.sad.urls' from '/home/rusbel/Proyectos/Django/CLIVET/apps/sad/urls.py'> (None:sad) ^sad/>], [<RegexURLResolver <module 'apps.mod_backend.urls' from '/home/rusbel/Proyectos/Django/CLIVET/apps/mod_backend/urls.py'> (None:mod_backend) ^mod_backend/>], [<RegexURLResolver <module 'apps.accounts.urls' from '/home/rusbel/Proyectos/Django/CLIVET/apps/accounts/urls.py'> (None:None) ^accounts/>], [<RegexURLResolver <module 'apps.clivet.urls' from '/home/rusbel/Proyectos/Django/CLIVET/apps/clivet/urls.py'> (None:clivet) ^clivet/>], [<RegexURLResolver <module 'django.conf.urls.i18n' from '/home/rusbel/Proyectos/myvenv/lib/python3.5/site-packages/django/conf/urls/i18n.py'> (None:None) ^i18n/>], [<RegexURLPattern None ^jsi18n/>], [<RegexURLPattern None ^media\/(?P<path>.*)$>]], 'path': 'bootstrap/images/kittens.jpg'}

During handling of the above exception, another exception occurred:

Traceback (most recent call last):
  File "/home/rusbel/Proyectos/myvenv/lib/python3.5/site-packages/django/template/base.py", line 883, in _resolve_lookup
    current = current[bit]
TypeError: 'RegexURLResolver' object is not subscriptable

During handling of the above exception, another exception occurred:

Traceback (most recent call last):
  File "/home/rusbel/Proyectos/myvenv/lib/python3.5/site-packages/django/template/base.py", line 891, in _resolve_lookup
    current = getattr(current, bit)
AttributeError: 'RegexURLResolver' object has no attribute 'name'

During handling of the above exception, another exception occurred:

Traceback (most recent call last):
  File "/home/rusbel/Proyectos/myvenv/lib/python3.5/site-packages/django/template/base.py", line 898, in _resolve_lookup
    current = current[int(bit)]
ValueError: invalid literal for int() with base 10: 'name'

During handling of the above exception, another exception occurred:

Traceback (most recent call last):
  File "/home/rusbel/Proyectos/myvenv/lib/python3.5/site-packages/django/template/base.py", line 905, in _resolve_lookup
    (bit, current))  # missing attribute
django.template.base.VariableDoesNotExist: Failed lookup for key [name] in "<RegexURLResolver <module 'apps.accounts.urls' from '/home/rusbel/Proyectos/Django/CLIVET/apps/accounts/urls.py'> (None:None) ^accounts/>"
[2016-10-05 00:01:14] DEBUG [django.template:927] Exception while resolving variable 'name' in template 'unknown'.
Traceback (most recent call last):
  File "/home/rusbel/Proyectos/myvenv/lib/python3.5/site-packages/django/core/handlers/base.py", line 134, in get_response
    resolver_match = resolver.resolve(request.path_info)
  File "/home/rusbel/Proyectos/myvenv/lib/python3.5/site-packages/django/core/urlresolvers.py", line 404, in resolve
    raise Resolver404({'tried': tried, 'path': new_path})
django.core.urlresolvers.Resolver404: {'tried': [[<RegexURLResolver <RegexURLPattern list> (admin:admin) ^admin/>], [<RegexURLResolver <module 'django.contrib.admindocs.urls' from '/home/rusbel/Proyectos/myvenv/lib/python3.5/site-packages/django/contrib/admindocs/urls.py'> (None:None) ^admin/doc/>], [<RegexURLResolver <module 'apps.home.urls' from '/home/rusbel/Proyectos/Django/CLIVET/apps/home/urls.py'> (None:home) ^home/>], [<RegexURLPattern index ^$>], [<RegexURLResolver <module 'apps.space.urls' from '/home/rusbel/Proyectos/Django/CLIVET/apps/space/urls.py'> (None:space) ^space/>], [<RegexURLResolver <module 'apps.sad.urls' from '/home/rusbel/Proyectos/Django/CLIVET/apps/sad/urls.py'> (None:sad) ^sad/>], [<RegexURLResolver <module 'apps.mod_backend.urls' from '/home/rusbel/Proyectos/Django/CLIVET/apps/mod_backend/urls.py'> (None:mod_backend) ^mod_backend/>], [<RegexURLResolver <module 'apps.accounts.urls' from '/home/rusbel/Proyectos/Django/CLIVET/apps/accounts/urls.py'> (None:None) ^accounts/>], [<RegexURLResolver <module 'apps.clivet.urls' from '/home/rusbel/Proyectos/Django/CLIVET/apps/clivet/urls.py'> (None:clivet) ^clivet/>], [<RegexURLResolver <module 'django.conf.urls.i18n' from '/home/rusbel/Proyectos/myvenv/lib/python3.5/site-packages/django/conf/urls/i18n.py'> (None:None) ^i18n/>], [<RegexURLPattern None ^jsi18n/>], [<RegexURLPattern None ^media\/(?P<path>.*)$>]], 'path': 'bootstrap/images/kittens.jpg'}

During handling of the above exception, another exception occurred:

Traceback (most recent call last):
  File "/home/rusbel/Proyectos/myvenv/lib/python3.5/site-packages/django/template/base.py", line 883, in _resolve_lookup
    current = current[bit]
TypeError: 'RegexURLResolver' object is not subscriptable

During handling of the above exception, another exception occurred:

Traceback (most recent call last):
  File "/home/rusbel/Proyectos/myvenv/lib/python3.5/site-packages/django/template/base.py", line 891, in _resolve_lookup
    current = getattr(current, bit)
AttributeError: 'RegexURLResolver' object has no attribute 'name'

During handling of the above exception, another exception occurred:

Traceback (most recent call last):
  File "/home/rusbel/Proyectos/myvenv/lib/python3.5/site-packages/django/template/base.py", line 898, in _resolve_lookup
    current = current[int(bit)]
ValueError: invalid literal for int() with base 10: 'name'

During handling of the above exception, another exception occurred:

Traceback (most recent call last):
  File "/home/rusbel/Proyectos/myvenv/lib/python3.5/site-packages/django/template/base.py", line 905, in _resolve_lookup
    (bit, current))  # missing attribute
django.template.base.VariableDoesNotExist: Failed lookup for key [name] in "<RegexURLResolver <module 'apps.clivet.urls' from '/home/rusbel/Proyectos/Django/CLIVET/apps/clivet/urls.py'> (None:clivet) ^clivet/>"
[2016-10-05 00:01:14] DEBUG [django.template:927] Exception while resolving variable 'name' in template 'unknown'.
Traceback (most recent call last):
  File "/home/rusbel/Proyectos/myvenv/lib/python3.5/site-packages/django/core/handlers/base.py", line 134, in get_response
    resolver_match = resolver.resolve(request.path_info)
  File "/home/rusbel/Proyectos/myvenv/lib/python3.5/site-packages/django/core/urlresolvers.py", line 404, in resolve
    raise Resolver404({'tried': tried, 'path': new_path})
django.core.urlresolvers.Resolver404: {'tried': [[<RegexURLResolver <RegexURLPattern list> (admin:admin) ^admin/>], [<RegexURLResolver <module 'django.contrib.admindocs.urls' from '/home/rusbel/Proyectos/myvenv/lib/python3.5/site-packages/django/contrib/admindocs/urls.py'> (None:None) ^admin/doc/>], [<RegexURLResolver <module 'apps.home.urls' from '/home/rusbel/Proyectos/Django/CLIVET/apps/home/urls.py'> (None:home) ^home/>], [<RegexURLPattern index ^$>], [<RegexURLResolver <module 'apps.space.urls' from '/home/rusbel/Proyectos/Django/CLIVET/apps/space/urls.py'> (None:space) ^space/>], [<RegexURLResolver <module 'apps.sad.urls' from '/home/rusbel/Proyectos/Django/CLIVET/apps/sad/urls.py'> (None:sad) ^sad/>], [<RegexURLResolver <module 'apps.mod_backend.urls' from '/home/rusbel/Proyectos/Django/CLIVET/apps/mod_backend/urls.py'> (None:mod_backend) ^mod_backend/>], [<RegexURLResolver <module 'apps.accounts.urls' from '/home/rusbel/Proyectos/Django/CLIVET/apps/accounts/urls.py'> (None:None) ^accounts/>], [<RegexURLResolver <module 'apps.clivet.urls' from '/home/rusbel/Proyectos/Django/CLIVET/apps/clivet/urls.py'> (None:clivet) ^clivet/>], [<RegexURLResolver <module 'django.conf.urls.i18n' from '/home/rusbel/Proyectos/myvenv/lib/python3.5/site-packages/django/conf/urls/i18n.py'> (None:None) ^i18n/>], [<RegexURLPattern None ^jsi18n/>], [<RegexURLPattern None ^media\/(?P<path>.*)$>]], 'path': 'bootstrap/images/kittens.jpg'}

During handling of the above exception, another exception occurred:

Traceback (most recent call last):
  File "/home/rusbel/Proyectos/myvenv/lib/python3.5/site-packages/django/template/base.py", line 883, in _resolve_lookup
    current = current[bit]
TypeError: 'RegexURLResolver' object is not subscriptable

During handling of the above exception, another exception occurred:

Traceback (most recent call last):
  File "/home/rusbel/Proyectos/myvenv/lib/python3.5/site-packages/django/template/base.py", line 891, in _resolve_lookup
    current = getattr(current, bit)
AttributeError: 'RegexURLResolver' object has no attribute 'name'

During handling of the above exception, another exception occurred:

Traceback (most recent call last):
  File "/home/rusbel/Proyectos/myvenv/lib/python3.5/site-packages/django/template/base.py", line 898, in _resolve_lookup
    current = current[int(bit)]
ValueError: invalid literal for int() with base 10: 'name'

During handling of the above exception, another exception occurred:

Traceback (most recent call last):
  File "/home/rusbel/Proyectos/myvenv/lib/python3.5/site-packages/django/template/base.py", line 905, in _resolve_lookup
    (bit, current))  # missing attribute
django.template.base.VariableDoesNotExist: Failed lookup for key [name] in "<RegexURLResolver <module 'django.conf.urls.i18n' from '/home/rusbel/Proyectos/myvenv/lib/python3.5/site-packages/django/conf/urls/i18n.py'> (None:None) ^i18n/>"
[2016-10-05 00:01:39] DEBUG [django.db.backends:89] (0.001) SELECT "django_session"."session_key", "django_session"."session_data", "django_session"."expire_date" FROM "django_session" WHERE ("django_session"."session_key" = '73tz8dalqomobmynelxwtkp1yjyaxv1o' AND "django_session"."expire_date" > '2016-10-05 00:01:39.440508'); args=('73tz8dalqomobmynelxwtkp1yjyaxv1o', '2016-10-05 00:01:39.440508')
[2016-10-05 00:01:39] DEBUG [django.db.backends:89] (0.000) SELECT "auth_user"."id", "auth_user"."password", "auth_user"."last_login", "auth_user"."is_superuser", "auth_user"."username", "auth_user"."first_name", "auth_user"."last_name", "auth_user"."email", "auth_user"."is_staff", "auth_user"."is_active", "auth_user"."date_joined", "auth_user"."last_headquar_id", "auth_user"."last_module_id", "auth_user"."person_id" FROM "auth_user" WHERE "auth_user"."id" = 1; args=(1,)
[2016-10-05 00:01:39] DEBUG [django.template:927] Exception while resolving variable 'is_popup' in template 'admin/index.html'.
Traceback (most recent call last):
  File "/home/rusbel/Proyectos/myvenv/lib/python3.5/site-packages/django/template/base.py", line 883, in _resolve_lookup
    current = current[bit]
  File "/home/rusbel/Proyectos/myvenv/lib/python3.5/site-packages/django/template/context.py", line 77, in __getitem__
    raise KeyError(key)
KeyError: 'is_popup'

During handling of the above exception, another exception occurred:

Traceback (most recent call last):
  File "/home/rusbel/Proyectos/myvenv/lib/python3.5/site-packages/django/template/base.py", line 889, in _resolve_lookup
    if isinstance(current, BaseContext) and getattr(type(current), bit):
AttributeError: type object 'RequestContext' has no attribute 'is_popup'

During handling of the above exception, another exception occurred:

Traceback (most recent call last):
  File "/home/rusbel/Proyectos/myvenv/lib/python3.5/site-packages/django/template/base.py", line 898, in _resolve_lookup
    current = current[int(bit)]
ValueError: invalid literal for int() with base 10: 'is_popup'

During handling of the above exception, another exception occurred:

Traceback (most recent call last):
  File "/home/rusbel/Proyectos/myvenv/lib/python3.5/site-packages/django/template/base.py", line 905, in _resolve_lookup
    (bit, current))  # missing attribute
django.template.base.VariableDoesNotExist: Failed lookup for key [is_popup] in "[{'False': False, 'None': None, 'True': True}, {'request': <WSGIRequest: GET '/admin/'>, 'LANGUAGE_BIDI': False, 'messages': <django.contrib.messages.storage.fallback.FallbackStorage object at 0x7f6bf905b518>, 'MEDIA_URL': '/media/', 'LANGUAGES': (('ja', <django.utils.functional.lazy.<locals>.__proxy__ object at 0x7f6bfc310198>), ('zh-tw', <django.utils.functional.lazy.<locals>.__proxy__ object at 0x7f6bfc3101d0>), ('fr', <django.utils.functional.lazy.<locals>.__proxy__ object at 0x7f6bfc310208>), ('de', <django.utils.functional.lazy.<locals>.__proxy__ object at 0x7f6bfc310240>), ('en', <django.utils.functional.lazy.<locals>.__proxy__ object at 0x7f6bfc321588>), ('es', <django.utils.functional.lazy.<locals>.__proxy__ object at 0x7f6bfc321550>), ('es-ar', <django.utils.functional.lazy.<locals>.__proxy__ object at 0x7f6bfc321518>), ('es-pe', <django.utils.functional.lazy.<locals>.__proxy__ object at 0x7f6bfc3215c0>), ('pt', <django.utils.functional.lazy.<locals>.__proxy__ object at 0x7f6bfc3215f8>), ('pt-br', <django.utils.functional.lazy.<locals>.__proxy__ object at 0x7f6bfc321668>)), 'user': <SimpleLazyObject: <User: admin>>, 'perms': <django.contrib.auth.context_processors.PermWrapper object at 0x7f6be9d1df28>, 'TIME_ZONE': 'UTC', 'LANGUAGE_CODE': 'es', 'csrf_token': <SimpleLazyObject: <function csrf.<locals>._get_val at 0x7f6bf9071d08>>, 'STATIC_URL': '/static/', 'DEFAULT_MESSAGE_LEVELS': {'INFO': 20, 'DEBUG': 10, 'ERROR': 40, 'SUCCESS': 25, 'WARNING': 30}}, {}, {'has_permission': True, 'available_apps': [{'has_module_perms': True, 'name': <django.utils.functional.lazy.<locals>.__proxy__ object at 0x7f6bfaf0b3c8>, 'models': [{'name': <django.utils.functional.lazy.<locals>.__proxy__ object at 0x7f6bea7adc50>, 'add_url': '/admin/auth/group/add/', 'admin_url': '/admin/auth/group/', 'object_name': 'Group', 'perms': {'delete': True, 'change': True, 'add': True}}, {'name': <django.utils.functional.lazy.<locals>.__proxy__ object at 0x7f6bea79a9e8>, 'add_url': '/admin/auth/permission/add/', 'admin_url': '/admin/auth/permission/', 'object_name': 'Permission', 'perms': {'delete': True, 'change': True, 'add': True}}], 'app_label': 'auth', 'app_url': '/admin/auth/'}, {'has_module_perms': True, 'name': 'Params', 'models': [{'name': <django.utils.functional.lazy.<locals>.__proxy__ object at 0x7f6bea7ad470>, 'add_url': '/admin/params/person/add/', 'admin_url': '/admin/params/person/', 'object_name': 'Person', 'perms': {'delete': True, 'change': True, 'add': True}}], 'app_label': 'params', 'app_url': '/admin/params/'}, {'has_module_perms': True, 'name': <django.utils.functional.lazy.<locals>.__proxy__ object at 0x7f6bfaf15978>, 'models': [{'name': <django.utils.functional.lazy.<locals>.__proxy__ object at 0x7f6bea7ad8d0>, 'add_url': '/admin/flatpages/flatpage/add/', 'admin_url': '/admin/flatpages/flatpage/', 'object_name': 'FlatPage', 'perms': {'delete': True, 'change': True, 'add': True}}], 'app_label': 'flatpages', 'app_url': '/admin/flatpages/'}, {'has_module_perms': True, 'name': 'Sad', 'models': [{'name': <django.utils.functional.lazy.<locals>.__proxy__ object at 0x7f6bea7ad978>, 'add_url': '/admin/sad/user/add/', 'admin_url': '/admin/sad/user/', 'object_name': 'User', 'perms': {'delete': True, 'change': True, 'add': True}}], 'app_label': 'sad', 'app_url': '/admin/sad/'}, {'has_module_perms': True, 'name': <django.utils.functional.lazy.<locals>.__proxy__ object at 0x7f6bfaf15898>, 'models': [{'name': <django.utils.functional.lazy.<locals>.__proxy__ object at 0x7f6bea7add68>, 'add_url': '/admin/sites/site/add/', 'admin_url': '/admin/sites/site/', 'object_name': 'Site', 'perms': {'delete': True, 'change': True, 'add': True}}], 'app_label': 'sites', 'app_url': '/admin/sites/'}, {'has_module_perms': True, 'name': 'Space', 'models': [{'name': <django.utils.functional.lazy.<locals>.__proxy__ object at 0x7f6bea7add30>, 'add_url': '/admin/space/solution/add/', 'admin_url': '/admin/space/solution/', 'object_name': 'Solution', 'perms': {'delete': True, 'change': True, 'add': True}}], 'app_label': 'space', 'app_url': '/admin/space/'}, {'has_module_perms': True, 'name': <django.utils.functional.lazy.<locals>.__proxy__ object at 0x7f6bfaf0bb38>, 'models': [{'name': <django.utils.functional.lazy.<locals>.__proxy__ object at 0x7f6bea7adfd0>, 'add_url': '/admin/contenttypes/contenttype/add/', 'admin_url': '/admin/contenttypes/contenttype/', 'object_name': 'ContentType', 'perms': {'delete': True, 'change': True, 'add': True}}], 'app_label': 'contenttypes', 'app_url': '/admin/contenttypes/'}], 'title': <django.utils.functional.lazy.<locals>.__proxy__ object at 0x7f6bfaf04c18>, 'site_title': <django.utils.functional.lazy.<locals>.__proxy__ object at 0x7f6bfaf04710>, 'site_url': '/', 'site_header': <django.utils.functional.lazy.<locals>.__proxy__ object at 0x7f6bfaf047b8>, 'LANGUAGE_CODE': 'es', 'app_list': [{'has_module_perms': True, 'name': <django.utils.functional.lazy.<locals>.__proxy__ object at 0x7f6bfaf0b3c8>, 'models': [{'name': <django.utils.functional.lazy.<locals>.__proxy__ object at 0x7f6bea7ad898>, 'add_url': '/admin/auth/group/add/', 'admin_url': '/admin/auth/group/', 'object_name': 'Group', 'perms': {'delete': True, 'change': True, 'add': True}}, {'name': <django.utils.functional.lazy.<locals>.__proxy__ object at 0x7f6bea7ad5f8>, 'add_url': '/admin/auth/permission/add/', 'admin_url': '/admin/auth/permission/', 'object_name': 'Permission', 'perms': {'delete': True, 'change': True, 'add': True}}], 'app_label': 'auth', 'app_url': '/admin/auth/'}, {'has_module_perms': True, 'name': 'Params', 'models': [{'name': <django.utils.functional.lazy.<locals>.__proxy__ object at 0x7f6bea7ad908>, 'add_url': '/admin/params/person/add/', 'admin_url': '/admin/params/person/', 'object_name': 'Person', 'perms': {'delete': True, 'change': True, 'add': True}}], 'app_label': 'params', 'app_url': '/admin/params/'}, {'has_module_perms': True, 'name': <django.utils.functional.lazy.<locals>.__proxy__ object at 0x7f6bfaf15978>, 'models': [{'name': <django.utils.functional.lazy.<locals>.__proxy__ object at 0x7f6bea7ad160>, 'add_url': '/admin/flatpages/flatpage/add/', 'admin_url': '/admin/flatpages/flatpage/', 'object_name': 'FlatPage', 'perms': {'delete': True, 'change': True, 'add': True}}], 'app_label': 'flatpages', 'app_url': '/admin/flatpages/'}, {'has_module_perms': True, 'name': 'Sad', 'models': [{'name': <django.utils.functional.lazy.<locals>.__proxy__ object at 0x7f6bf905ba20>, 'add_url': '/admin/sad/user/add/', 'admin_url': '/admin/sad/user/', 'object_name': 'User', 'perms': {'delete': True, 'change': True, 'add': True}}], 'app_label': 'sad', 'app_url': '/admin/sad/'}, {'has_module_perms': True, 'name': <django.utils.functional.lazy.<locals>.__proxy__ object at 0x7f6bfaf15898>, 'models': [{'name': <django.utils.functional.lazy.<locals>.__proxy__ object at 0x7f6be9cfce10>, 'add_url': '/admin/sites/site/add/', 'admin_url': '/admin/sites/site/', 'object_name': 'Site', 'perms': {'delete': True, 'change': True, 'add': True}}], 'app_label': 'sites', 'app_url': '/admin/sites/'}, {'has_module_perms': True, 'name': 'Space', 'models': [{'name': <django.utils.functional.lazy.<locals>.__proxy__ object at 0x7f6bea7ad3c8>, 'add_url': '/admin/space/solution/add/', 'admin_url': '/admin/space/solution/', 'object_name': 'Solution', 'perms': {'delete': True, 'change': True, 'add': True}}], 'app_label': 'space', 'app_url': '/admin/space/'}, {'has_module_perms': True, 'name': <django.utils.functional.lazy.<locals>.__proxy__ object at 0x7f6bfaf0bb38>, 'models': [{'name': <django.utils.functional.lazy.<locals>.__proxy__ object at 0x7f6bea7adcc0>, 'add_url': '/admin/contenttypes/contenttype/add/', 'admin_url': '/admin/contenttypes/contenttype/', 'object_name': 'ContentType', 'perms': {'delete': True, 'change': True, 'add': True}}], 'app_label': 'contenttypes', 'app_url': '/admin/contenttypes/'}], 'LANGUAGE_BIDI': False}]"
[2016-10-05 00:01:39] DEBUG [django.template:927] Exception while resolving variable 'is_popup' in template 'admin/index.html'.
Traceback (most recent call last):
  File "/home/rusbel/Proyectos/myvenv/lib/python3.5/site-packages/django/template/base.py", line 883, in _resolve_lookup
    current = current[bit]
  File "/home/rusbel/Proyectos/myvenv/lib/python3.5/site-packages/django/template/context.py", line 77, in __getitem__
    raise KeyError(key)
KeyError: 'is_popup'

During handling of the above exception, another exception occurred:

Traceback (most recent call last):
  File "/home/rusbel/Proyectos/myvenv/lib/python3.5/site-packages/django/template/base.py", line 889, in _resolve_lookup
    if isinstance(current, BaseContext) and getattr(type(current), bit):
AttributeError: type object 'RequestContext' has no attribute 'is_popup'

During handling of the above exception, another exception occurred:

Traceback (most recent call last):
  File "/home/rusbel/Proyectos/myvenv/lib/python3.5/site-packages/django/template/base.py", line 898, in _resolve_lookup
    current = current[int(bit)]
ValueError: invalid literal for int() with base 10: 'is_popup'

During handling of the above exception, another exception occurred:

Traceback (most recent call last):
  File "/home/rusbel/Proyectos/myvenv/lib/python3.5/site-packages/django/template/base.py", line 905, in _resolve_lookup
    (bit, current))  # missing attribute
django.template.base.VariableDoesNotExist: Failed lookup for key [is_popup] in "[{'False': False, 'None': None, 'True': True}, {'request': <WSGIRequest: GET '/admin/'>, 'LANGUAGE_BIDI': False, 'messages': <django.contrib.messages.storage.fallback.FallbackStorage object at 0x7f6bf905b518>, 'MEDIA_URL': '/media/', 'LANGUAGES': (('ja', <django.utils.functional.lazy.<locals>.__proxy__ object at 0x7f6bfc310198>), ('zh-tw', <django.utils.functional.lazy.<locals>.__proxy__ object at 0x7f6bfc3101d0>), ('fr', <django.utils.functional.lazy.<locals>.__proxy__ object at 0x7f6bfc310208>), ('de', <django.utils.functional.lazy.<locals>.__proxy__ object at 0x7f6bfc310240>), ('en', <django.utils.functional.lazy.<locals>.__proxy__ object at 0x7f6bfc321588>), ('es', <django.utils.functional.lazy.<locals>.__proxy__ object at 0x7f6bfc321550>), ('es-ar', <django.utils.functional.lazy.<locals>.__proxy__ object at 0x7f6bfc321518>), ('es-pe', <django.utils.functional.lazy.<locals>.__proxy__ object at 0x7f6bfc3215c0>), ('pt', <django.utils.functional.lazy.<locals>.__proxy__ object at 0x7f6bfc3215f8>), ('pt-br', <django.utils.functional.lazy.<locals>.__proxy__ object at 0x7f6bfc321668>)), 'user': <SimpleLazyObject: <User: admin>>, 'perms': <django.contrib.auth.context_processors.PermWrapper object at 0x7f6be9d1df28>, 'TIME_ZONE': 'UTC', 'LANGUAGE_CODE': 'es', 'csrf_token': <SimpleLazyObject: <function csrf.<locals>._get_val at 0x7f6bf9071d08>>, 'STATIC_URL': '/static/', 'DEFAULT_MESSAGE_LEVELS': {'INFO': 20, 'DEBUG': 10, 'ERROR': 40, 'SUCCESS': 25, 'WARNING': 30}}, {}, {'has_permission': True, 'available_apps': [{'has_module_perms': True, 'name': <django.utils.functional.lazy.<locals>.__proxy__ object at 0x7f6bfaf0b3c8>, 'models': [{'name': <django.utils.functional.lazy.<locals>.__proxy__ object at 0x7f6bea7adc50>, 'add_url': '/admin/auth/group/add/', 'admin_url': '/admin/auth/group/', 'object_name': 'Group', 'perms': {'delete': True, 'change': True, 'add': True}}, {'name': <django.utils.functional.lazy.<locals>.__proxy__ object at 0x7f6bea79a9e8>, 'add_url': '/admin/auth/permission/add/', 'admin_url': '/admin/auth/permission/', 'object_name': 'Permission', 'perms': {'delete': True, 'change': True, 'add': True}}], 'app_label': 'auth', 'app_url': '/admin/auth/'}, {'has_module_perms': True, 'name': 'Params', 'models': [{'name': <django.utils.functional.lazy.<locals>.__proxy__ object at 0x7f6bea7ad470>, 'add_url': '/admin/params/person/add/', 'admin_url': '/admin/params/person/', 'object_name': 'Person', 'perms': {'delete': True, 'change': True, 'add': True}}], 'app_label': 'params', 'app_url': '/admin/params/'}, {'has_module_perms': True, 'name': <django.utils.functional.lazy.<locals>.__proxy__ object at 0x7f6bfaf15978>, 'models': [{'name': <django.utils.functional.lazy.<locals>.__proxy__ object at 0x7f6bea7ad8d0>, 'add_url': '/admin/flatpages/flatpage/add/', 'admin_url': '/admin/flatpages/flatpage/', 'object_name': 'FlatPage', 'perms': {'delete': True, 'change': True, 'add': True}}], 'app_label': 'flatpages', 'app_url': '/admin/flatpages/'}, {'has_module_perms': True, 'name': 'Sad', 'models': [{'name': <django.utils.functional.lazy.<locals>.__proxy__ object at 0x7f6bea7ad978>, 'add_url': '/admin/sad/user/add/', 'admin_url': '/admin/sad/user/', 'object_name': 'User', 'perms': {'delete': True, 'change': True, 'add': True}}], 'app_label': 'sad', 'app_url': '/admin/sad/'}, {'has_module_perms': True, 'name': <django.utils.functional.lazy.<locals>.__proxy__ object at 0x7f6bfaf15898>, 'models': [{'name': <django.utils.functional.lazy.<locals>.__proxy__ object at 0x7f6bea7add68>, 'add_url': '/admin/sites/site/add/', 'admin_url': '/admin/sites/site/', 'object_name': 'Site', 'perms': {'delete': True, 'change': True, 'add': True}}], 'app_label': 'sites', 'app_url': '/admin/sites/'}, {'has_module_perms': True, 'name': 'Space', 'models': [{'name': <django.utils.functional.lazy.<locals>.__proxy__ object at 0x7f6bea7add30>, 'add_url': '/admin/space/solution/add/', 'admin_url': '/admin/space/solution/', 'object_name': 'Solution', 'perms': {'delete': True, 'change': True, 'add': True}}], 'app_label': 'space', 'app_url': '/admin/space/'}, {'has_module_perms': True, 'name': <django.utils.functional.lazy.<locals>.__proxy__ object at 0x7f6bfaf0bb38>, 'models': [{'name': <django.utils.functional.lazy.<locals>.__proxy__ object at 0x7f6bea7adfd0>, 'add_url': '/admin/contenttypes/contenttype/add/', 'admin_url': '/admin/contenttypes/contenttype/', 'object_name': 'ContentType', 'perms': {'delete': True, 'change': True, 'add': True}}], 'app_label': 'contenttypes', 'app_url': '/admin/contenttypes/'}], 'title': <django.utils.functional.lazy.<locals>.__proxy__ object at 0x7f6bfaf04c18>, 'site_title': <django.utils.functional.lazy.<locals>.__proxy__ object at 0x7f6bfaf04710>, 'site_url': '/', 'site_header': <django.utils.functional.lazy.<locals>.__proxy__ object at 0x7f6bfaf047b8>, 'LANGUAGE_CODE': 'es', 'app_list': [{'has_module_perms': True, 'name': <django.utils.functional.lazy.<locals>.__proxy__ object at 0x7f6bfaf0b3c8>, 'models': [{'name': <django.utils.functional.lazy.<locals>.__proxy__ object at 0x7f6bea7ad898>, 'add_url': '/admin/auth/group/add/', 'admin_url': '/admin/auth/group/', 'object_name': 'Group', 'perms': {'delete': True, 'change': True, 'add': True}}, {'name': <django.utils.functional.lazy.<locals>.__proxy__ object at 0x7f6bea7ad5f8>, 'add_url': '/admin/auth/permission/add/', 'admin_url': '/admin/auth/permission/', 'object_name': 'Permission', 'perms': {'delete': True, 'change': True, 'add': True}}], 'app_label': 'auth', 'app_url': '/admin/auth/'}, {'has_module_perms': True, 'name': 'Params', 'models': [{'name': <django.utils.functional.lazy.<locals>.__proxy__ object at 0x7f6bea7ad908>, 'add_url': '/admin/params/person/add/', 'admin_url': '/admin/params/person/', 'object_name': 'Person', 'perms': {'delete': True, 'change': True, 'add': True}}], 'app_label': 'params', 'app_url': '/admin/params/'}, {'has_module_perms': True, 'name': <django.utils.functional.lazy.<locals>.__proxy__ object at 0x7f6bfaf15978>, 'models': [{'name': <django.utils.functional.lazy.<locals>.__proxy__ object at 0x7f6bea7ad160>, 'add_url': '/admin/flatpages/flatpage/add/', 'admin_url': '/admin/flatpages/flatpage/', 'object_name': 'FlatPage', 'perms': {'delete': True, 'change': True, 'add': True}}], 'app_label': 'flatpages', 'app_url': '/admin/flatpages/'}, {'has_module_perms': True, 'name': 'Sad', 'models': [{'name': <django.utils.functional.lazy.<locals>.__proxy__ object at 0x7f6bf905ba20>, 'add_url': '/admin/sad/user/add/', 'admin_url': '/admin/sad/user/', 'object_name': 'User', 'perms': {'delete': True, 'change': True, 'add': True}}], 'app_label': 'sad', 'app_url': '/admin/sad/'}, {'has_module_perms': True, 'name': <django.utils.functional.lazy.<locals>.__proxy__ object at 0x7f6bfaf15898>, 'models': [{'name': <django.utils.functional.lazy.<locals>.__proxy__ object at 0x7f6be9cfce10>, 'add_url': '/admin/sites/site/add/', 'admin_url': '/admin/sites/site/', 'object_name': 'Site', 'perms': {'delete': True, 'change': True, 'add': True}}], 'app_label': 'sites', 'app_url': '/admin/sites/'}, {'has_module_perms': True, 'name': 'Space', 'models': [{'name': <django.utils.functional.lazy.<locals>.__proxy__ object at 0x7f6bea7ad3c8>, 'add_url': '/admin/space/solution/add/', 'admin_url': '/admin/space/solution/', 'object_name': 'Solution', 'perms': {'delete': True, 'change': True, 'add': True}}], 'app_label': 'space', 'app_url': '/admin/space/'}, {'has_module_perms': True, 'name': <django.utils.functional.lazy.<locals>.__proxy__ object at 0x7f6bfaf0bb38>, 'models': [{'name': <django.utils.functional.lazy.<locals>.__proxy__ object at 0x7f6bea7adcc0>, 'add_url': '/admin/contenttypes/contenttype/add/', 'admin_url': '/admin/contenttypes/contenttype/', 'object_name': 'ContentType', 'perms': {'delete': True, 'change': True, 'add': True}}], 'app_label': 'contenttypes', 'app_url': '/admin/contenttypes/'}], 'LANGUAGE_BIDI': False}]"
[2016-10-05 00:01:39] DEBUG [django.db.backends:89] (0.000) SELECT "django_admin_log"."id", "django_admin_log"."action_time", "django_admin_log"."user_id", "django_admin_log"."content_type_id", "django_admin_log"."object_id", "django_admin_log"."object_repr", "django_admin_log"."action_flag", "django_admin_log"."change_message", "auth_user"."id", "auth_user"."password", "auth_user"."last_login", "auth_user"."is_superuser", "auth_user"."username", "auth_user"."first_name", "auth_user"."last_name", "auth_user"."email", "auth_user"."is_staff", "auth_user"."is_active", "auth_user"."date_joined", "auth_user"."last_headquar_id", "auth_user"."last_module_id", "auth_user"."person_id", "django_content_type"."id", "django_content_type"."app_label", "django_content_type"."model" FROM "django_admin_log" INNER JOIN "auth_user" ON ("django_admin_log"."user_id" = "auth_user"."id") LEFT OUTER JOIN "django_content_type" ON ("django_admin_log"."content_type_id" = "django_content_type"."id") WHERE "django_admin_log"."user_id" = 1 ORDER BY "django_admin_log"."action_time" DESC LIMIT 10; args=(1,)
[2016-10-05 00:02:07] DEBUG [django.db.backends:89] (0.001) SELECT "django_session"."session_key", "django_session"."session_data", "django_session"."expire_date" FROM "django_session" WHERE ("django_session"."session_key" = '73tz8dalqomobmynelxwtkp1yjyaxv1o' AND "django_session"."expire_date" > '2016-10-05 00:02:07.526372'); args=('73tz8dalqomobmynelxwtkp1yjyaxv1o', '2016-10-05 00:02:07.526372')
[2016-10-05 00:02:07] DEBUG [django.db.backends:89] (0.001) SELECT "django_session"."session_key", "django_session"."session_data", "django_session"."expire_date" FROM "django_session" WHERE ("django_session"."session_key" = '73tz8dalqomobmynelxwtkp1yjyaxv1o' AND "django_session"."expire_date" > '2016-10-05 00:02:07.599901'); args=('73tz8dalqomobmynelxwtkp1yjyaxv1o', '2016-10-05 00:02:07.599901')
[2016-10-05 00:02:07] WARNING [django.request:182] Not Found: /bootstrap/images/kittens.jpg
[2016-10-05 00:02:07] DEBUG [django.template:927] Exception while resolving variable 'name' in template 'unknown'.
Traceback (most recent call last):
  File "/home/rusbel/Proyectos/myvenv/lib/python3.5/site-packages/django/core/handlers/base.py", line 134, in get_response
    resolver_match = resolver.resolve(request.path_info)
  File "/home/rusbel/Proyectos/myvenv/lib/python3.5/site-packages/django/core/urlresolvers.py", line 404, in resolve
    raise Resolver404({'tried': tried, 'path': new_path})
django.core.urlresolvers.Resolver404: {'tried': [[<RegexURLResolver <RegexURLPattern list> (admin:admin) ^admin/>], [<RegexURLResolver <module 'django.contrib.admindocs.urls' from '/home/rusbel/Proyectos/myvenv/lib/python3.5/site-packages/django/contrib/admindocs/urls.py'> (None:None) ^admin/doc/>], [<RegexURLResolver <module 'apps.home.urls' from '/home/rusbel/Proyectos/Django/CLIVET/apps/home/urls.py'> (None:home) ^home/>], [<RegexURLPattern index ^$>], [<RegexURLResolver <module 'apps.space.urls' from '/home/rusbel/Proyectos/Django/CLIVET/apps/space/urls.py'> (None:space) ^space/>], [<RegexURLResolver <module 'apps.sad.urls' from '/home/rusbel/Proyectos/Django/CLIVET/apps/sad/urls.py'> (None:sad) ^sad/>], [<RegexURLResolver <module 'apps.mod_backend.urls' from '/home/rusbel/Proyectos/Django/CLIVET/apps/mod_backend/urls.py'> (None:mod_backend) ^mod_backend/>], [<RegexURLResolver <module 'apps.accounts.urls' from '/home/rusbel/Proyectos/Django/CLIVET/apps/accounts/urls.py'> (None:None) ^accounts/>], [<RegexURLResolver <module 'apps.clivet.urls' from '/home/rusbel/Proyectos/Django/CLIVET/apps/clivet/urls.py'> (None:clivet) ^clivet/>], [<RegexURLResolver <module 'django.conf.urls.i18n' from '/home/rusbel/Proyectos/myvenv/lib/python3.5/site-packages/django/conf/urls/i18n.py'> (None:None) ^i18n/>], [<RegexURLPattern None ^jsi18n/>], [<RegexURLPattern None ^media\/(?P<path>.*)$>]], 'path': 'bootstrap/images/kittens.jpg'}

During handling of the above exception, another exception occurred:

Traceback (most recent call last):
  File "/home/rusbel/Proyectos/myvenv/lib/python3.5/site-packages/django/template/base.py", line 883, in _resolve_lookup
    current = current[bit]
TypeError: 'RegexURLResolver' object is not subscriptable

During handling of the above exception, another exception occurred:

Traceback (most recent call last):
  File "/home/rusbel/Proyectos/myvenv/lib/python3.5/site-packages/django/template/base.py", line 891, in _resolve_lookup
    current = getattr(current, bit)
AttributeError: 'RegexURLResolver' object has no attribute 'name'

During handling of the above exception, another exception occurred:

Traceback (most recent call last):
  File "/home/rusbel/Proyectos/myvenv/lib/python3.5/site-packages/django/template/base.py", line 898, in _resolve_lookup
    current = current[int(bit)]
ValueError: invalid literal for int() with base 10: 'name'

During handling of the above exception, another exception occurred:

Traceback (most recent call last):
  File "/home/rusbel/Proyectos/myvenv/lib/python3.5/site-packages/django/template/base.py", line 905, in _resolve_lookup
    (bit, current))  # missing attribute
django.template.base.VariableDoesNotExist: Failed lookup for key [name] in '<RegexURLResolver <RegexURLPattern list> (admin:admin) ^admin/>'
[2016-10-05 00:02:07] DEBUG [django.template:927] Exception while resolving variable 'name' in template 'unknown'.
Traceback (most recent call last):
  File "/home/rusbel/Proyectos/myvenv/lib/python3.5/site-packages/django/core/handlers/base.py", line 134, in get_response
    resolver_match = resolver.resolve(request.path_info)
  File "/home/rusbel/Proyectos/myvenv/lib/python3.5/site-packages/django/core/urlresolvers.py", line 404, in resolve
    raise Resolver404({'tried': tried, 'path': new_path})
django.core.urlresolvers.Resolver404: {'tried': [[<RegexURLResolver <RegexURLPattern list> (admin:admin) ^admin/>], [<RegexURLResolver <module 'django.contrib.admindocs.urls' from '/home/rusbel/Proyectos/myvenv/lib/python3.5/site-packages/django/contrib/admindocs/urls.py'> (None:None) ^admin/doc/>], [<RegexURLResolver <module 'apps.home.urls' from '/home/rusbel/Proyectos/Django/CLIVET/apps/home/urls.py'> (None:home) ^home/>], [<RegexURLPattern index ^$>], [<RegexURLResolver <module 'apps.space.urls' from '/home/rusbel/Proyectos/Django/CLIVET/apps/space/urls.py'> (None:space) ^space/>], [<RegexURLResolver <module 'apps.sad.urls' from '/home/rusbel/Proyectos/Django/CLIVET/apps/sad/urls.py'> (None:sad) ^sad/>], [<RegexURLResolver <module 'apps.mod_backend.urls' from '/home/rusbel/Proyectos/Django/CLIVET/apps/mod_backend/urls.py'> (None:mod_backend) ^mod_backend/>], [<RegexURLResolver <module 'apps.accounts.urls' from '/home/rusbel/Proyectos/Django/CLIVET/apps/accounts/urls.py'> (None:None) ^accounts/>], [<RegexURLResolver <module 'apps.clivet.urls' from '/home/rusbel/Proyectos/Django/CLIVET/apps/clivet/urls.py'> (None:clivet) ^clivet/>], [<RegexURLResolver <module 'django.conf.urls.i18n' from '/home/rusbel/Proyectos/myvenv/lib/python3.5/site-packages/django/conf/urls/i18n.py'> (None:None) ^i18n/>], [<RegexURLPattern None ^jsi18n/>], [<RegexURLPattern None ^media\/(?P<path>.*)$>]], 'path': 'bootstrap/images/kittens.jpg'}

During handling of the above exception, another exception occurred:

Traceback (most recent call last):
  File "/home/rusbel/Proyectos/myvenv/lib/python3.5/site-packages/django/template/base.py", line 883, in _resolve_lookup
    current = current[bit]
TypeError: 'RegexURLResolver' object is not subscriptable

During handling of the above exception, another exception occurred:

Traceback (most recent call last):
  File "/home/rusbel/Proyectos/myvenv/lib/python3.5/site-packages/django/template/base.py", line 891, in _resolve_lookup
    current = getattr(current, bit)
AttributeError: 'RegexURLResolver' object has no attribute 'name'

During handling of the above exception, another exception occurred:

Traceback (most recent call last):
  File "/home/rusbel/Proyectos/myvenv/lib/python3.5/site-packages/django/template/base.py", line 898, in _resolve_lookup
    current = current[int(bit)]
ValueError: invalid literal for int() with base 10: 'name'

During handling of the above exception, another exception occurred:

Traceback (most recent call last):
  File "/home/rusbel/Proyectos/myvenv/lib/python3.5/site-packages/django/template/base.py", line 905, in _resolve_lookup
    (bit, current))  # missing attribute
django.template.base.VariableDoesNotExist: Failed lookup for key [name] in "<RegexURLResolver <module 'django.contrib.admindocs.urls' from '/home/rusbel/Proyectos/myvenv/lib/python3.5/site-packages/django/contrib/admindocs/urls.py'> (None:None) ^admin/doc/>"
[2016-10-05 00:02:07] DEBUG [django.template:927] Exception while resolving variable 'name' in template 'unknown'.
Traceback (most recent call last):
  File "/home/rusbel/Proyectos/myvenv/lib/python3.5/site-packages/django/core/handlers/base.py", line 134, in get_response
    resolver_match = resolver.resolve(request.path_info)
  File "/home/rusbel/Proyectos/myvenv/lib/python3.5/site-packages/django/core/urlresolvers.py", line 404, in resolve
    raise Resolver404({'tried': tried, 'path': new_path})
django.core.urlresolvers.Resolver404: {'tried': [[<RegexURLResolver <RegexURLPattern list> (admin:admin) ^admin/>], [<RegexURLResolver <module 'django.contrib.admindocs.urls' from '/home/rusbel/Proyectos/myvenv/lib/python3.5/site-packages/django/contrib/admindocs/urls.py'> (None:None) ^admin/doc/>], [<RegexURLResolver <module 'apps.home.urls' from '/home/rusbel/Proyectos/Django/CLIVET/apps/home/urls.py'> (None:home) ^home/>], [<RegexURLPattern index ^$>], [<RegexURLResolver <module 'apps.space.urls' from '/home/rusbel/Proyectos/Django/CLIVET/apps/space/urls.py'> (None:space) ^space/>], [<RegexURLResolver <module 'apps.sad.urls' from '/home/rusbel/Proyectos/Django/CLIVET/apps/sad/urls.py'> (None:sad) ^sad/>], [<RegexURLResolver <module 'apps.mod_backend.urls' from '/home/rusbel/Proyectos/Django/CLIVET/apps/mod_backend/urls.py'> (None:mod_backend) ^mod_backend/>], [<RegexURLResolver <module 'apps.accounts.urls' from '/home/rusbel/Proyectos/Django/CLIVET/apps/accounts/urls.py'> (None:None) ^accounts/>], [<RegexURLResolver <module 'apps.clivet.urls' from '/home/rusbel/Proyectos/Django/CLIVET/apps/clivet/urls.py'> (None:clivet) ^clivet/>], [<RegexURLResolver <module 'django.conf.urls.i18n' from '/home/rusbel/Proyectos/myvenv/lib/python3.5/site-packages/django/conf/urls/i18n.py'> (None:None) ^i18n/>], [<RegexURLPattern None ^jsi18n/>], [<RegexURLPattern None ^media\/(?P<path>.*)$>]], 'path': 'bootstrap/images/kittens.jpg'}

During handling of the above exception, another exception occurred:

Traceback (most recent call last):
  File "/home/rusbel/Proyectos/myvenv/lib/python3.5/site-packages/django/template/base.py", line 883, in _resolve_lookup
    current = current[bit]
TypeError: 'RegexURLResolver' object is not subscriptable

During handling of the above exception, another exception occurred:

Traceback (most recent call last):
  File "/home/rusbel/Proyectos/myvenv/lib/python3.5/site-packages/django/template/base.py", line 891, in _resolve_lookup
    current = getattr(current, bit)
AttributeError: 'RegexURLResolver' object has no attribute 'name'

During handling of the above exception, another exception occurred:

Traceback (most recent call last):
  File "/home/rusbel/Proyectos/myvenv/lib/python3.5/site-packages/django/template/base.py", line 898, in _resolve_lookup
    current = current[int(bit)]
ValueError: invalid literal for int() with base 10: 'name'

During handling of the above exception, another exception occurred:

Traceback (most recent call last):
  File "/home/rusbel/Proyectos/myvenv/lib/python3.5/site-packages/django/template/base.py", line 905, in _resolve_lookup
    (bit, current))  # missing attribute
django.template.base.VariableDoesNotExist: Failed lookup for key [name] in "<RegexURLResolver <module 'apps.home.urls' from '/home/rusbel/Proyectos/Django/CLIVET/apps/home/urls.py'> (None:home) ^home/>"
[2016-10-05 00:02:07] DEBUG [django.template:927] Exception while resolving variable 'name' in template 'unknown'.
Traceback (most recent call last):
  File "/home/rusbel/Proyectos/myvenv/lib/python3.5/site-packages/django/core/handlers/base.py", line 134, in get_response
    resolver_match = resolver.resolve(request.path_info)
  File "/home/rusbel/Proyectos/myvenv/lib/python3.5/site-packages/django/core/urlresolvers.py", line 404, in resolve
    raise Resolver404({'tried': tried, 'path': new_path})
django.core.urlresolvers.Resolver404: {'tried': [[<RegexURLResolver <RegexURLPattern list> (admin:admin) ^admin/>], [<RegexURLResolver <module 'django.contrib.admindocs.urls' from '/home/rusbel/Proyectos/myvenv/lib/python3.5/site-packages/django/contrib/admindocs/urls.py'> (None:None) ^admin/doc/>], [<RegexURLResolver <module 'apps.home.urls' from '/home/rusbel/Proyectos/Django/CLIVET/apps/home/urls.py'> (None:home) ^home/>], [<RegexURLPattern index ^$>], [<RegexURLResolver <module 'apps.space.urls' from '/home/rusbel/Proyectos/Django/CLIVET/apps/space/urls.py'> (None:space) ^space/>], [<RegexURLResolver <module 'apps.sad.urls' from '/home/rusbel/Proyectos/Django/CLIVET/apps/sad/urls.py'> (None:sad) ^sad/>], [<RegexURLResolver <module 'apps.mod_backend.urls' from '/home/rusbel/Proyectos/Django/CLIVET/apps/mod_backend/urls.py'> (None:mod_backend) ^mod_backend/>], [<RegexURLResolver <module 'apps.accounts.urls' from '/home/rusbel/Proyectos/Django/CLIVET/apps/accounts/urls.py'> (None:None) ^accounts/>], [<RegexURLResolver <module 'apps.clivet.urls' from '/home/rusbel/Proyectos/Django/CLIVET/apps/clivet/urls.py'> (None:clivet) ^clivet/>], [<RegexURLResolver <module 'django.conf.urls.i18n' from '/home/rusbel/Proyectos/myvenv/lib/python3.5/site-packages/django/conf/urls/i18n.py'> (None:None) ^i18n/>], [<RegexURLPattern None ^jsi18n/>], [<RegexURLPattern None ^media\/(?P<path>.*)$>]], 'path': 'bootstrap/images/kittens.jpg'}

During handling of the above exception, another exception occurred:

Traceback (most recent call last):
  File "/home/rusbel/Proyectos/myvenv/lib/python3.5/site-packages/django/template/base.py", line 883, in _resolve_lookup
    current = current[bit]
TypeError: 'RegexURLResolver' object is not subscriptable

During handling of the above exception, another exception occurred:

Traceback (most recent call last):
  File "/home/rusbel/Proyectos/myvenv/lib/python3.5/site-packages/django/template/base.py", line 891, in _resolve_lookup
    current = getattr(current, bit)
AttributeError: 'RegexURLResolver' object has no attribute 'name'

During handling of the above exception, another exception occurred:

Traceback (most recent call last):
  File "/home/rusbel/Proyectos/myvenv/lib/python3.5/site-packages/django/template/base.py", line 898, in _resolve_lookup
    current = current[int(bit)]
ValueError: invalid literal for int() with base 10: 'name'

During handling of the above exception, another exception occurred:

Traceback (most recent call last):
  File "/home/rusbel/Proyectos/myvenv/lib/python3.5/site-packages/django/template/base.py", line 905, in _resolve_lookup
    (bit, current))  # missing attribute
django.template.base.VariableDoesNotExist: Failed lookup for key [name] in "<RegexURLResolver <module 'apps.space.urls' from '/home/rusbel/Proyectos/Django/CLIVET/apps/space/urls.py'> (None:space) ^space/>"
[2016-10-05 00:02:07] DEBUG [django.template:927] Exception while resolving variable 'name' in template 'unknown'.
Traceback (most recent call last):
  File "/home/rusbel/Proyectos/myvenv/lib/python3.5/site-packages/django/core/handlers/base.py", line 134, in get_response
    resolver_match = resolver.resolve(request.path_info)
  File "/home/rusbel/Proyectos/myvenv/lib/python3.5/site-packages/django/core/urlresolvers.py", line 404, in resolve
    raise Resolver404({'tried': tried, 'path': new_path})
django.core.urlresolvers.Resolver404: {'tried': [[<RegexURLResolver <RegexURLPattern list> (admin:admin) ^admin/>], [<RegexURLResolver <module 'django.contrib.admindocs.urls' from '/home/rusbel/Proyectos/myvenv/lib/python3.5/site-packages/django/contrib/admindocs/urls.py'> (None:None) ^admin/doc/>], [<RegexURLResolver <module 'apps.home.urls' from '/home/rusbel/Proyectos/Django/CLIVET/apps/home/urls.py'> (None:home) ^home/>], [<RegexURLPattern index ^$>], [<RegexURLResolver <module 'apps.space.urls' from '/home/rusbel/Proyectos/Django/CLIVET/apps/space/urls.py'> (None:space) ^space/>], [<RegexURLResolver <module 'apps.sad.urls' from '/home/rusbel/Proyectos/Django/CLIVET/apps/sad/urls.py'> (None:sad) ^sad/>], [<RegexURLResolver <module 'apps.mod_backend.urls' from '/home/rusbel/Proyectos/Django/CLIVET/apps/mod_backend/urls.py'> (None:mod_backend) ^mod_backend/>], [<RegexURLResolver <module 'apps.accounts.urls' from '/home/rusbel/Proyectos/Django/CLIVET/apps/accounts/urls.py'> (None:None) ^accounts/>], [<RegexURLResolver <module 'apps.clivet.urls' from '/home/rusbel/Proyectos/Django/CLIVET/apps/clivet/urls.py'> (None:clivet) ^clivet/>], [<RegexURLResolver <module 'django.conf.urls.i18n' from '/home/rusbel/Proyectos/myvenv/lib/python3.5/site-packages/django/conf/urls/i18n.py'> (None:None) ^i18n/>], [<RegexURLPattern None ^jsi18n/>], [<RegexURLPattern None ^media\/(?P<path>.*)$>]], 'path': 'bootstrap/images/kittens.jpg'}

During handling of the above exception, another exception occurred:

Traceback (most recent call last):
  File "/home/rusbel/Proyectos/myvenv/lib/python3.5/site-packages/django/template/base.py", line 883, in _resolve_lookup
    current = current[bit]
TypeError: 'RegexURLResolver' object is not subscriptable

During handling of the above exception, another exception occurred:

Traceback (most recent call last):
  File "/home/rusbel/Proyectos/myvenv/lib/python3.5/site-packages/django/template/base.py", line 891, in _resolve_lookup
    current = getattr(current, bit)
AttributeError: 'RegexURLResolver' object has no attribute 'name'

During handling of the above exception, another exception occurred:

Traceback (most recent call last):
  File "/home/rusbel/Proyectos/myvenv/lib/python3.5/site-packages/django/template/base.py", line 898, in _resolve_lookup
    current = current[int(bit)]
ValueError: invalid literal for int() with base 10: 'name'

During handling of the above exception, another exception occurred:

Traceback (most recent call last):
  File "/home/rusbel/Proyectos/myvenv/lib/python3.5/site-packages/django/template/base.py", line 905, in _resolve_lookup
    (bit, current))  # missing attribute
django.template.base.VariableDoesNotExist: Failed lookup for key [name] in "<RegexURLResolver <module 'apps.sad.urls' from '/home/rusbel/Proyectos/Django/CLIVET/apps/sad/urls.py'> (None:sad) ^sad/>"
[2016-10-05 00:02:07] DEBUG [django.template:927] Exception while resolving variable 'name' in template 'unknown'.
Traceback (most recent call last):
  File "/home/rusbel/Proyectos/myvenv/lib/python3.5/site-packages/django/core/handlers/base.py", line 134, in get_response
    resolver_match = resolver.resolve(request.path_info)
  File "/home/rusbel/Proyectos/myvenv/lib/python3.5/site-packages/django/core/urlresolvers.py", line 404, in resolve
    raise Resolver404({'tried': tried, 'path': new_path})
django.core.urlresolvers.Resolver404: {'tried': [[<RegexURLResolver <RegexURLPattern list> (admin:admin) ^admin/>], [<RegexURLResolver <module 'django.contrib.admindocs.urls' from '/home/rusbel/Proyectos/myvenv/lib/python3.5/site-packages/django/contrib/admindocs/urls.py'> (None:None) ^admin/doc/>], [<RegexURLResolver <module 'apps.home.urls' from '/home/rusbel/Proyectos/Django/CLIVET/apps/home/urls.py'> (None:home) ^home/>], [<RegexURLPattern index ^$>], [<RegexURLResolver <module 'apps.space.urls' from '/home/rusbel/Proyectos/Django/CLIVET/apps/space/urls.py'> (None:space) ^space/>], [<RegexURLResolver <module 'apps.sad.urls' from '/home/rusbel/Proyectos/Django/CLIVET/apps/sad/urls.py'> (None:sad) ^sad/>], [<RegexURLResolver <module 'apps.mod_backend.urls' from '/home/rusbel/Proyectos/Django/CLIVET/apps/mod_backend/urls.py'> (None:mod_backend) ^mod_backend/>], [<RegexURLResolver <module 'apps.accounts.urls' from '/home/rusbel/Proyectos/Django/CLIVET/apps/accounts/urls.py'> (None:None) ^accounts/>], [<RegexURLResolver <module 'apps.clivet.urls' from '/home/rusbel/Proyectos/Django/CLIVET/apps/clivet/urls.py'> (None:clivet) ^clivet/>], [<RegexURLResolver <module 'django.conf.urls.i18n' from '/home/rusbel/Proyectos/myvenv/lib/python3.5/site-packages/django/conf/urls/i18n.py'> (None:None) ^i18n/>], [<RegexURLPattern None ^jsi18n/>], [<RegexURLPattern None ^media\/(?P<path>.*)$>]], 'path': 'bootstrap/images/kittens.jpg'}

During handling of the above exception, another exception occurred:

Traceback (most recent call last):
  File "/home/rusbel/Proyectos/myvenv/lib/python3.5/site-packages/django/template/base.py", line 883, in _resolve_lookup
    current = current[bit]
TypeError: 'RegexURLResolver' object is not subscriptable

During handling of the above exception, another exception occurred:

Traceback (most recent call last):
  File "/home/rusbel/Proyectos/myvenv/lib/python3.5/site-packages/django/template/base.py", line 891, in _resolve_lookup
    current = getattr(current, bit)
AttributeError: 'RegexURLResolver' object has no attribute 'name'

During handling of the above exception, another exception occurred:

Traceback (most recent call last):
  File "/home/rusbel/Proyectos/myvenv/lib/python3.5/site-packages/django/template/base.py", line 898, in _resolve_lookup
    current = current[int(bit)]
ValueError: invalid literal for int() with base 10: 'name'

During handling of the above exception, another exception occurred:

Traceback (most recent call last):
  File "/home/rusbel/Proyectos/myvenv/lib/python3.5/site-packages/django/template/base.py", line 905, in _resolve_lookup
    (bit, current))  # missing attribute
django.template.base.VariableDoesNotExist: Failed lookup for key [name] in "<RegexURLResolver <module 'apps.mod_backend.urls' from '/home/rusbel/Proyectos/Django/CLIVET/apps/mod_backend/urls.py'> (None:mod_backend) ^mod_backend/>"
[2016-10-05 00:02:07] DEBUG [django.template:927] Exception while resolving variable 'name' in template 'unknown'.
Traceback (most recent call last):
  File "/home/rusbel/Proyectos/myvenv/lib/python3.5/site-packages/django/core/handlers/base.py", line 134, in get_response
    resolver_match = resolver.resolve(request.path_info)
  File "/home/rusbel/Proyectos/myvenv/lib/python3.5/site-packages/django/core/urlresolvers.py", line 404, in resolve
    raise Resolver404({'tried': tried, 'path': new_path})
django.core.urlresolvers.Resolver404: {'tried': [[<RegexURLResolver <RegexURLPattern list> (admin:admin) ^admin/>], [<RegexURLResolver <module 'django.contrib.admindocs.urls' from '/home/rusbel/Proyectos/myvenv/lib/python3.5/site-packages/django/contrib/admindocs/urls.py'> (None:None) ^admin/doc/>], [<RegexURLResolver <module 'apps.home.urls' from '/home/rusbel/Proyectos/Django/CLIVET/apps/home/urls.py'> (None:home) ^home/>], [<RegexURLPattern index ^$>], [<RegexURLResolver <module 'apps.space.urls' from '/home/rusbel/Proyectos/Django/CLIVET/apps/space/urls.py'> (None:space) ^space/>], [<RegexURLResolver <module 'apps.sad.urls' from '/home/rusbel/Proyectos/Django/CLIVET/apps/sad/urls.py'> (None:sad) ^sad/>], [<RegexURLResolver <module 'apps.mod_backend.urls' from '/home/rusbel/Proyectos/Django/CLIVET/apps/mod_backend/urls.py'> (None:mod_backend) ^mod_backend/>], [<RegexURLResolver <module 'apps.accounts.urls' from '/home/rusbel/Proyectos/Django/CLIVET/apps/accounts/urls.py'> (None:None) ^accounts/>], [<RegexURLResolver <module 'apps.clivet.urls' from '/home/rusbel/Proyectos/Django/CLIVET/apps/clivet/urls.py'> (None:clivet) ^clivet/>], [<RegexURLResolver <module 'django.conf.urls.i18n' from '/home/rusbel/Proyectos/myvenv/lib/python3.5/site-packages/django/conf/urls/i18n.py'> (None:None) ^i18n/>], [<RegexURLPattern None ^jsi18n/>], [<RegexURLPattern None ^media\/(?P<path>.*)$>]], 'path': 'bootstrap/images/kittens.jpg'}

During handling of the above exception, another exception occurred:

Traceback (most recent call last):
  File "/home/rusbel/Proyectos/myvenv/lib/python3.5/site-packages/django/template/base.py", line 883, in _resolve_lookup
    current = current[bit]
TypeError: 'RegexURLResolver' object is not subscriptable

During handling of the above exception, another exception occurred:

Traceback (most recent call last):
  File "/home/rusbel/Proyectos/myvenv/lib/python3.5/site-packages/django/template/base.py", line 891, in _resolve_lookup
    current = getattr(current, bit)
AttributeError: 'RegexURLResolver' object has no attribute 'name'

During handling of the above exception, another exception occurred:

Traceback (most recent call last):
  File "/home/rusbel/Proyectos/myvenv/lib/python3.5/site-packages/django/template/base.py", line 898, in _resolve_lookup
    current = current[int(bit)]
ValueError: invalid literal for int() with base 10: 'name'

During handling of the above exception, another exception occurred:

Traceback (most recent call last):
  File "/home/rusbel/Proyectos/myvenv/lib/python3.5/site-packages/django/template/base.py", line 905, in _resolve_lookup
    (bit, current))  # missing attribute
django.template.base.VariableDoesNotExist: Failed lookup for key [name] in "<RegexURLResolver <module 'apps.accounts.urls' from '/home/rusbel/Proyectos/Django/CLIVET/apps/accounts/urls.py'> (None:None) ^accounts/>"
[2016-10-05 00:02:07] DEBUG [django.template:927] Exception while resolving variable 'name' in template 'unknown'.
Traceback (most recent call last):
  File "/home/rusbel/Proyectos/myvenv/lib/python3.5/site-packages/django/core/handlers/base.py", line 134, in get_response
    resolver_match = resolver.resolve(request.path_info)
  File "/home/rusbel/Proyectos/myvenv/lib/python3.5/site-packages/django/core/urlresolvers.py", line 404, in resolve
    raise Resolver404({'tried': tried, 'path': new_path})
django.core.urlresolvers.Resolver404: {'tried': [[<RegexURLResolver <RegexURLPattern list> (admin:admin) ^admin/>], [<RegexURLResolver <module 'django.contrib.admindocs.urls' from '/home/rusbel/Proyectos/myvenv/lib/python3.5/site-packages/django/contrib/admindocs/urls.py'> (None:None) ^admin/doc/>], [<RegexURLResolver <module 'apps.home.urls' from '/home/rusbel/Proyectos/Django/CLIVET/apps/home/urls.py'> (None:home) ^home/>], [<RegexURLPattern index ^$>], [<RegexURLResolver <module 'apps.space.urls' from '/home/rusbel/Proyectos/Django/CLIVET/apps/space/urls.py'> (None:space) ^space/>], [<RegexURLResolver <module 'apps.sad.urls' from '/home/rusbel/Proyectos/Django/CLIVET/apps/sad/urls.py'> (None:sad) ^sad/>], [<RegexURLResolver <module 'apps.mod_backend.urls' from '/home/rusbel/Proyectos/Django/CLIVET/apps/mod_backend/urls.py'> (None:mod_backend) ^mod_backend/>], [<RegexURLResolver <module 'apps.accounts.urls' from '/home/rusbel/Proyectos/Django/CLIVET/apps/accounts/urls.py'> (None:None) ^accounts/>], [<RegexURLResolver <module 'apps.clivet.urls' from '/home/rusbel/Proyectos/Django/CLIVET/apps/clivet/urls.py'> (None:clivet) ^clivet/>], [<RegexURLResolver <module 'django.conf.urls.i18n' from '/home/rusbel/Proyectos/myvenv/lib/python3.5/site-packages/django/conf/urls/i18n.py'> (None:None) ^i18n/>], [<RegexURLPattern None ^jsi18n/>], [<RegexURLPattern None ^media\/(?P<path>.*)$>]], 'path': 'bootstrap/images/kittens.jpg'}

During handling of the above exception, another exception occurred:

Traceback (most recent call last):
  File "/home/rusbel/Proyectos/myvenv/lib/python3.5/site-packages/django/template/base.py", line 883, in _resolve_lookup
    current = current[bit]
TypeError: 'RegexURLResolver' object is not subscriptable

During handling of the above exception, another exception occurred:

Traceback (most recent call last):
  File "/home/rusbel/Proyectos/myvenv/lib/python3.5/site-packages/django/template/base.py", line 891, in _resolve_lookup
    current = getattr(current, bit)
AttributeError: 'RegexURLResolver' object has no attribute 'name'

During handling of the above exception, another exception occurred:

Traceback (most recent call last):
  File "/home/rusbel/Proyectos/myvenv/lib/python3.5/site-packages/django/template/base.py", line 898, in _resolve_lookup
    current = current[int(bit)]
ValueError: invalid literal for int() with base 10: 'name'

During handling of the above exception, another exception occurred:

Traceback (most recent call last):
  File "/home/rusbel/Proyectos/myvenv/lib/python3.5/site-packages/django/template/base.py", line 905, in _resolve_lookup
    (bit, current))  # missing attribute
django.template.base.VariableDoesNotExist: Failed lookup for key [name] in "<RegexURLResolver <module 'apps.clivet.urls' from '/home/rusbel/Proyectos/Django/CLIVET/apps/clivet/urls.py'> (None:clivet) ^clivet/>"
[2016-10-05 00:02:07] DEBUG [django.template:927] Exception while resolving variable 'name' in template 'unknown'.
Traceback (most recent call last):
  File "/home/rusbel/Proyectos/myvenv/lib/python3.5/site-packages/django/core/handlers/base.py", line 134, in get_response
    resolver_match = resolver.resolve(request.path_info)
  File "/home/rusbel/Proyectos/myvenv/lib/python3.5/site-packages/django/core/urlresolvers.py", line 404, in resolve
    raise Resolver404({'tried': tried, 'path': new_path})
django.core.urlresolvers.Resolver404: {'tried': [[<RegexURLResolver <RegexURLPattern list> (admin:admin) ^admin/>], [<RegexURLResolver <module 'django.contrib.admindocs.urls' from '/home/rusbel/Proyectos/myvenv/lib/python3.5/site-packages/django/contrib/admindocs/urls.py'> (None:None) ^admin/doc/>], [<RegexURLResolver <module 'apps.home.urls' from '/home/rusbel/Proyectos/Django/CLIVET/apps/home/urls.py'> (None:home) ^home/>], [<RegexURLPattern index ^$>], [<RegexURLResolver <module 'apps.space.urls' from '/home/rusbel/Proyectos/Django/CLIVET/apps/space/urls.py'> (None:space) ^space/>], [<RegexURLResolver <module 'apps.sad.urls' from '/home/rusbel/Proyectos/Django/CLIVET/apps/sad/urls.py'> (None:sad) ^sad/>], [<RegexURLResolver <module 'apps.mod_backend.urls' from '/home/rusbel/Proyectos/Django/CLIVET/apps/mod_backend/urls.py'> (None:mod_backend) ^mod_backend/>], [<RegexURLResolver <module 'apps.accounts.urls' from '/home/rusbel/Proyectos/Django/CLIVET/apps/accounts/urls.py'> (None:None) ^accounts/>], [<RegexURLResolver <module 'apps.clivet.urls' from '/home/rusbel/Proyectos/Django/CLIVET/apps/clivet/urls.py'> (None:clivet) ^clivet/>], [<RegexURLResolver <module 'django.conf.urls.i18n' from '/home/rusbel/Proyectos/myvenv/lib/python3.5/site-packages/django/conf/urls/i18n.py'> (None:None) ^i18n/>], [<RegexURLPattern None ^jsi18n/>], [<RegexURLPattern None ^media\/(?P<path>.*)$>]], 'path': 'bootstrap/images/kittens.jpg'}

During handling of the above exception, another exception occurred:

Traceback (most recent call last):
  File "/home/rusbel/Proyectos/myvenv/lib/python3.5/site-packages/django/template/base.py", line 883, in _resolve_lookup
    current = current[bit]
TypeError: 'RegexURLResolver' object is not subscriptable

During handling of the above exception, another exception occurred:

Traceback (most recent call last):
  File "/home/rusbel/Proyectos/myvenv/lib/python3.5/site-packages/django/template/base.py", line 891, in _resolve_lookup
    current = getattr(current, bit)
AttributeError: 'RegexURLResolver' object has no attribute 'name'

During handling of the above exception, another exception occurred:

Traceback (most recent call last):
  File "/home/rusbel/Proyectos/myvenv/lib/python3.5/site-packages/django/template/base.py", line 898, in _resolve_lookup
    current = current[int(bit)]
ValueError: invalid literal for int() with base 10: 'name'

During handling of the above exception, another exception occurred:

Traceback (most recent call last):
  File "/home/rusbel/Proyectos/myvenv/lib/python3.5/site-packages/django/template/base.py", line 905, in _resolve_lookup
    (bit, current))  # missing attribute
django.template.base.VariableDoesNotExist: Failed lookup for key [name] in "<RegexURLResolver <module 'django.conf.urls.i18n' from '/home/rusbel/Proyectos/myvenv/lib/python3.5/site-packages/django/conf/urls/i18n.py'> (None:None) ^i18n/>"
[2016-10-05 00:02:10] DEBUG [django.db.backends:89] (0.001) SELECT "django_session"."session_key", "django_session"."session_data", "django_session"."expire_date" FROM "django_session" WHERE ("django_session"."session_key" = '73tz8dalqomobmynelxwtkp1yjyaxv1o' AND "django_session"."expire_date" > '2016-10-05 00:02:10.959968'); args=('73tz8dalqomobmynelxwtkp1yjyaxv1o', '2016-10-05 00:02:10.959968')
[2016-10-05 00:02:10] DEBUG [django.db.backends:89] (0.000) SELECT "auth_user"."id", "auth_user"."password", "auth_user"."last_login", "auth_user"."is_superuser", "auth_user"."username", "auth_user"."first_name", "auth_user"."last_name", "auth_user"."email", "auth_user"."is_staff", "auth_user"."is_active", "auth_user"."date_joined", "auth_user"."last_headquar_id", "auth_user"."last_module_id", "auth_user"."person_id" FROM "auth_user" WHERE "auth_user"."id" = 1; args=(1,)
[2016-10-05 00:02:10] DEBUG [django.template:927] Exception while resolving variable 'is_popup' in template 'admin/index.html'.
Traceback (most recent call last):
  File "/home/rusbel/Proyectos/myvenv/lib/python3.5/site-packages/django/template/base.py", line 883, in _resolve_lookup
    current = current[bit]
  File "/home/rusbel/Proyectos/myvenv/lib/python3.5/site-packages/django/template/context.py", line 77, in __getitem__
    raise KeyError(key)
KeyError: 'is_popup'

During handling of the above exception, another exception occurred:

Traceback (most recent call last):
  File "/home/rusbel/Proyectos/myvenv/lib/python3.5/site-packages/django/template/base.py", line 889, in _resolve_lookup
    if isinstance(current, BaseContext) and getattr(type(current), bit):
AttributeError: type object 'RequestContext' has no attribute 'is_popup'

During handling of the above exception, another exception occurred:

Traceback (most recent call last):
  File "/home/rusbel/Proyectos/myvenv/lib/python3.5/site-packages/django/template/base.py", line 898, in _resolve_lookup
    current = current[int(bit)]
ValueError: invalid literal for int() with base 10: 'is_popup'

During handling of the above exception, another exception occurred:

Traceback (most recent call last):
  File "/home/rusbel/Proyectos/myvenv/lib/python3.5/site-packages/django/template/base.py", line 905, in _resolve_lookup
    (bit, current))  # missing attribute
django.template.base.VariableDoesNotExist: Failed lookup for key [is_popup] in "[{'False': False, 'None': None, 'True': True}, {'request': <WSGIRequest: GET '/admin/'>, 'LANGUAGE_BIDI': False, 'messages': <django.contrib.messages.storage.fallback.FallbackStorage object at 0x7f6be9d09668>, 'MEDIA_URL': '/media/', 'LANGUAGES': (('ja', <django.utils.functional.lazy.<locals>.__proxy__ object at 0x7f6bfc310198>), ('zh-tw', <django.utils.functional.lazy.<locals>.__proxy__ object at 0x7f6bfc3101d0>), ('fr', <django.utils.functional.lazy.<locals>.__proxy__ object at 0x7f6bfc310208>), ('de', <django.utils.functional.lazy.<locals>.__proxy__ object at 0x7f6bfc310240>), ('en', <django.utils.functional.lazy.<locals>.__proxy__ object at 0x7f6bfc321588>), ('es', <django.utils.functional.lazy.<locals>.__proxy__ object at 0x7f6bfc321550>), ('es-ar', <django.utils.functional.lazy.<locals>.__proxy__ object at 0x7f6bfc321518>), ('es-pe', <django.utils.functional.lazy.<locals>.__proxy__ object at 0x7f6bfc3215c0>), ('pt', <django.utils.functional.lazy.<locals>.__proxy__ object at 0x7f6bfc3215f8>), ('pt-br', <django.utils.functional.lazy.<locals>.__proxy__ object at 0x7f6bfc321668>)), 'user': <SimpleLazyObject: <User: admin>>, 'perms': <django.contrib.auth.context_processors.PermWrapper object at 0x7f6be9cb1a58>, 'TIME_ZONE': 'UTC', 'LANGUAGE_CODE': 'es', 'csrf_token': <SimpleLazyObject: <function csrf.<locals>._get_val at 0x7f6bea775a60>>, 'STATIC_URL': '/static/', 'DEFAULT_MESSAGE_LEVELS': {'INFO': 20, 'DEBUG': 10, 'ERROR': 40, 'SUCCESS': 25, 'WARNING': 30}}, {}, {'has_permission': True, 'available_apps': [{'has_module_perms': True, 'name': <django.utils.functional.lazy.<locals>.__proxy__ object at 0x7f6bfaf0b3c8>, 'models': [{'name': <django.utils.functional.lazy.<locals>.__proxy__ object at 0x7f6be9d09ef0>, 'add_url': '/admin/auth/group/add/', 'admin_url': '/admin/auth/group/', 'object_name': 'Group', 'perms': {'delete': True, 'change': True, 'add': True}}, {'name': <django.utils.functional.lazy.<locals>.__proxy__ object at 0x7f6be9d09978>, 'add_url': '/admin/auth/permission/add/', 'admin_url': '/admin/auth/permission/', 'object_name': 'Permission', 'perms': {'delete': True, 'change': True, 'add': True}}], 'app_label': 'auth', 'app_url': '/admin/auth/'}, {'has_module_perms': True, 'name': 'Params', 'models': [{'name': <django.utils.functional.lazy.<locals>.__proxy__ object at 0x7f6be9d09908>, 'add_url': '/admin/params/person/add/', 'admin_url': '/admin/params/person/', 'object_name': 'Person', 'perms': {'delete': True, 'change': True, 'add': True}}], 'app_label': 'params', 'app_url': '/admin/params/'}, {'has_module_perms': True, 'name': <django.utils.functional.lazy.<locals>.__proxy__ object at 0x7f6bfaf15978>, 'models': [{'name': <django.utils.functional.lazy.<locals>.__proxy__ object at 0x7f6bea7cdcf8>, 'add_url': '/admin/flatpages/flatpage/add/', 'admin_url': '/admin/flatpages/flatpage/', 'object_name': 'FlatPage', 'perms': {'delete': True, 'change': True, 'add': True}}], 'app_label': 'flatpages', 'app_url': '/admin/flatpages/'}, {'has_module_perms': True, 'name': 'Sad', 'models': [{'name': <django.utils.functional.lazy.<locals>.__proxy__ object at 0x7f6bf95fdcf8>, 'add_url': '/admin/sad/user/add/', 'admin_url': '/admin/sad/user/', 'object_name': 'User', 'perms': {'delete': True, 'change': True, 'add': True}}], 'app_label': 'sad', 'app_url': '/admin/sad/'}, {'has_module_perms': True, 'name': <django.utils.functional.lazy.<locals>.__proxy__ object at 0x7f6bfaf15898>, 'models': [{'name': <django.utils.functional.lazy.<locals>.__proxy__ object at 0x7f6bf906cdd8>, 'add_url': '/admin/sites/site/add/', 'admin_url': '/admin/sites/site/', 'object_name': 'Site', 'perms': {'delete': True, 'change': True, 'add': True}}], 'app_label': 'sites', 'app_url': '/admin/sites/'}, {'has_module_perms': True, 'name': 'Space', 'models': [{'name': <django.utils.functional.lazy.<locals>.__proxy__ object at 0x7f6be9d09eb8>, 'add_url': '/admin/space/solution/add/', 'admin_url': '/admin/space/solution/', 'object_name': 'Solution', 'perms': {'delete': True, 'change': True, 'add': True}}], 'app_label': 'space', 'app_url': '/admin/space/'}, {'has_module_perms': True, 'name': <django.utils.functional.lazy.<locals>.__proxy__ object at 0x7f6bfaf0bb38>, 'models': [{'name': <django.utils.functional.lazy.<locals>.__proxy__ object at 0x7f6be9d09ac8>, 'add_url': '/admin/contenttypes/contenttype/add/', 'admin_url': '/admin/contenttypes/contenttype/', 'object_name': 'ContentType', 'perms': {'delete': True, 'change': True, 'add': True}}], 'app_label': 'contenttypes', 'app_url': '/admin/contenttypes/'}], 'title': <django.utils.functional.lazy.<locals>.__proxy__ object at 0x7f6bfaf04c18>, 'site_title': <django.utils.functional.lazy.<locals>.__proxy__ object at 0x7f6bfaf04710>, 'site_url': '/', 'site_header': <django.utils.functional.lazy.<locals>.__proxy__ object at 0x7f6bfaf047b8>, 'LANGUAGE_CODE': 'es', 'app_list': [{'has_module_perms': True, 'name': <django.utils.functional.lazy.<locals>.__proxy__ object at 0x7f6bfaf0b3c8>, 'models': [{'name': <django.utils.functional.lazy.<locals>.__proxy__ object at 0x7f6bf95fda20>, 'add_url': '/admin/auth/group/add/', 'admin_url': '/admin/auth/group/', 'object_name': 'Group', 'perms': {'delete': True, 'change': True, 'add': True}}, {'name': <django.utils.functional.lazy.<locals>.__proxy__ object at 0x7f6bf9603278>, 'add_url': '/admin/auth/permission/add/', 'admin_url': '/admin/auth/permission/', 'object_name': 'Permission', 'perms': {'delete': True, 'change': True, 'add': True}}], 'app_label': 'auth', 'app_url': '/admin/auth/'}, {'has_module_perms': True, 'name': 'Params', 'models': [{'name': <django.utils.functional.lazy.<locals>.__proxy__ object at 0x7f6bf95fdda0>, 'add_url': '/admin/params/person/add/', 'admin_url': '/admin/params/person/', 'object_name': 'Person', 'perms': {'delete': True, 'change': True, 'add': True}}], 'app_label': 'params', 'app_url': '/admin/params/'}, {'has_module_perms': True, 'name': <django.utils.functional.lazy.<locals>.__proxy__ object at 0x7f6bfaf15978>, 'models': [{'name': <django.utils.functional.lazy.<locals>.__proxy__ object at 0x7f6bf9603160>, 'add_url': '/admin/flatpages/flatpage/add/', 'admin_url': '/admin/flatpages/flatpage/', 'object_name': 'FlatPage', 'perms': {'delete': True, 'change': True, 'add': True}}], 'app_label': 'flatpages', 'app_url': '/admin/flatpages/'}, {'has_module_perms': True, 'name': 'Sad', 'models': [{'name': <django.utils.functional.lazy.<locals>.__proxy__ object at 0x7f6be9d091d0>, 'add_url': '/admin/sad/user/add/', 'admin_url': '/admin/sad/user/', 'object_name': 'User', 'perms': {'delete': True, 'change': True, 'add': True}}], 'app_label': 'sad', 'app_url': '/admin/sad/'}, {'has_module_perms': True, 'name': <django.utils.functional.lazy.<locals>.__proxy__ object at 0x7f6bfaf15898>, 'models': [{'name': <django.utils.functional.lazy.<locals>.__proxy__ object at 0x7f6be9d09c18>, 'add_url': '/admin/sites/site/add/', 'admin_url': '/admin/sites/site/', 'object_name': 'Site', 'perms': {'delete': True, 'change': True, 'add': True}}], 'app_label': 'sites', 'app_url': '/admin/sites/'}, {'has_module_perms': True, 'name': 'Space', 'models': [{'name': <django.utils.functional.lazy.<locals>.__proxy__ object at 0x7f6bf96038d0>, 'add_url': '/admin/space/solution/add/', 'admin_url': '/admin/space/solution/', 'object_name': 'Solution', 'perms': {'delete': True, 'change': True, 'add': True}}], 'app_label': 'space', 'app_url': '/admin/space/'}, {'has_module_perms': True, 'name': <django.utils.functional.lazy.<locals>.__proxy__ object at 0x7f6bfaf0bb38>, 'models': [{'name': <django.utils.functional.lazy.<locals>.__proxy__ object at 0x7f6bf9603e10>, 'add_url': '/admin/contenttypes/contenttype/add/', 'admin_url': '/admin/contenttypes/contenttype/', 'object_name': 'ContentType', 'perms': {'delete': True, 'change': True, 'add': True}}], 'app_label': 'contenttypes', 'app_url': '/admin/contenttypes/'}], 'LANGUAGE_BIDI': False}]"
[2016-10-05 00:02:10] DEBUG [django.template:927] Exception while resolving variable 'is_popup' in template 'admin/index.html'.
Traceback (most recent call last):
  File "/home/rusbel/Proyectos/myvenv/lib/python3.5/site-packages/django/template/base.py", line 883, in _resolve_lookup
    current = current[bit]
  File "/home/rusbel/Proyectos/myvenv/lib/python3.5/site-packages/django/template/context.py", line 77, in __getitem__
    raise KeyError(key)
KeyError: 'is_popup'

During handling of the above exception, another exception occurred:

Traceback (most recent call last):
  File "/home/rusbel/Proyectos/myvenv/lib/python3.5/site-packages/django/template/base.py", line 889, in _resolve_lookup
    if isinstance(current, BaseContext) and getattr(type(current), bit):
AttributeError: type object 'RequestContext' has no attribute 'is_popup'

During handling of the above exception, another exception occurred:

Traceback (most recent call last):
  File "/home/rusbel/Proyectos/myvenv/lib/python3.5/site-packages/django/template/base.py", line 898, in _resolve_lookup
    current = current[int(bit)]
ValueError: invalid literal for int() with base 10: 'is_popup'

During handling of the above exception, another exception occurred:

Traceback (most recent call last):
  File "/home/rusbel/Proyectos/myvenv/lib/python3.5/site-packages/django/template/base.py", line 905, in _resolve_lookup
    (bit, current))  # missing attribute
django.template.base.VariableDoesNotExist: Failed lookup for key [is_popup] in "[{'False': False, 'None': None, 'True': True}, {'request': <WSGIRequest: GET '/admin/'>, 'LANGUAGE_BIDI': False, 'messages': <django.contrib.messages.storage.fallback.FallbackStorage object at 0x7f6be9d09668>, 'MEDIA_URL': '/media/', 'LANGUAGES': (('ja', <django.utils.functional.lazy.<locals>.__proxy__ object at 0x7f6bfc310198>), ('zh-tw', <django.utils.functional.lazy.<locals>.__proxy__ object at 0x7f6bfc3101d0>), ('fr', <django.utils.functional.lazy.<locals>.__proxy__ object at 0x7f6bfc310208>), ('de', <django.utils.functional.lazy.<locals>.__proxy__ object at 0x7f6bfc310240>), ('en', <django.utils.functional.lazy.<locals>.__proxy__ object at 0x7f6bfc321588>), ('es', <django.utils.functional.lazy.<locals>.__proxy__ object at 0x7f6bfc321550>), ('es-ar', <django.utils.functional.lazy.<locals>.__proxy__ object at 0x7f6bfc321518>), ('es-pe', <django.utils.functional.lazy.<locals>.__proxy__ object at 0x7f6bfc3215c0>), ('pt', <django.utils.functional.lazy.<locals>.__proxy__ object at 0x7f6bfc3215f8>), ('pt-br', <django.utils.functional.lazy.<locals>.__proxy__ object at 0x7f6bfc321668>)), 'user': <SimpleLazyObject: <User: admin>>, 'perms': <django.contrib.auth.context_processors.PermWrapper object at 0x7f6be9cb1a58>, 'TIME_ZONE': 'UTC', 'LANGUAGE_CODE': 'es', 'csrf_token': <SimpleLazyObject: <function csrf.<locals>._get_val at 0x7f6bea775a60>>, 'STATIC_URL': '/static/', 'DEFAULT_MESSAGE_LEVELS': {'INFO': 20, 'DEBUG': 10, 'ERROR': 40, 'SUCCESS': 25, 'WARNING': 30}}, {}, {'has_permission': True, 'available_apps': [{'has_module_perms': True, 'name': <django.utils.functional.lazy.<locals>.__proxy__ object at 0x7f6bfaf0b3c8>, 'models': [{'name': <django.utils.functional.lazy.<locals>.__proxy__ object at 0x7f6be9d09ef0>, 'add_url': '/admin/auth/group/add/', 'admin_url': '/admin/auth/group/', 'object_name': 'Group', 'perms': {'delete': True, 'change': True, 'add': True}}, {'name': <django.utils.functional.lazy.<locals>.__proxy__ object at 0x7f6be9d09978>, 'add_url': '/admin/auth/permission/add/', 'admin_url': '/admin/auth/permission/', 'object_name': 'Permission', 'perms': {'delete': True, 'change': True, 'add': True}}], 'app_label': 'auth', 'app_url': '/admin/auth/'}, {'has_module_perms': True, 'name': 'Params', 'models': [{'name': <django.utils.functional.lazy.<locals>.__proxy__ object at 0x7f6be9d09908>, 'add_url': '/admin/params/person/add/', 'admin_url': '/admin/params/person/', 'object_name': 'Person', 'perms': {'delete': True, 'change': True, 'add': True}}], 'app_label': 'params', 'app_url': '/admin/params/'}, {'has_module_perms': True, 'name': <django.utils.functional.lazy.<locals>.__proxy__ object at 0x7f6bfaf15978>, 'models': [{'name': <django.utils.functional.lazy.<locals>.__proxy__ object at 0x7f6bea7cdcf8>, 'add_url': '/admin/flatpages/flatpage/add/', 'admin_url': '/admin/flatpages/flatpage/', 'object_name': 'FlatPage', 'perms': {'delete': True, 'change': True, 'add': True}}], 'app_label': 'flatpages', 'app_url': '/admin/flatpages/'}, {'has_module_perms': True, 'name': 'Sad', 'models': [{'name': <django.utils.functional.lazy.<locals>.__proxy__ object at 0x7f6bf95fdcf8>, 'add_url': '/admin/sad/user/add/', 'admin_url': '/admin/sad/user/', 'object_name': 'User', 'perms': {'delete': True, 'change': True, 'add': True}}], 'app_label': 'sad', 'app_url': '/admin/sad/'}, {'has_module_perms': True, 'name': <django.utils.functional.lazy.<locals>.__proxy__ object at 0x7f6bfaf15898>, 'models': [{'name': <django.utils.functional.lazy.<locals>.__proxy__ object at 0x7f6bf906cdd8>, 'add_url': '/admin/sites/site/add/', 'admin_url': '/admin/sites/site/', 'object_name': 'Site', 'perms': {'delete': True, 'change': True, 'add': True}}], 'app_label': 'sites', 'app_url': '/admin/sites/'}, {'has_module_perms': True, 'name': 'Space', 'models': [{'name': <django.utils.functional.lazy.<locals>.__proxy__ object at 0x7f6be9d09eb8>, 'add_url': '/admin/space/solution/add/', 'admin_url': '/admin/space/solution/', 'object_name': 'Solution', 'perms': {'delete': True, 'change': True, 'add': True}}], 'app_label': 'space', 'app_url': '/admin/space/'}, {'has_module_perms': True, 'name': <django.utils.functional.lazy.<locals>.__proxy__ object at 0x7f6bfaf0bb38>, 'models': [{'name': <django.utils.functional.lazy.<locals>.__proxy__ object at 0x7f6be9d09ac8>, 'add_url': '/admin/contenttypes/contenttype/add/', 'admin_url': '/admin/contenttypes/contenttype/', 'object_name': 'ContentType', 'perms': {'delete': True, 'change': True, 'add': True}}], 'app_label': 'contenttypes', 'app_url': '/admin/contenttypes/'}], 'title': <django.utils.functional.lazy.<locals>.__proxy__ object at 0x7f6bfaf04c18>, 'site_title': <django.utils.functional.lazy.<locals>.__proxy__ object at 0x7f6bfaf04710>, 'site_url': '/', 'site_header': <django.utils.functional.lazy.<locals>.__proxy__ object at 0x7f6bfaf047b8>, 'LANGUAGE_CODE': 'es', 'app_list': [{'has_module_perms': True, 'name': <django.utils.functional.lazy.<locals>.__proxy__ object at 0x7f6bfaf0b3c8>, 'models': [{'name': <django.utils.functional.lazy.<locals>.__proxy__ object at 0x7f6bf95fda20>, 'add_url': '/admin/auth/group/add/', 'admin_url': '/admin/auth/group/', 'object_name': 'Group', 'perms': {'delete': True, 'change': True, 'add': True}}, {'name': <django.utils.functional.lazy.<locals>.__proxy__ object at 0x7f6bf9603278>, 'add_url': '/admin/auth/permission/add/', 'admin_url': '/admin/auth/permission/', 'object_name': 'Permission', 'perms': {'delete': True, 'change': True, 'add': True}}], 'app_label': 'auth', 'app_url': '/admin/auth/'}, {'has_module_perms': True, 'name': 'Params', 'models': [{'name': <django.utils.functional.lazy.<locals>.__proxy__ object at 0x7f6bf95fdda0>, 'add_url': '/admin/params/person/add/', 'admin_url': '/admin/params/person/', 'object_name': 'Person', 'perms': {'delete': True, 'change': True, 'add': True}}], 'app_label': 'params', 'app_url': '/admin/params/'}, {'has_module_perms': True, 'name': <django.utils.functional.lazy.<locals>.__proxy__ object at 0x7f6bfaf15978>, 'models': [{'name': <django.utils.functional.lazy.<locals>.__proxy__ object at 0x7f6bf9603160>, 'add_url': '/admin/flatpages/flatpage/add/', 'admin_url': '/admin/flatpages/flatpage/', 'object_name': 'FlatPage', 'perms': {'delete': True, 'change': True, 'add': True}}], 'app_label': 'flatpages', 'app_url': '/admin/flatpages/'}, {'has_module_perms': True, 'name': 'Sad', 'models': [{'name': <django.utils.functional.lazy.<locals>.__proxy__ object at 0x7f6be9d091d0>, 'add_url': '/admin/sad/user/add/', 'admin_url': '/admin/sad/user/', 'object_name': 'User', 'perms': {'delete': True, 'change': True, 'add': True}}], 'app_label': 'sad', 'app_url': '/admin/sad/'}, {'has_module_perms': True, 'name': <django.utils.functional.lazy.<locals>.__proxy__ object at 0x7f6bfaf15898>, 'models': [{'name': <django.utils.functional.lazy.<locals>.__proxy__ object at 0x7f6be9d09c18>, 'add_url': '/admin/sites/site/add/', 'admin_url': '/admin/sites/site/', 'object_name': 'Site', 'perms': {'delete': True, 'change': True, 'add': True}}], 'app_label': 'sites', 'app_url': '/admin/sites/'}, {'has_module_perms': True, 'name': 'Space', 'models': [{'name': <django.utils.functional.lazy.<locals>.__proxy__ object at 0x7f6bf96038d0>, 'add_url': '/admin/space/solution/add/', 'admin_url': '/admin/space/solution/', 'object_name': 'Solution', 'perms': {'delete': True, 'change': True, 'add': True}}], 'app_label': 'space', 'app_url': '/admin/space/'}, {'has_module_perms': True, 'name': <django.utils.functional.lazy.<locals>.__proxy__ object at 0x7f6bfaf0bb38>, 'models': [{'name': <django.utils.functional.lazy.<locals>.__proxy__ object at 0x7f6bf9603e10>, 'add_url': '/admin/contenttypes/contenttype/add/', 'admin_url': '/admin/contenttypes/contenttype/', 'object_name': 'ContentType', 'perms': {'delete': True, 'change': True, 'add': True}}], 'app_label': 'contenttypes', 'app_url': '/admin/contenttypes/'}], 'LANGUAGE_BIDI': False}]"
[2016-10-05 00:02:10] DEBUG [django.db.backends:89] (0.000) SELECT "django_admin_log"."id", "django_admin_log"."action_time", "django_admin_log"."user_id", "django_admin_log"."content_type_id", "django_admin_log"."object_id", "django_admin_log"."object_repr", "django_admin_log"."action_flag", "django_admin_log"."change_message", "auth_user"."id", "auth_user"."password", "auth_user"."last_login", "auth_user"."is_superuser", "auth_user"."username", "auth_user"."first_name", "auth_user"."last_name", "auth_user"."email", "auth_user"."is_staff", "auth_user"."is_active", "auth_user"."date_joined", "auth_user"."last_headquar_id", "auth_user"."last_module_id", "auth_user"."person_id", "django_content_type"."id", "django_content_type"."app_label", "django_content_type"."model" FROM "django_admin_log" INNER JOIN "auth_user" ON ("django_admin_log"."user_id" = "auth_user"."id") LEFT OUTER JOIN "django_content_type" ON ("django_admin_log"."content_type_id" = "django_content_type"."id") WHERE "django_admin_log"."user_id" = 1 ORDER BY "django_admin_log"."action_time" DESC LIMIT 10; args=(1,)
[2016-10-05 00:02:14] DEBUG [django.db.backends:89] (0.001) SELECT "django_session"."session_key", "django_session"."session_data", "django_session"."expire_date" FROM "django_session" WHERE ("django_session"."session_key" = '73tz8dalqomobmynelxwtkp1yjyaxv1o' AND "django_session"."expire_date" > '2016-10-05 00:02:14.736737'); args=('73tz8dalqomobmynelxwtkp1yjyaxv1o', '2016-10-05 00:02:14.736737')
[2016-10-05 00:02:14] DEBUG [django.db.backends:89] (0.000) SELECT "auth_user"."id", "auth_user"."password", "auth_user"."last_login", "auth_user"."is_superuser", "auth_user"."username", "auth_user"."first_name", "auth_user"."last_name", "auth_user"."email", "auth_user"."is_staff", "auth_user"."is_active", "auth_user"."date_joined", "auth_user"."last_headquar_id", "auth_user"."last_module_id", "auth_user"."person_id" FROM "auth_user" WHERE "auth_user"."id" = 1; args=(1,)
[2016-10-05 00:02:14] DEBUG [django.db.backends:89] (0.000) SELECT COUNT(*) AS "__count" FROM "params_person"; args=()
[2016-10-05 00:02:14] DEBUG [django.db.backends:89] (0.000) SELECT "params_person"."id", "params_person"."identity_type", "params_person"."identity_num", "params_person"."first_name", "params_person"."last_name", "params_person"."birth_date", "params_person"."photo" FROM "params_person" ORDER BY "params_person"."id" DESC; args=()
[2016-10-05 00:02:14] DEBUG [django.template:927] Exception while resolving variable 'errors' in template 'admin/change_list.html'.
Traceback (most recent call last):
  File "/home/rusbel/Proyectos/myvenv/lib/python3.5/site-packages/django/template/base.py", line 883, in _resolve_lookup
    current = current[bit]
TypeError: 'NoneType' object is not subscriptable

During handling of the above exception, another exception occurred:

Traceback (most recent call last):
  File "/home/rusbel/Proyectos/myvenv/lib/python3.5/site-packages/django/template/base.py", line 891, in _resolve_lookup
    current = getattr(current, bit)
AttributeError: 'NoneType' object has no attribute 'errors'

During handling of the above exception, another exception occurred:

Traceback (most recent call last):
  File "/home/rusbel/Proyectos/myvenv/lib/python3.5/site-packages/django/template/base.py", line 898, in _resolve_lookup
    current = current[int(bit)]
ValueError: invalid literal for int() with base 10: 'errors'

During handling of the above exception, another exception occurred:

Traceback (most recent call last):
  File "/home/rusbel/Proyectos/myvenv/lib/python3.5/site-packages/django/template/base.py", line 905, in _resolve_lookup
    (bit, current))  # missing attribute
django.template.base.VariableDoesNotExist: Failed lookup for key [errors] in 'None'
[2016-10-05 00:02:14] DEBUG [django.template:927] Exception while resolving variable 'show' in template 'admin/change_list.html'.
Traceback (most recent call last):
  File "/home/rusbel/Proyectos/myvenv/lib/python3.5/site-packages/django/template/base.py", line 883, in _resolve_lookup
    current = current[bit]
  File "/home/rusbel/Proyectos/myvenv/lib/python3.5/site-packages/django/template/context.py", line 77, in __getitem__
    raise KeyError(key)
KeyError: 'show'

During handling of the above exception, another exception occurred:

Traceback (most recent call last):
  File "/home/rusbel/Proyectos/myvenv/lib/python3.5/site-packages/django/template/base.py", line 889, in _resolve_lookup
    if isinstance(current, BaseContext) and getattr(type(current), bit):
AttributeError: type object 'RequestContext' has no attribute 'show'

During handling of the above exception, another exception occurred:

Traceback (most recent call last):
  File "/home/rusbel/Proyectos/myvenv/lib/python3.5/site-packages/django/template/base.py", line 898, in _resolve_lookup
    current = current[int(bit)]
ValueError: invalid literal for int() with base 10: 'show'

During handling of the above exception, another exception occurred:

Traceback (most recent call last):
  File "/home/rusbel/Proyectos/myvenv/lib/python3.5/site-packages/django/template/base.py", line 905, in _resolve_lookup
    (bit, current))  # missing attribute
django.template.base.VariableDoesNotExist: Failed lookup for key [show] in "[{'False': False, 'None': None, 'True': True, 'csrf_token': <SimpleLazyObject: <function csrf.<locals>._get_val at 0x7f6bea76ed08>>}]"
[2016-10-05 00:02:14] DEBUG [django.template:927] Exception while resolving variable 'is_multipart' in template 'admin/change_list.html'.
Traceback (most recent call last):
  File "/home/rusbel/Proyectos/myvenv/lib/python3.5/site-packages/django/template/base.py", line 883, in _resolve_lookup
    current = current[bit]
TypeError: 'NoneType' object is not subscriptable

During handling of the above exception, another exception occurred:

Traceback (most recent call last):
  File "/home/rusbel/Proyectos/myvenv/lib/python3.5/site-packages/django/template/base.py", line 891, in _resolve_lookup
    current = getattr(current, bit)
AttributeError: 'NoneType' object has no attribute 'is_multipart'

During handling of the above exception, another exception occurred:

Traceback (most recent call last):
  File "/home/rusbel/Proyectos/myvenv/lib/python3.5/site-packages/django/template/base.py", line 898, in _resolve_lookup
    current = current[int(bit)]
ValueError: invalid literal for int() with base 10: 'is_multipart'

During handling of the above exception, another exception occurred:

Traceback (most recent call last):
  File "/home/rusbel/Proyectos/myvenv/lib/python3.5/site-packages/django/template/base.py", line 905, in _resolve_lookup
    (bit, current))  # missing attribute
django.template.base.VariableDoesNotExist: Failed lookup for key [is_multipart] in 'None'
[2016-10-05 00:02:14] DEBUG [django.template:927] Exception while resolving variable 'non_field_errors' in template 'admin/change_list.html'.
Traceback (most recent call last):
  File "/home/rusbel/Proyectos/myvenv/lib/python3.5/site-packages/django/template/base.py", line 883, in _resolve_lookup
    current = current[bit]
TypeError: 'NoneType' object is not subscriptable

During handling of the above exception, another exception occurred:

Traceback (most recent call last):
  File "/home/rusbel/Proyectos/myvenv/lib/python3.5/site-packages/django/template/base.py", line 891, in _resolve_lookup
    current = getattr(current, bit)
AttributeError: 'NoneType' object has no attribute 'non_field_errors'

During handling of the above exception, another exception occurred:

Traceback (most recent call last):
  File "/home/rusbel/Proyectos/myvenv/lib/python3.5/site-packages/django/template/base.py", line 898, in _resolve_lookup
    current = current[int(bit)]
ValueError: invalid literal for int() with base 10: 'non_field_errors'

During handling of the above exception, another exception occurred:

Traceback (most recent call last):
  File "/home/rusbel/Proyectos/myvenv/lib/python3.5/site-packages/django/template/base.py", line 905, in _resolve_lookup
    (bit, current))  # missing attribute
django.template.base.VariableDoesNotExist: Failed lookup for key [non_field_errors] in 'None'
[2016-10-05 00:02:14] DEBUG [django.db.backends:89] (0.004) SELECT "django_session"."session_key", "django_session"."session_data", "django_session"."expire_date" FROM "django_session" WHERE ("django_session"."session_key" = '73tz8dalqomobmynelxwtkp1yjyaxv1o' AND "django_session"."expire_date" > '2016-10-05 00:02:14.819342'); args=('73tz8dalqomobmynelxwtkp1yjyaxv1o', '2016-10-05 00:02:14.819342')
[2016-10-05 00:02:14] DEBUG [django.db.backends:89] (0.000) SELECT "auth_user"."id", "auth_user"."password", "auth_user"."last_login", "auth_user"."is_superuser", "auth_user"."username", "auth_user"."first_name", "auth_user"."last_name", "auth_user"."email", "auth_user"."is_staff", "auth_user"."is_active", "auth_user"."date_joined", "auth_user"."last_headquar_id", "auth_user"."last_module_id", "auth_user"."person_id" FROM "auth_user" WHERE "auth_user"."id" = 1; args=(1,)
[2016-10-05 00:02:16] DEBUG [django.db.backends:89] (0.001) SELECT "django_session"."session_key", "django_session"."session_data", "django_session"."expire_date" FROM "django_session" WHERE ("django_session"."session_key" = '73tz8dalqomobmynelxwtkp1yjyaxv1o' AND "django_session"."expire_date" > '2016-10-05 00:02:16.647620'); args=('73tz8dalqomobmynelxwtkp1yjyaxv1o', '2016-10-05 00:02:16.647620')
[2016-10-05 00:02:16] DEBUG [django.db.backends:89] (0.000) SELECT "auth_user"."id", "auth_user"."password", "auth_user"."last_login", "auth_user"."is_superuser", "auth_user"."username", "auth_user"."first_name", "auth_user"."last_name", "auth_user"."email", "auth_user"."is_staff", "auth_user"."is_active", "auth_user"."date_joined", "auth_user"."last_headquar_id", "auth_user"."last_module_id", "auth_user"."person_id" FROM "auth_user" WHERE "auth_user"."id" = 1; args=(1,)
[2016-10-05 00:02:16] DEBUG [django.template:927] Exception while resolving variable 'is_popup' in template 'admin/index.html'.
Traceback (most recent call last):
  File "/home/rusbel/Proyectos/myvenv/lib/python3.5/site-packages/django/template/base.py", line 883, in _resolve_lookup
    current = current[bit]
  File "/home/rusbel/Proyectos/myvenv/lib/python3.5/site-packages/django/template/context.py", line 77, in __getitem__
    raise KeyError(key)
KeyError: 'is_popup'

During handling of the above exception, another exception occurred:

Traceback (most recent call last):
  File "/home/rusbel/Proyectos/myvenv/lib/python3.5/site-packages/django/template/base.py", line 889, in _resolve_lookup
    if isinstance(current, BaseContext) and getattr(type(current), bit):
AttributeError: type object 'RequestContext' has no attribute 'is_popup'

During handling of the above exception, another exception occurred:

Traceback (most recent call last):
  File "/home/rusbel/Proyectos/myvenv/lib/python3.5/site-packages/django/template/base.py", line 898, in _resolve_lookup
    current = current[int(bit)]
ValueError: invalid literal for int() with base 10: 'is_popup'

During handling of the above exception, another exception occurred:

Traceback (most recent call last):
  File "/home/rusbel/Proyectos/myvenv/lib/python3.5/site-packages/django/template/base.py", line 905, in _resolve_lookup
    (bit, current))  # missing attribute
django.template.base.VariableDoesNotExist: Failed lookup for key [is_popup] in "[{'False': False, 'None': None, 'True': True}, {'request': <WSGIRequest: GET '/admin/'>, 'LANGUAGE_BIDI': False, 'messages': <django.contrib.messages.storage.fallback.FallbackStorage object at 0x7f6be9c85048>, 'MEDIA_URL': '/media/', 'LANGUAGES': (('ja', <django.utils.functional.lazy.<locals>.__proxy__ object at 0x7f6bfc310198>), ('zh-tw', <django.utils.functional.lazy.<locals>.__proxy__ object at 0x7f6bfc3101d0>), ('fr', <django.utils.functional.lazy.<locals>.__proxy__ object at 0x7f6bfc310208>), ('de', <django.utils.functional.lazy.<locals>.__proxy__ object at 0x7f6bfc310240>), ('en', <django.utils.functional.lazy.<locals>.__proxy__ object at 0x7f6bfc321588>), ('es', <django.utils.functional.lazy.<locals>.__proxy__ object at 0x7f6bfc321550>), ('es-ar', <django.utils.functional.lazy.<locals>.__proxy__ object at 0x7f6bfc321518>), ('es-pe', <django.utils.functional.lazy.<locals>.__proxy__ object at 0x7f6bfc3215c0>), ('pt', <django.utils.functional.lazy.<locals>.__proxy__ object at 0x7f6bfc3215f8>), ('pt-br', <django.utils.functional.lazy.<locals>.__proxy__ object at 0x7f6bfc321668>)), 'user': <SimpleLazyObject: <User: admin>>, 'perms': <django.contrib.auth.context_processors.PermWrapper object at 0x7f6bf9078390>, 'TIME_ZONE': 'UTC', 'LANGUAGE_CODE': 'es', 'csrf_token': <SimpleLazyObject: <function csrf.<locals>._get_val at 0x7f6bea76e2f0>>, 'STATIC_URL': '/static/', 'DEFAULT_MESSAGE_LEVELS': {'INFO': 20, 'DEBUG': 10, 'ERROR': 40, 'SUCCESS': 25, 'WARNING': 30}}, {}, {'has_permission': True, 'available_apps': [{'has_module_perms': True, 'name': <django.utils.functional.lazy.<locals>.__proxy__ object at 0x7f6bfaf0b3c8>, 'models': [{'name': <django.utils.functional.lazy.<locals>.__proxy__ object at 0x7f6be9cca828>, 'add_url': '/admin/auth/group/add/', 'admin_url': '/admin/auth/group/', 'object_name': 'Group', 'perms': {'delete': True, 'change': True, 'add': True}}, {'name': <django.utils.functional.lazy.<locals>.__proxy__ object at 0x7f6be9ccae48>, 'add_url': '/admin/auth/permission/add/', 'admin_url': '/admin/auth/permission/', 'object_name': 'Permission', 'perms': {'delete': True, 'change': True, 'add': True}}], 'app_label': 'auth', 'app_url': '/admin/auth/'}, {'has_module_perms': True, 'name': 'Params', 'models': [{'name': <django.utils.functional.lazy.<locals>.__proxy__ object at 0x7f6be9cca978>, 'add_url': '/admin/params/person/add/', 'admin_url': '/admin/params/person/', 'object_name': 'Person', 'perms': {'delete': True, 'change': True, 'add': True}}], 'app_label': 'params', 'app_url': '/admin/params/'}, {'has_module_perms': True, 'name': <django.utils.functional.lazy.<locals>.__proxy__ object at 0x7f6bfaf15978>, 'models': [{'name': <django.utils.functional.lazy.<locals>.__proxy__ object at 0x7f6be9ccabe0>, 'add_url': '/admin/flatpages/flatpage/add/', 'admin_url': '/admin/flatpages/flatpage/', 'object_name': 'FlatPage', 'perms': {'delete': True, 'change': True, 'add': True}}], 'app_label': 'flatpages', 'app_url': '/admin/flatpages/'}, {'has_module_perms': True, 'name': 'Sad', 'models': [{'name': <django.utils.functional.lazy.<locals>.__proxy__ object at 0x7f6be9cca630>, 'add_url': '/admin/sad/user/add/', 'admin_url': '/admin/sad/user/', 'object_name': 'User', 'perms': {'delete': True, 'change': True, 'add': True}}], 'app_label': 'sad', 'app_url': '/admin/sad/'}, {'has_module_perms': True, 'name': <django.utils.functional.lazy.<locals>.__proxy__ object at 0x7f6bfaf15898>, 'models': [{'name': <django.utils.functional.lazy.<locals>.__proxy__ object at 0x7f6be9ccafd0>, 'add_url': '/admin/sites/site/add/', 'admin_url': '/admin/sites/site/', 'object_name': 'Site', 'perms': {'delete': True, 'change': True, 'add': True}}], 'app_label': 'sites', 'app_url': '/admin/sites/'}, {'has_module_perms': True, 'name': 'Space', 'models': [{'name': <django.utils.functional.lazy.<locals>.__proxy__ object at 0x7f6be9cca780>, 'add_url': '/admin/space/solution/add/', 'admin_url': '/admin/space/solution/', 'object_name': 'Solution', 'perms': {'delete': True, 'change': True, 'add': True}}], 'app_label': 'space', 'app_url': '/admin/space/'}, {'has_module_perms': True, 'name': <django.utils.functional.lazy.<locals>.__proxy__ object at 0x7f6bfaf0bb38>, 'models': [{'name': <django.utils.functional.lazy.<locals>.__proxy__ object at 0x7f6be9ccad68>, 'add_url': '/admin/contenttypes/contenttype/add/', 'admin_url': '/admin/contenttypes/contenttype/', 'object_name': 'ContentType', 'perms': {'delete': True, 'change': True, 'add': True}}], 'app_label': 'contenttypes', 'app_url': '/admin/contenttypes/'}], 'title': <django.utils.functional.lazy.<locals>.__proxy__ object at 0x7f6bfaf04c18>, 'site_title': <django.utils.functional.lazy.<locals>.__proxy__ object at 0x7f6bfaf04710>, 'site_url': '/', 'site_header': <django.utils.functional.lazy.<locals>.__proxy__ object at 0x7f6bfaf047b8>, 'LANGUAGE_CODE': 'es', 'app_list': [{'has_module_perms': True, 'name': <django.utils.functional.lazy.<locals>.__proxy__ object at 0x7f6bfaf0b3c8>, 'models': [{'name': <django.utils.functional.lazy.<locals>.__proxy__ object at 0x7f6be9cca8d0>, 'add_url': '/admin/auth/group/add/', 'admin_url': '/admin/auth/group/', 'object_name': 'Group', 'perms': {'delete': True, 'change': True, 'add': True}}, {'name': <django.utils.functional.lazy.<locals>.__proxy__ object at 0x7f6be9c85390>, 'add_url': '/admin/auth/permission/add/', 'admin_url': '/admin/auth/permission/', 'object_name': 'Permission', 'perms': {'delete': True, 'change': True, 'add': True}}], 'app_label': 'auth', 'app_url': '/admin/auth/'}, {'has_module_perms': True, 'name': 'Params', 'models': [{'name': <django.utils.functional.lazy.<locals>.__proxy__ object at 0x7f6be9cca6d8>, 'add_url': '/admin/params/person/add/', 'admin_url': '/admin/params/person/', 'object_name': 'Person', 'perms': {'delete': True, 'change': True, 'add': True}}], 'app_label': 'params', 'app_url': '/admin/params/'}, {'has_module_perms': True, 'name': <django.utils.functional.lazy.<locals>.__proxy__ object at 0x7f6bfaf15978>, 'models': [{'name': <django.utils.functional.lazy.<locals>.__proxy__ object at 0x7f6be9c856a0>, 'add_url': '/admin/flatpages/flatpage/add/', 'admin_url': '/admin/flatpages/flatpage/', 'object_name': 'FlatPage', 'perms': {'delete': True, 'change': True, 'add': True}}], 'app_label': 'flatpages', 'app_url': '/admin/flatpages/'}, {'has_module_perms': True, 'name': 'Sad', 'models': [{'name': <django.utils.functional.lazy.<locals>.__proxy__ object at 0x7f6be9c853c8>, 'add_url': '/admin/sad/user/add/', 'admin_url': '/admin/sad/user/', 'object_name': 'User', 'perms': {'delete': True, 'change': True, 'add': True}}], 'app_label': 'sad', 'app_url': '/admin/sad/'}, {'has_module_perms': True, 'name': <django.utils.functional.lazy.<locals>.__proxy__ object at 0x7f6bfaf15898>, 'models': [{'name': <django.utils.functional.lazy.<locals>.__proxy__ object at 0x7f6be9c85438>, 'add_url': '/admin/sites/site/add/', 'admin_url': '/admin/sites/site/', 'object_name': 'Site', 'perms': {'delete': True, 'change': True, 'add': True}}], 'app_label': 'sites', 'app_url': '/admin/sites/'}, {'has_module_perms': True, 'name': 'Space', 'models': [{'name': <django.utils.functional.lazy.<locals>.__proxy__ object at 0x7f6be9ccaf98>, 'add_url': '/admin/space/solution/add/', 'admin_url': '/admin/space/solution/', 'object_name': 'Solution', 'perms': {'delete': True, 'change': True, 'add': True}}], 'app_label': 'space', 'app_url': '/admin/space/'}, {'has_module_perms': True, 'name': <django.utils.functional.lazy.<locals>.__proxy__ object at 0x7f6bfaf0bb38>, 'models': [{'name': <django.utils.functional.lazy.<locals>.__proxy__ object at 0x7f6be9ccad30>, 'add_url': '/admin/contenttypes/contenttype/add/', 'admin_url': '/admin/contenttypes/contenttype/', 'object_name': 'ContentType', 'perms': {'delete': True, 'change': True, 'add': True}}], 'app_label': 'contenttypes', 'app_url': '/admin/contenttypes/'}], 'LANGUAGE_BIDI': False}]"
[2016-10-05 00:02:16] DEBUG [django.template:927] Exception while resolving variable 'is_popup' in template 'admin/index.html'.
Traceback (most recent call last):
  File "/home/rusbel/Proyectos/myvenv/lib/python3.5/site-packages/django/template/base.py", line 883, in _resolve_lookup
    current = current[bit]
  File "/home/rusbel/Proyectos/myvenv/lib/python3.5/site-packages/django/template/context.py", line 77, in __getitem__
    raise KeyError(key)
KeyError: 'is_popup'

During handling of the above exception, another exception occurred:

Traceback (most recent call last):
  File "/home/rusbel/Proyectos/myvenv/lib/python3.5/site-packages/django/template/base.py", line 889, in _resolve_lookup
    if isinstance(current, BaseContext) and getattr(type(current), bit):
AttributeError: type object 'RequestContext' has no attribute 'is_popup'

During handling of the above exception, another exception occurred:

Traceback (most recent call last):
  File "/home/rusbel/Proyectos/myvenv/lib/python3.5/site-packages/django/template/base.py", line 898, in _resolve_lookup
    current = current[int(bit)]
ValueError: invalid literal for int() with base 10: 'is_popup'

During handling of the above exception, another exception occurred:

Traceback (most recent call last):
  File "/home/rusbel/Proyectos/myvenv/lib/python3.5/site-packages/django/template/base.py", line 905, in _resolve_lookup
    (bit, current))  # missing attribute
django.template.base.VariableDoesNotExist: Failed lookup for key [is_popup] in "[{'False': False, 'None': None, 'True': True}, {'request': <WSGIRequest: GET '/admin/'>, 'LANGUAGE_BIDI': False, 'messages': <django.contrib.messages.storage.fallback.FallbackStorage object at 0x7f6be9c85048>, 'MEDIA_URL': '/media/', 'LANGUAGES': (('ja', <django.utils.functional.lazy.<locals>.__proxy__ object at 0x7f6bfc310198>), ('zh-tw', <django.utils.functional.lazy.<locals>.__proxy__ object at 0x7f6bfc3101d0>), ('fr', <django.utils.functional.lazy.<locals>.__proxy__ object at 0x7f6bfc310208>), ('de', <django.utils.functional.lazy.<locals>.__proxy__ object at 0x7f6bfc310240>), ('en', <django.utils.functional.lazy.<locals>.__proxy__ object at 0x7f6bfc321588>), ('es', <django.utils.functional.lazy.<locals>.__proxy__ object at 0x7f6bfc321550>), ('es-ar', <django.utils.functional.lazy.<locals>.__proxy__ object at 0x7f6bfc321518>), ('es-pe', <django.utils.functional.lazy.<locals>.__proxy__ object at 0x7f6bfc3215c0>), ('pt', <django.utils.functional.lazy.<locals>.__proxy__ object at 0x7f6bfc3215f8>), ('pt-br', <django.utils.functional.lazy.<locals>.__proxy__ object at 0x7f6bfc321668>)), 'user': <SimpleLazyObject: <User: admin>>, 'perms': <django.contrib.auth.context_processors.PermWrapper object at 0x7f6bf9078390>, 'TIME_ZONE': 'UTC', 'LANGUAGE_CODE': 'es', 'csrf_token': <SimpleLazyObject: <function csrf.<locals>._get_val at 0x7f6bea76e2f0>>, 'STATIC_URL': '/static/', 'DEFAULT_MESSAGE_LEVELS': {'INFO': 20, 'DEBUG': 10, 'ERROR': 40, 'SUCCESS': 25, 'WARNING': 30}}, {}, {'has_permission': True, 'available_apps': [{'has_module_perms': True, 'name': <django.utils.functional.lazy.<locals>.__proxy__ object at 0x7f6bfaf0b3c8>, 'models': [{'name': <django.utils.functional.lazy.<locals>.__proxy__ object at 0x7f6be9cca828>, 'add_url': '/admin/auth/group/add/', 'admin_url': '/admin/auth/group/', 'object_name': 'Group', 'perms': {'delete': True, 'change': True, 'add': True}}, {'name': <django.utils.functional.lazy.<locals>.__proxy__ object at 0x7f6be9ccae48>, 'add_url': '/admin/auth/permission/add/', 'admin_url': '/admin/auth/permission/', 'object_name': 'Permission', 'perms': {'delete': True, 'change': True, 'add': True}}], 'app_label': 'auth', 'app_url': '/admin/auth/'}, {'has_module_perms': True, 'name': 'Params', 'models': [{'name': <django.utils.functional.lazy.<locals>.__proxy__ object at 0x7f6be9cca978>, 'add_url': '/admin/params/person/add/', 'admin_url': '/admin/params/person/', 'object_name': 'Person', 'perms': {'delete': True, 'change': True, 'add': True}}], 'app_label': 'params', 'app_url': '/admin/params/'}, {'has_module_perms': True, 'name': <django.utils.functional.lazy.<locals>.__proxy__ object at 0x7f6bfaf15978>, 'models': [{'name': <django.utils.functional.lazy.<locals>.__proxy__ object at 0x7f6be9ccabe0>, 'add_url': '/admin/flatpages/flatpage/add/', 'admin_url': '/admin/flatpages/flatpage/', 'object_name': 'FlatPage', 'perms': {'delete': True, 'change': True, 'add': True}}], 'app_label': 'flatpages', 'app_url': '/admin/flatpages/'}, {'has_module_perms': True, 'name': 'Sad', 'models': [{'name': <django.utils.functional.lazy.<locals>.__proxy__ object at 0x7f6be9cca630>, 'add_url': '/admin/sad/user/add/', 'admin_url': '/admin/sad/user/', 'object_name': 'User', 'perms': {'delete': True, 'change': True, 'add': True}}], 'app_label': 'sad', 'app_url': '/admin/sad/'}, {'has_module_perms': True, 'name': <django.utils.functional.lazy.<locals>.__proxy__ object at 0x7f6bfaf15898>, 'models': [{'name': <django.utils.functional.lazy.<locals>.__proxy__ object at 0x7f6be9ccafd0>, 'add_url': '/admin/sites/site/add/', 'admin_url': '/admin/sites/site/', 'object_name': 'Site', 'perms': {'delete': True, 'change': True, 'add': True}}], 'app_label': 'sites', 'app_url': '/admin/sites/'}, {'has_module_perms': True, 'name': 'Space', 'models': [{'name': <django.utils.functional.lazy.<locals>.__proxy__ object at 0x7f6be9cca780>, 'add_url': '/admin/space/solution/add/', 'admin_url': '/admin/space/solution/', 'object_name': 'Solution', 'perms': {'delete': True, 'change': True, 'add': True}}], 'app_label': 'space', 'app_url': '/admin/space/'}, {'has_module_perms': True, 'name': <django.utils.functional.lazy.<locals>.__proxy__ object at 0x7f6bfaf0bb38>, 'models': [{'name': <django.utils.functional.lazy.<locals>.__proxy__ object at 0x7f6be9ccad68>, 'add_url': '/admin/contenttypes/contenttype/add/', 'admin_url': '/admin/contenttypes/contenttype/', 'object_name': 'ContentType', 'perms': {'delete': True, 'change': True, 'add': True}}], 'app_label': 'contenttypes', 'app_url': '/admin/contenttypes/'}], 'title': <django.utils.functional.lazy.<locals>.__proxy__ object at 0x7f6bfaf04c18>, 'site_title': <django.utils.functional.lazy.<locals>.__proxy__ object at 0x7f6bfaf04710>, 'site_url': '/', 'site_header': <django.utils.functional.lazy.<locals>.__proxy__ object at 0x7f6bfaf047b8>, 'LANGUAGE_CODE': 'es', 'app_list': [{'has_module_perms': True, 'name': <django.utils.functional.lazy.<locals>.__proxy__ object at 0x7f6bfaf0b3c8>, 'models': [{'name': <django.utils.functional.lazy.<locals>.__proxy__ object at 0x7f6be9cca8d0>, 'add_url': '/admin/auth/group/add/', 'admin_url': '/admin/auth/group/', 'object_name': 'Group', 'perms': {'delete': True, 'change': True, 'add': True}}, {'name': <django.utils.functional.lazy.<locals>.__proxy__ object at 0x7f6be9c85390>, 'add_url': '/admin/auth/permission/add/', 'admin_url': '/admin/auth/permission/', 'object_name': 'Permission', 'perms': {'delete': True, 'change': True, 'add': True}}], 'app_label': 'auth', 'app_url': '/admin/auth/'}, {'has_module_perms': True, 'name': 'Params', 'models': [{'name': <django.utils.functional.lazy.<locals>.__proxy__ object at 0x7f6be9cca6d8>, 'add_url': '/admin/params/person/add/', 'admin_url': '/admin/params/person/', 'object_name': 'Person', 'perms': {'delete': True, 'change': True, 'add': True}}], 'app_label': 'params', 'app_url': '/admin/params/'}, {'has_module_perms': True, 'name': <django.utils.functional.lazy.<locals>.__proxy__ object at 0x7f6bfaf15978>, 'models': [{'name': <django.utils.functional.lazy.<locals>.__proxy__ object at 0x7f6be9c856a0>, 'add_url': '/admin/flatpages/flatpage/add/', 'admin_url': '/admin/flatpages/flatpage/', 'object_name': 'FlatPage', 'perms': {'delete': True, 'change': True, 'add': True}}], 'app_label': 'flatpages', 'app_url': '/admin/flatpages/'}, {'has_module_perms': True, 'name': 'Sad', 'models': [{'name': <django.utils.functional.lazy.<locals>.__proxy__ object at 0x7f6be9c853c8>, 'add_url': '/admin/sad/user/add/', 'admin_url': '/admin/sad/user/', 'object_name': 'User', 'perms': {'delete': True, 'change': True, 'add': True}}], 'app_label': 'sad', 'app_url': '/admin/sad/'}, {'has_module_perms': True, 'name': <django.utils.functional.lazy.<locals>.__proxy__ object at 0x7f6bfaf15898>, 'models': [{'name': <django.utils.functional.lazy.<locals>.__proxy__ object at 0x7f6be9c85438>, 'add_url': '/admin/sites/site/add/', 'admin_url': '/admin/sites/site/', 'object_name': 'Site', 'perms': {'delete': True, 'change': True, 'add': True}}], 'app_label': 'sites', 'app_url': '/admin/sites/'}, {'has_module_perms': True, 'name': 'Space', 'models': [{'name': <django.utils.functional.lazy.<locals>.__proxy__ object at 0x7f6be9ccaf98>, 'add_url': '/admin/space/solution/add/', 'admin_url': '/admin/space/solution/', 'object_name': 'Solution', 'perms': {'delete': True, 'change': True, 'add': True}}], 'app_label': 'space', 'app_url': '/admin/space/'}, {'has_module_perms': True, 'name': <django.utils.functional.lazy.<locals>.__proxy__ object at 0x7f6bfaf0bb38>, 'models': [{'name': <django.utils.functional.lazy.<locals>.__proxy__ object at 0x7f6be9ccad30>, 'add_url': '/admin/contenttypes/contenttype/add/', 'admin_url': '/admin/contenttypes/contenttype/', 'object_name': 'ContentType', 'perms': {'delete': True, 'change': True, 'add': True}}], 'app_label': 'contenttypes', 'app_url': '/admin/contenttypes/'}], 'LANGUAGE_BIDI': False}]"
[2016-10-05 00:02:16] DEBUG [django.db.backends:89] (0.000) SELECT "django_admin_log"."id", "django_admin_log"."action_time", "django_admin_log"."user_id", "django_admin_log"."content_type_id", "django_admin_log"."object_id", "django_admin_log"."object_repr", "django_admin_log"."action_flag", "django_admin_log"."change_message", "auth_user"."id", "auth_user"."password", "auth_user"."last_login", "auth_user"."is_superuser", "auth_user"."username", "auth_user"."first_name", "auth_user"."last_name", "auth_user"."email", "auth_user"."is_staff", "auth_user"."is_active", "auth_user"."date_joined", "auth_user"."last_headquar_id", "auth_user"."last_module_id", "auth_user"."person_id", "django_content_type"."id", "django_content_type"."app_label", "django_content_type"."model" FROM "django_admin_log" INNER JOIN "auth_user" ON ("django_admin_log"."user_id" = "auth_user"."id") LEFT OUTER JOIN "django_content_type" ON ("django_admin_log"."content_type_id" = "django_content_type"."id") WHERE "django_admin_log"."user_id" = 1 ORDER BY "django_admin_log"."action_time" DESC LIMIT 10; args=(1,)
